Workbook

Sheet Portada
A1: Valuación de Organización Soriana, S.A.B. de C.V.: DCF, múltiplos y transacciones precedentes
A2: Tecnológico de Monterrey · Valuación de Empresas · 2026 · generado el 19 de octubre de 2026
A4: Empresa | B4: Organización Soriana, S.A.B. de C.V. (SORIANA B · BMV)
A5: Escenario | B5: Caso base del Excel (inflación Base)
A6: Precio de mercado | B6: Cierre 25-sep-2026
A7: Fecha de valuación | B7: 01-oct-2026
A9: Equipo
A10: Adrián Fermín Rodríguez Valades | B10: A01614820
A11: Saúl González Loredo | B11: A016113349
A12: Miguel Emilio Pérez García | B12: A01613516
A13: Mauricio Fernandez Juarez | B13: A01614732
A14: Francisco Aarón Ponce Flores | B14: A01614662
A16: Dato clave | B16: Valor
A17: Precio de mercado de referencia | B17: $33.48 (cierre 25-sep-2026)
A18: Fecha de valuación | B18: 01-oct-2026
A19: Valor DCF por acción | B19: $38.34 (+14.5% frente al mercado)
A20: Rango DCF por escenario de inflación | B20: $37.93 a $39.14 (Cautela, Base, Alcista)
A21: Trading Comps | B21: $33.49 (7 comparable(s), media)
A22: Precedent Transactions LSEG/SDC (referencia) | B22: $23.74 (mediana EV/EBITDA, 8 operaciones; peso 0%)
... A29: Peso del valor terminal en el EV | B29: 70.3%
A31: Hojas con fórmulas: Supuestos, WACC, FCFF y valuación, Transacciones SDC y Combinada. Las demás hojas reproducen las tablas numeradas del reporte técnico.

Sheet Supuestos
A1: Supuestos activos (insumos de las hojas con fórmulas)
A2: Valores en azul: cambiarlos recalcula WACC, FCFF y valuación, transacciones y combinada.
A3: Supuesto | B3: Valor | C3: Unidad | D3: Fuente
A4: Tasa libre de riesgo (Rf) | B4: 0.09517 | C4: fracción | D4: Bono M 10 años
A5: Prima de riesgo de mercado | B5: 0.0423 | C5: fracción | D5: Hoja WACC
A6: Beta desapalancada (βU) | B6: 0.17052082 | C6: x | D6: Regresión semanal (βL 0.2178) desapalancada
A7: Deuda total para el WACC | B7: 23618 | C7: mdp | D7: Deuda + arrendamientos
A8: Tasa del escudo fiscal | B8: 0.3 | C8: fracción | D8: Hoja WACC
A9: Kd antes de impuestos | B9: 0.1 | C9: fracción | D9: Hoja Beta y Kd
A10: Crecimiento perpetuo (g) | B10: 0.035 | C10: fracción | D10: Hoja Proyección Final
A11: Múltiplo de salida EV/EBITDA | B11: 5.810772 | C11: x | D11: Mediana comparables −10%
A12: Peso de Gordon | B12: 0.5 | C12: fracción | D12: Ponderación del valor terminal
A13: Deuda bursátil y bancaria al cierre | B13: 11500 | C13: mdp | D13: Puente al cierre
A14: Arrendamientos al cierre | B14: 12118 | C14: mdp | D14: Puente al cierre
A15: Efectivo al cierre | B15: 9295 | C15: mdp | D15: Puente al cierre
... A28: Umbral de venta | B28: -0.1 | C28: fracción | D28: Regla de recomendación

Sheet WACC
A1: WACC con fórmulas (última iteración, equity del DCF)
A2: El equity E es el del DCF en la última iteración del motor; el resto se calcula aquí.
A3: Concepto | B3: Valor | C3: Fórmula | D3: App
A4: Equity E (DCF, última iteración) | B4: 71948.058 | C4: dato del motor
A5: D / E | B5: =Supuestos!$B$7/B4 | C5: D ÷ E | D5: 0.32826459
A6: βL = βU × [1 + (1 − t) × D/E] | B6: =Supuestos!$B$6*(1+(1-Supuestos!$B$8)*B5) | C6: Hamada | D6: 0.20970398
A7: Ke = Rf + βL × PRM | B7: =Supuestos!$B$4+B6*Supuestos!$B$5 | C7: CAPM | D7: 0.10404048
A8: Kd después de impuestos | B8: =Supuestos!$B$9*(1-Supuestos!$B$8) | C8: Kd × (1 − t) | D8: 0.07
A9: E / (D + E) | B9: =B4/(B4+Supuestos!$B$7) | C9: peso del capital | D9: 0.75286205
A10: D / (D + E) | B10: =Supuestos!$B$7/(B4+Supuestos!$B$7) | C10: peso de la deuda | D10: 0.24713795
A11: WACC | B11: =B9*B7+B10*B8 | C11: E/V × Ke + D/V × Kd(1−t) | D11: 0.095627784
A12: Modo activo del WACC en el modelo | B12: iterado
A13: WACC usado en el DCF | B13: =B11
A14: Ke usado en el DCF | B14: =B7
A17: Iteraciones del motor
A18: Iteración | B18: WACC entrada | C18: Equity DCF | D18: D/E | E18: Beta | F18: Ke | G18: WACC salida
A19: 0 | B19: 0.10063018 | C19: 65552.804 | D19: 0.3602897 | E19: 0.21352664 | F19: 0.10420218 | G19: 0.095143304
A20: 1 | B20: 0.095143304 | C20: 72623.558 | D20: 0.32521128 | E20: 0.20933952 | F20: 0.10402506 | G20: 0.095675198
A21: 2 | B21: 0.095675198 | C21: 71882.453 | D21: 0.32856419 | E21: 0.20973974 | F21: 0.10404199 | G21: 0.095623144
A22: 3 | B22: 0.095623144 | C22: 71954.411 | D22: 0.32823561 | E22: 0.20970052 | F22: 0.10404033 | G22: 0.095628233
A23: 4 | B23: 0.095628233 | C23: 71947.369 | D23: 0.32826774 | E23: 0.20970435 | F23: 0.10404049 | G23: 0.095627735
A24: 5 | B24: 0.095627735 | C24: 71948.058 | D24: 0.32826459 | E24: 0.20970398 | F24: 0.10404048 | G24: 0.095627784

Sheet FCFF y valuación
A1: Proyección FCFF y valuación con fórmulas
A2: Fondo azul claro: proyección por drivers del motor (con la inflación del escenario). Lo demás son fórmulas que leen Supuestos y WACC.
A3: Concepto | B3: 2026E | C3: 2027E | D3: 2028E | E3: 2029E | F3: 2030E
A4: Ventas | B4: 169070.37 | C4: 171572.61 | D4: 177530.47 | E4: 185040.01 | F4: 193343.68
A5: Utilidad de operación (EBIT) | B5: 7424.4795 | C5: 7498.3315 | D5: 7790.9429 | E5: 8159.6462 | F5: 8572.5137
A6: Tasa de impuestos sobre EBIT | B6: 0.30020143 | C6: 0.30370143 | D6: 0.30391786 | E6: 0.30413428 | F6: 0.30435071
A7: (−) Impuestos sobre EBIT | B7: =B5*B6 | C7: =C5*C6 | D7: =D5*D6 | E7: =E5*E6 | F7: =F5*F6
A8: NOPAT | B8: =B5-B7 | C8: =C5-C7 | D8: =D5-D7 | E8: =E5-E7 | F8: =F5-F7
A9: (+) Depreciación y amortización | B9: 4130.1467 | C9: 4191.2729 | D9: 4337.7421 | E9: 4522.1951 | F9: 4726.1385
A10: (−) Capex | B10: 3864.608 | C10: 3428.8779 | D10: 3535.2085 | E10: 3671.4719 | F10: 3822.3574
A11: (−) Inversión en capital de trabajo | B11: -106.63803 | C11: 94.414009 | D11: -198.13236 | E11: 147.23122 | F11: 162.80088
A12: FCFF | B12: =B8+B9-B10-B11 | C12: =C8+C9-C10-C11 | D12: =D8+D9-D10-D11 | E12: =E8+E9-E10-E11 | F12: =F8+F9-F10-F11
A13: Periodo n | B13: 1 | C13: 2 | D13: 3 | E13: 4 | F13: 5
A14: Factor de descuento 1/(1+WACC)^n | B14: =1/(1+WACC!$B$13)^B13 | C14: =1/(1+WACC!$B$13)^C13 | D14: =1/(1+WACC!$B$13)^D13 | E14: =1/(1+WACC!$B$13)^E13 | F14: =1/(1+WACC!$B$13)^F13
A15: Valor presente del FCFF | B15: =B12*B14 | C15: =C12*C14 | D15: =D12*D14 | E15: =E12*E14 | F15: =F12*F14
A16: EBITDA | B16: 11554.626 | C16: 11689.604 | D16: 12128.685 | E16: 12681.841 | F16: 13298.652
A18: Valuación
A19: Suma VP de los FCFF | B19: =SUM(B15:F15)
A20: FCF normalizado 2030E (capex = D&A): NOPAT − ΔNWC | B20: =F8-F11
A21: Valor terminal Gordon = FCF × (1+g)/(WACC − g) | B21: =B20*(1+Supuestos!$B$10)/(WACC!$B$13-Supuestos!$B$10)
A22: VP valor terminal Gordon | B22: =B21*F14
A23: EV Gordon | B23: =B19+B22
A24: Valor terminal múltiplo = EBITDA × múltiplo | B24: =F16*Supuestos!$B$11
A25: VP valor terminal múltiplo | B25: =B24*F14
A26: EV múltiplo | B26: =B19+B25
A27: EV ponderado al cierre | B27: =Supuestos!$B$12*B23+(1-Supuestos!$B$12)*B26
A28: EV capitalizado = EV × (1+WACC)^t1 | B28: =B27*(1+WACC!$B$13)^Supuestos!$B$16
A29: EV al balance intermedio (+ ajuste FCF del periodo) | B29: =B28+Supuestos!$B$17
A30: Equity al balance intermedio = EV − deuda − arrendamientos + efectivo | B30: =B29-Supuestos!$B$18-Supuestos!$B$19+Supuestos!$B$20
A31: Equity a la fecha de valuación = × (1+Ke)^t2 | B31: =B30*(1+WACC!$B$14)^Supuestos!$B$21
A32: Valor DCF por acción (MXN) | B32: =B31/Supuestos!$B$22
A33: Precio de mercado (MXN) | B33: =Supuestos!$B$23
A34: Potencial (%) | B34: =B32/B33-1
A36: Valor DCF por acción calculado por la app | B36: 38.340078
A37: Diferencia fórmula − app (MXN) | B37: =B32-B36
A38: Nota: con WACC iterado, cambiar un supuesto aquí no repite la iteración (el equity del DCF queda fijo en la hoja WACC); la app sí la repite.

Sheet Transacciones SDC
A1: Precedent Transactions LSEG/SDC: muestra, criterios y estadísticos con fórmulas
A2: LSEG/SDC (Refinitiv) · GridExport_October_19_2026_9_29_57.pdf · 2026-10-19 · tipo de cambio 18.48 MXN/USD (Implícito en S&P Capital IQ: capitalización 59,580 mdp / 3,223.7 USD mm al cierre del 7-oct-2026 (reporte comparativo, p. 1 y 25). Equivalente MXN solo informativo: los múltiplos no requieren conversión.)
A4: Objetivo | B4: Deal # | C4: Anuncio | D4: País objetivo | E4: Comprador | F4: País comprador | G4: Subindustria | H4: Valor operación (USD mm) | I4: EV (USD mm) | J4: EV (MXN mm) | K4: EV/EBITDA | L4: EV/Ventas | M4: P/E | N4: # múltiplos | O4: Ventana | P4: ≥2 múltiplos | Q4: Autoservicio | R4: Recompra | S4: Juicio | T4: Incluir (1/0) | U4: EV/EBITDA usado | V4: Motivo
A5: Almacenes Exito SA | B5: 4144889040 | C5: 2023-10-16 | D5: Colombia | E5: Cama Commercial Group Corp | F5: Panama | G5: Discount and Department Store Retailing | H5: 1019.99 | I5: 1744.4697 | J5: =I5*18.48 | K5: 4.98 | L5: 0.34 | M5: NA | N5: =COUNT(K5:M5) | O5: Sí | P5: Sí | Q5: Sí | R5: No | S5: Elegible | T5: 1 | U5: =IF(AND(T5=1,ISNUMBER(K5)),K5,"") | V5: OPA por el control de Éxito (hiper y supermercados); vendedor grupo Casino. Comprador: Cama Commercial Group (vehículo de Grupo Calleja / Super Selectos). SDC clasifica al objetivo como "Discount and Department Store Retailing". Misma operación que la muestra CIQ.
A6: Profi Rom Food Srl | B6: 4150545040 | C6: 2023-10-30 | D6: Romania | E6: Koninklijke Ahold Delhaize NV | F6: Netherlands | G6: Food & Beverage Retailing | H6: 1703.42 | I6: 1711.6877 | J6: =I6*18.48 | K6: 21.31 | L6: 0.69 | M6: NA | N6: =COUNT(K6:M6) | O6: Sí | P6: Sí | Q6: Sí | R6: No | S6: Elegible | T6: 1 | U6: =IF(AND(T6=1,ISNUMBER(K6)),K6,"") | V6: Compra del 100% de la cadena de supermercados Profi (Rumania). Múltiplo alto por crecimiento y sinergias: atípico estadístico (ver sección 3).
A7: Lawson Inc | B7: 4191742040 | C7: 2024-02-06 | D7: Japan | E7: KDDI CORP | F7: Japan | G7: Food & Beverage Retailing | H7: 3339.55 | I7: 11027.053 | J7: =I7*18.48 | K7: 3.24 | L7: 0.9 | M7: 13.72 | N7: =COUNT(K7:M7) | O7: Sí | P7: Sí | Q7: Sí | R7: No | S7: Elegible | T7: 1 | U7: =IF(AND(T7=1,ISNUMBER(K7)),K7,"") | V7: OPA de KDDI; control conjunto 50/50 con Mitsubishi. Tiendas de conveniencia (formato de proximidad): comparabilidad con reserva.
A8: KANSAI FOOD MARKET LTD | B8: 4234985040 | C8: 2024-05-15 | D8: Japan | E8: H2O RETAILING CORP | F8: Japan | G8: Food & Beverage Retailing | H8: 234.33 | I8: 700.28122 | J8: =I8*18.48 | K8: 7.64 | L8: 0.28 | M8: 18.52 | N8: =COUNT(K8:M8) | O8: Sí | P8: Sí | Q8: Sí | R8: No | S8: Elegible | T8: 1 | U8: =IF(AND(T8=1,ISNUMBER(K8)),K8,"") | V8: OPA de H2O Retailing para consolidar el control del supermercado.
A9: Yonghui Superstores Co Ltd | B9: 4291087040 | C9: 2024-09-23 | D9: China (Mainland) | E9: Guangdong Juncai International Trading Co Ltd | F9: China (Mainland) | G9: Food & Beverage Retailing | H9: 889.32 | I9: 5614.0797 | J9: =I9*18.48 | K9: 12.77 | L9: 0.53 | M9: NA | N9: =COUNT(K9:M9) | O9: Sí | P9: Sí | Q9: Sí | R9: No | S9: Elegible | T9: 1 | U9: =IF(AND(T9=1,ISNUMBER(K9)),K9,"") | V9: Compra de ~29% por Guangdong Juncai (filial de Miniso); queda como mayor accionista. Participación estratégica relevante, no control pleno.
A10: Sun Art Retail Group Ltd | B10: 4338758040 | C10: 2025-01-01 | D10: Hong Kong | E10: Paragon Shine Ltd | F10: Hong Kong | G10: Food & Beverage Retailing | H10: 1333.8 | I10: 824.10101 | J10: =I10*18.48 | K10: 2.2 | L10: 0.08 | M10: NA | N10: =COUNT(K10:M10) | O10: Sí | P10: Sí | Q10: Sí | R10: No | S10: Elegible | T10: 1 | U10: =IF(AND(T10=1,ISNUMBER(K10)),K10,"") | V10: Compra de control a Alibaba con descuento (prima 1 día −44.4%): operación en dificultad; se conserva y se cuantifica su efecto en la sección 4.
A11: METRO AG | B11: 4353024040 | C11: 2025-02-05 | D11: Germany | E11: EP Global Commerce GmbH | F11: Germany | G11: Food & Beverage Retailing | H11: 294.05 | I11: 5048.5763 | J11: =I11*18.48 | K11: 5.11 | L11: 0.16 | M11: NA | N11: =COUNT(K11:M11) | O11: Sí | P11: Sí | Q11: Sí | R11: No | S11: Elegible | T11: 1 | U11: =IF(AND(T11=1,ISNUMBER(K11)),K11,"") | V11: Oferta de EP Global Commerce (prima 1 día +38.8%). Mayoreo de alimentos (cash & carry), comparable con City Club.
A12: Seiyu Co Ltd | B12: 4340542040 | C12: 2025-03-05 | D12: Japan | E12: Trial Holdings Inc | F12: Japan | G12: Food & Beverage Retailing | H12: 2536.72 | I12: 2552.3912 | J12: =I12*18.48 | K12: NA | L12: 0.69 | M12: 3.88 | N12: =COUNT(K12:M12) | O12: Sí | P12: Sí | Q12: Sí | R12: No | S12: Elegible | T12: 1 | U12: =IF(AND(T12=1,ISNUMBER(K12)),K12,"") | V12: Compra de control por Trial Holdings. Sin EV/EBITDA: solo aporta EV/Ventas (no usado en el precio). P/E 3.88x distorsionado.
A13: Chengdu Hongqi Chain Co Ltd | B13: 4172416040 | C13: 2023-12-21 | D13: China (Mainland) | E13: Sichuan Shangtou Investment Co Ltd | F13: China (Mainland) | G13: Food & Beverage Retailing | H13: 182.33 | I13: 957.34243 | J13: =I13*18.48 | K13: 4.97 | L13: 0.67 | M13: 13.41 | N13: =COUNT(K13:M13) | O13: Sí | P13: Sí | Q13: Sí | R13: No | S13: Elegible | T13: 1 | U13: =IF(AND(T13=1,ISNUMBER(K13)),K13,"") | V13: CORRECCIÓN: el objetivo es Chengdu Hongqi Chain (cadena de conveniencia y supermercados de Sichuan), no "Chongqing Department Store". Sichuan Shangtou Investment pasa a ser el accionista de control. La pantalla no reporta el % adquirido: decisión del analista con base en el anuncio.
A14: Seven & i Holdings Co Ltd | B14: 4163818040 | C14: 2023-11-30 | D14: Japan | E14: Seven & i Holdings Co Ltd | F14: Japan | G14: Food & Beverage Retailing | H14: 747.08 | I14: 23898.264 | J14: =I14*18.48 | K14: 3.36 | L14: 0.31 | M14: 11.07 | N14: =COUNT(K14:M14) | O14: Sí | P14: Sí | Q14: Sí | R14: Sí | S14: No elegible | T14: 0 | U14: =IF(AND(T14=1,ISNUMBER(K14)),K14,"") | V14: Recompra propia: no hay cambio de control.
A15: Carrefour SA | B15: 4220226040 | C15: 2024-03-26 | D15: France | E15: Carrefour SA | F15: France | G15: Food & Beverage Retailing | H15: 395.51 | I15: 25430.571 | J15: =I15*18.48 | K15: 5.16 | L15: 0.28 | M15: 11.59 | N15: =COUNT(K15:M15) | O15: Sí | P15: Sí | Q15: Sí | R15: Sí | S15: No elegible | T15: 0 | U15: =IF(AND(T15=1,ISNUMBER(K15)),K15,"") | V15: Recompra propia: no hay cambio de control.
A16: Seven & i Holdings Co Ltd | B16: 4382315040 | C16: 2025-04-09 | D16: Japan | E16: Seven & i Holdings Co Ltd | F16: Japan | G16: Food & Beverage Retailing | H16: 4101.72 | I16: 57481.831 | J16: =I16*18.48 | K16: 8.74 | L16: 0.78 | M16: 17.36 | N16: =COUNT(K16:M16) | O16: Sí | P16: Sí | Q16: Sí | R16: Sí | S16: No elegible | T16: 0 | U16: =IF(AND(T16=1,ISNUMBER(K16)),K16,"") | V16: Recompra propia: no hay cambio de control.
A17: J Sainsbury PLC | B17: 4488172040 | C17: 2025-11-07 | D17: United Kingdom | E17: J Sainsbury PLC | F17: United Kingdom | G17: Food & Beverage Retailing | H17: 120.85 | I17: 13917.256 | J17: =I17*18.48 | K17: 4.71 | L17: 0.32 | M17: 17.52 | N17: =COUNT(K17:M17) | O17: Sí | P17: Sí | Q17: Sí | R17: Sí | S17: No elegible | T17: 0 | U17: =IF(AND(T17=1,ISNUMBER(K17)),K17,"") | V17: Recompra propia: no hay cambio de control.
A18: YAOKO Co Ltd | B18: 4343070040 | C18: 2025-01-14 | D18: Japan | E18: YAOKO Co Ltd | F18: Japan | G18: Food & Beverage Retailing | H18: 2412.71 | I18: 2864.3014 | J18: =I18*18.48 | K18: 10.68 | L18: 0.73 | M18: 20.83 | N18: =COUNT(K18:M18) | O18: Sí | P18: Sí | Q18: Sí | R18: Sí | S18: No elegible | T18: 0 | U18: =IF(AND(T18=1,ISNUMBER(K18)),K18,"") | V18: Recompra propia de YAOKO (supermercados, Japón): no hay cambio de control.
A19: Magnit PJSC | B19: 4143788040 | C19: 2023-10-10 | D19: Russia | E19: Magnit PJSC | F19: Russia | G19: Food & Beverage Retailing | H19: 180.44 | I19: 7977.494 | J19: =I19*18.48 | K19: 3.63 | L19: 0.32 | M19: 6.67 | N19: =COUNT(K19:M19) | O19: Sí | P19: Sí | Q19: Sí | R19: Sí | S19: No elegible | T19: 0 | U19: =IF(AND(T19=1,ISNUMBER(K19)),K19,"") | V19: Recompra propia en un mercado con sanciones (Rusia).
A20: Gorodskoi Supermarket OOO | B20: 4391691040 | C20: 2025-04-30 | D20: Russia | E20: Tander AO | F20: Russia | G20: Food & Beverage Retailing | H20: 361.67 | I20: 478.10036 | J20: =I20*18.48 | K20: NA | L20: 0.45 | M20: 44.78 | N20: =COUNT(K20:M20) | O20: Sí | P20: Sí | Q20: Sí | R20: No | S20: No elegible | T20: 0 | U20: =IF(AND(T20=1,ISNUMBER(K20)),K20,"") | V20: Rusia: valuaciones distorsionadas por sanciones; además sin EV/EBITDA.
A21: Better Life Commercial Chain Share Co Ltd | B21: 4228856040 | C21: 2024-04-09 | D21: China (Mainland) | E21: Investor Group | F21: China (Mainland) | G21: Food & Beverage Retailing | H21: 345.7 | I21: 2318.2596 | J21: =I21*18.48 | K21: 45.98 | L21: 5.64 | M21: NA | N21: =COUNT(K21:M21) | O21: Sí | P21: Sí | Q21: Sí | R21: No | S21: No elegible | T21: 0 | U21: =IF(AND(T21=1,ISNUMBER(K21)),K21,"") | V21: Better Life Commercial Chain (Bubugao, supermercados de Hunan) en reestructura judicial: EV/EBITDA 46.0x y EV/Ventas 5.6x no representan una adquisición en marcha.
A22: Wincommerce General Commercial Services JSC | B22: 4292215040 | C22: 2024-09-04 | D22: Vietnam | E22: Masan Consumer Holdings Co Ltd | F22: Vietnam | G22: Food & Beverage Retailing | H22: 200 | I22: 2951.1146 | J22: =I22*18.48 | K22: 323.13 | L22: 2.45 | M22: NA | N22: =COUNT(K22:M22) | O22: Sí | P22: Sí | Q22: Sí | R22: No | S22: No elegible | T22: 0 | U22: =IF(AND(T22=1,ISNUMBER(K22)),K22,"") | V22: Wincommerce (WinMart, Vietnam) adquirida por otra empresa del grupo Masan: reorganización intragrupo; EV/EBITDA 323.1x por EBITDA cercano a cero.
A23: Prosol Gestion SAS | B23: 4467353040 | C23: 2025-12-16 | D23: France | E23: Apollo Global Management Inc | F23: United States | G23: Food & Beverage Retailing | H23: 1727.54 | I23: 2464.1464 | J23: =I23*18.48 | K23: NA | L23: 44.45 | M23: 33.81 | N23: =COUNT(K23:M23) | O23: Sí | P23: Sí | Q23: Sí | R23: No | S23: No elegible | T23: 0 | U23: =IF(AND(T23=1,ISNUMBER(K23)),K23,"") | V23: Prosol (Grand Frais, alimentos frescos) adquirida por Apollo. Sin EV/EBITDA y EV/Ventas 44.5x incongruente con un minorista de alimentos: dato no confiable.
A24: Inageya Co Ltd | B24: 4069894040 | C24: 2023-04-25 | D24: Japan | E24: AEON CO LTD | F24: Japan | G24: Food & Beverage Retailing | H24: 170.08 | I24: 463.75651 | J24: =I24*18.48 | K24: 10.27 | L24: 0.24 | M24: NA | N24: =COUNT(K24:M24) | O24: No | P24: Sí | Q24: Sí | R24: No | S24: Elegible | T24: 0 | U24: =IF(AND(T24=1,ISNUMBER(K24)),K24,"") | V24: Fuera de la ventana de 3 años.
A25: Casino Guichard-Perrachon SA | B25: 4069904040 | C25: 2023-04-24 | D25: France | E25: Investor Group | F25: Czech Republic | G25: Discount and Department Store Retailing | H25: 1347.24 | I25: 12843.134 | J25: =I25*18.48 | K25: 6.38 | L25: 0.4 | M25: NA | N25: =COUNT(K25:M25) | O25: No | P25: Sí | Q25: Sí | R25: No | S25: Elegible | T25: 0 | U25: =IF(AND(T25=1,ISNUMBER(K25)),K25,"") | V25: Fuera de la ventana; reestructura de deuda.
A26: Dia Portugal Supermercados SA | B26: 4115751040 | C26: 2023-08-03 | D26: Portugal | E26: Auchan Retail Portugal Sa | F26: Portugal | G26: Food & Beverage Retailing | H26: 186.02 | I26: 186.16127 | J26: =I26*18.48 | K26: 46.78 | L26: 0.29 | M26: NA | N26: =COUNT(K26:M26) | O26: No | P26: Sí | Q26: Sí | R26: No | S26: Elegible | T26: 0 | U26: =IF(AND(T26=1,ISNUMBER(K26)),K26,"") | V26: Fuera de la ventana; EBITDA deprimido (46.8x).
A27: Rimi Baltic AB | B27: 4364904040 | C27: 2025-03-05 | D27: Latvia | E27: Salling Group A/S | F27: Denmark | G27: Food & Beverage Retailing | H27: 1381.11 | I27: NA | J27: NA | K27: NA | L27: NA | M27: 27.76 | N27: =COUNT(K27:M27) | O27: Sí | P27: No | Q27: Sí | R27: No | S27: Elegible | T27: 0 | U27: =IF(AND(T27=1,ISNUMBER(K27)),K27,"") | V27: Solo 1 múltiplo disponible.
A30: Estadísticos de EV/EBITDA (solo operaciones incluidas con dato; los NA no cuentan)
A31: Estadístico | B31: EV/EBITDA | C31: Precio implícito (MXN) | D31: App (MXN)
A32: Mínimo | B32: =MIN(U5:U27) | C32: =(B32*Supuestos!$B$24+Supuestos!$B$25)/Supuestos!$B$26 | D32: 5.0770623
A33: Percentil 25 | B33: =QUARTILE(U5:U27,1) | C33: =(B33*Supuestos!$B$24+Supuestos!$B$25)/Supuestos!$B$26 | D33: 20.414791
A34: Media | B34: =AVERAGE(U5:U27) | C34: =(B34*Supuestos!$B$24+Supuestos!$B$25)/Supuestos!$B$26 | D34: 41.674358
A35: Mediana | B35: =MEDIAN(U5:U27) | C35: =(B35*Supuestos!$B$24+Supuestos!$B$25)/Supuestos!$B$26 | D35: 23.7448
A36: Percentil 75 | B36: =QUARTILE(U5:U27,3) | C36: =(B36*Supuestos!$B$24+Supuestos!$B$25)/Supuestos!$B$26 | D36: 49.187385
A37: Máximo | B37: =MAX(U5:U27) | C37: =(B37*Supuestos!$B$24+Supuestos!$B$25)/Supuestos!$B$26 | D37: 130.46914
A38: n | B38: =COUNT(U5:U27)
A39: Precio de transacciones (estadístico oficial: median) | B39: =C35

Sheet Combinada
A1: Valuación combinada y recomendación con fórmulas
A2: Pesos en azul: editables. El precio objetivo y la recomendación se recalculan.
A3: Método | B3: Precio por acción | C3: Peso | D3: Contribución | E3: Origen
A4: DCF | B4: ='FCFF y valuación'!$B$32 | C4: 0.5 | D4: =IF(ISNUMBER(B4),B4*C4,0) | E4: Fórmula (hoja FCFF y valuación)
A5: Trading Comps | B5: 33.492841 | C5: 0.5 | D5: =IF(ISNUMBER(B5),B5*C5,0) | E5: Motor ValuFlow (Trading Comps, media)
A6: Precedent Transactions | B6: ='Transacciones SDC'!$B$39 | C6: 0 | D6: =IF(ISNUMBER(B6),B6*C6,0) | E6: Fórmula (hoja Transacciones SDC)
A7: Precio objetivo combinado | B7: =SUM(D4:D6)/C7 | C7: =SUM(C4:C6)
A9: Precio de mercado | B9: =Supuestos!$B$23
A10: Potencial | B10: =B7/B9-1
A11: Recomendación | B11: =IF(B10>Supuestos!$B$27,"COMPRAR",IF(B10<Supuestos!$B$28,"VENDER","MANTENER"))
A13: Precio objetivo calculado por la app | B13: 35.91646
A14: Recomendación de la app | B14: MANTENER
A15: Precio objetivo = valuación combinada; COMPRAR si el potencial supera +10%, VENDER si es menor que −10% (hoja Transacciones SDC §7).

Sheet 01 Resumen ejecutivo
A1: 1. Resumen ejecutivo
A2: Tablas numeradas como en el reporte técnico PDF. Caso base del Excel (inflación Base).
A3: Tabla 1. Datos clave de la valuación
A4: Concepto | B4: Valor
A5: Precio de mercado de referencia | B5: $33.48 (cierre 25-sep-2026)
A6: Fecha de valuación | B6: 01-oct-2026
A7: Valor DCF por acción | B7: $38.34 (+14.5% frente al mercado)
A8: Rango DCF por escenario de inflación | B8: $37.93 a $39.14 (Cautela, Base, Alcista)
A9: Trading Comps | B9: $33.49 (7 comparable(s), media)
A10: Precedent Transactions LSEG/SDC (referencia) | B10: $23.74 (mediana EV/EBITDA, 8 operaciones; peso 0%)
A11: Precio objetivo combinado | B11: $35.92 (50% DCF · 50% Trading Comps · 0% Transacciones)
A12: Recomendación | B12: MANTENER (potencial +7.3% frente a $33.48)
A13: WACC / Ke / g | B13: 9.56% / 10.40% / 3.50%
A14: Beta desapalancada (βU) / apalancada (βL) | B14: 0.1705 / 0.2097
A15: Enterprise Value (cierre de 2025 / 2T26) | B15: 79,383 / 84,152 mdp
A16: Equity Value a la fecha de valuación | B16: 69,012 mdp
A17: Peso del valor terminal en el EV | B17: 0.703
A18: Fuente: Motor ValuFlow con el Excel PRO auditado (Caso base del Excel (inflación Base)).

Sheet 02 Contexto, objetivo y alcance
A1: 2. Contexto, objetivo y alcance
A2: Tablas numeradas como en el reporte técnico PDF. Caso base del Excel (inflación Base).
A3: Tabla 2. Fechas del modelo
A4: Fecha | B4: Valor
A5: Estados financieros base | B5: 31-dic-2025
A6: Balance intermedio | B6: 30-jun-2026 (2T26)
A7: Precio de mercado | B7: 25-sep-2026
A8: Fecha de valuación | B8: 01-oct-2026
A9: Siguiente reporte trimestral | B9: 23-oct-2026
A10: Fuente: Excel PRO auditado · hoja Fuentes

Sheet 03 Variables, fuentes y fechas
A1: 3. Variables, fuentes y fechas
A2: Tablas numeradas como en el reporte técnico PDF. Caso base del Excel (inflación Base).
A3: Tabla 3. Registro de insumos y fuentes
A4: Dónde se usa | B4: Dónde se usa | C4: Valor | D4: Fecha | E4: Unidad | F4: Tipo | G4: Fuente
A5: Inflación INPC quincenal | B5: Inflación!A60:B172 | C5: 113 obs. | D5: 07-oct-2026 | E5: % anual | F5: Observado | G5: Banco de México, serie SP74833 (vía MODELO DE INFLACION EN LA VALUACION DE EMPRESAS.xlsx)
A6: Escenario Base 3.51% | B6: Inflación!B48 | C6: 0.0351 | D6: 07-oct-2026 | E6: % anual | F6: Modelo | G6: Modelo exponencial trimestral de clase (calculado en Inflación!33)
A7: Escenario Cautela 3.26% | B7: Inflación!B47 | C7: 0.0326 | D7: 07-oct-2026 | E7: % anual | F7: Supuesto | G7: Escenario derivado de la tendencia larga: Dossier de Soriana / Avances; construcción de clase más cercana Inflación!G36 (3.268%)
A8: Escenario Alcista 4.00% | B8: Inflación!B49 | C8: 0.04 | D8: — | E8: % anual | F8: Supuesto | G8: Supuesto de escenario de Avances de valuación intrínseca (no es pronóstico estadístico)
A9: Trayectoria Citi 2026–2030 — Referencia | B9: Inflación!B9:F9 | C9: 3.93/3.83/3.75% | D9: 22-sep-2026 | E9: % anual | F9: Referencia | G9: Encuesta Citi de Expectativas (comentario original de Proyección Final!C10). Referencia histórica del modelo anterior; no es escenario.
A10: Beta desapalancada (βU) · regresión semanal desapalancada (oficial) | B10: WACC!B9 ← 'Beta y Kd'!B19 ← H8 | C10: 0.17052082 | D10: 7-oct-2026 | E10: x | F10: Modelo | G10: Regresión semanal de rendimientos Soriana B vs. S&P/BMV IPC (Investing.com): βL observada 0.2178 (p = 0.087, no significativa al 95%), desapalancada con D/E 23,618 / 59,580 y t 30% → βU 0.1705. Referencia (no usada): Damodaran, Betas by Sector (Global), ene-2026, Retail (Grocery and Food), βU corregida por caja 0.69.
A11: Beta heredada (histórico) | B11: 'Beta y Kd'!B26 | C11: 0.8 | D11: — | E11: x | F11: Referencia | G11: Excel anterior / Material Maestro; solo para reproducir el baseline $31.16.
A12: Kd antes de impuestos (iteración) | B12: Proyección Final!C61 | C12: 0.1 | D12: 22-sep-2026 | E12: % | F12: Supuesto | G12: Comentario original de C61: Encuesta Citi (tasa Banxico 6.50% a fin de 2026 y 2027) y gastos financieros 1S26. Control: intereses 1S26 anualizados / deuda 2T26 = 9.87% ('Beta y Kd'!B58).
A13: Rf Bono M 10 años | B13: WACC!B5 | C13: 0.09517 | D13: 25-sep-2026 | E13: % anual | F13: Observado | G13: Cierre del Bono M 10 años el 25-sep-2026 (misma fecha que el precio de Soriana, WACC!B14): 9.517%. Fuente consultada: Investing.com, histórico Mexico 10Y (no oficial); confirmar en Banxico SIE (vector de precios de valores gubernamentales). Al usar el Bono M en pesos, el Rf ya incorpora el riesgo soberano de México.
A14: Prima de riesgo de mercado | B14: WACC!B6 | C14: 0.0423 | D14: ene-2026 | E14: % anual | F14: Observado | G14: Damodaran, Historical Implied Equity Risk Premiums (ene-2026): ERP implícita del S&P 500 = 4.23%. La prima país México (2.46%, Damodaran Country Risk Premiums, 5-ene-2026) queda solo como referencia en WACC!B7 para no duplicar el riesgo país ya incluido en el Rf en pesos.
A15: Crecimiento perpetuo g | B15: Proyección Final!B123 | C15: 0.035 | D15: oct-2026 | E15: % anual | F15: Supuesto | G15: g nominal = inflación de largo plazo (escenario Base 3.51%, Inflación!B48; meta de Banxico 3% ±1 pp) → crecimiento real ≈ 0%, prudente para un autoservicio maduro con ventas a la baja. g < Rf (9.52%) y g < WACC; FCF terminal normalizado con capex = D&A (Proyección Final!B127).
A16: Múltiplos de comparables | B16: Trading Comps | C16: 10 empresas | D16: 30-jun-2026 | E16: x | F16: Observado | G16: S&P Capital IQ, MULTIPLOS DE SORIANA Y COMPETIDORES.xls
A17: Transacciones | B17: Precedent Transactions | C17: 3 operaciones | D17: — | E17: x / MXN mm | F17: Observado | G17: S&P Capital IQ, TRANSACCIONES INDUSTRIA RETAIL.xls
A18: Métricas LTM y balance 2T26 de Soriana | B18: Trading Comps sección 2 | C18: mdp | D18: 30-jun-2026 | E18: MXN | F18: Observado | G18: Hoja Datos (reportes trimestrales de Soriana)
A19: Pesos de la combinada | B19: Valuación Combinada!C4:C6 | C19: 50/50/0 | D19: — | E19: % | F19: Supuesto | G19: Pesos iguales entre métodos activos (diap. 18). Precedent Transactions = 0%: la muestra CIQ (3 operaciones) no es defendible y la muestra LSEG/SDC auditada es global, de control mixto y muy dispersa; se muestra como referencia.
A20: Transacciones LSEG/SDC | B20: Transacciones SDC | C20: 23 evaluadas · 166 en pantalla | D20: 19-oct-2026 | E20: USD mm / x | F20: Observado | G20: LSEG/SDC (Refinitiv), GridExport_October_19_2026_9_29_57.pdf (Current Screen Template, 19-oct-2026 09:29:57). Juicio del analista separado en columnas naranjas.
A21: Contraste S&P Capital IQ / LSEG Refinitiv | B21: Contraste externo | C21: 13 referencias | D21: 19-oct-2026 | E21: MXN por acción / x | F21: Referencia | G21: Soriana_Reporte_Valuacion_CapitalIQ_Refinitiv.pdf (consulta 19-oct-2026; último cierre en CIQ 7-oct-2026). No se incorpora al precio oficial.
A22: Tipo de cambio de referencia
A23: Cada insumo del modelo con su origen. Tipo: Observado · Supuesto · Modelo · Pendiente (input heredado sin fuente verificada).
A24: Fuente: Excel · hoja Fuentes
A26: Tabla 4. Fuentes documentales
A27: Fuente | B27: Documento | C27: Uso
A28: Excel PRO auditado | B28: EXCEL FINAL PRO DEFINITIVO SORIANA - AUDITADO.xlsx | C28: Fuente maestra: DCF, inflación, Trading Comps, Precedent Transactions (CIQ y LSEG/SDC), combinada, contraste externo y validación (49 controles)
A29: Excel PRO original | B29: EXCEL FINAL PRO DEFINITIVO SORIANA.xlsx (excel/original, sin cambios) | C29: Versión del equipo antes de la auditoría; cambios en la hoja Auditoría
A30: LSEG/SDC (Refinitiv) | B30: GridExport_October_19_2026_9_29_57.pdf · Current Screen Template, 19-oct-2026 | C30: 166 operaciones; 23 evaluadas en la hoja Transacciones SDC
A31: Reporte comparativo | B31: Soriana_Reporte_Valuacion_CapitalIQ_Refinitiv.pdf (19-oct-2026) | C31: DCF con estimados CIQ, múltiplos, transacciones, consenso CIQ y Refinitiv, StarMine (referencias)
A32: Banco de México | B32: Serie SP74833 · INPC variación anual quincenal | C32: Datos de los modelos de inflación (consulta 07-oct-2026)
A33: S&P Capital IQ | B33: Quick Comparable Analysis (as-of 30-jun-2026) | C33: Múltiplos publicados de 10 comparables (extracto con atribución)
A34: Regresión semanal Soriana B vs. IPC | B34: Investing.com · hoja Beta y Kd §2 | C34: βL observada 0.2178 → βU 0.1705 (beta oficial del WACC)
A35: Damodaran (NYU Stern) | B35: Betas by Sector (Global), enero 2026 · Retail (Grocery and Food) | C35: βL 0.87, βU 0.65; corregida por caja 0.69 (referencia; beta oficial hasta el 19-oct-2026)
A36: S&P Capital IQ | B36: Comparable M&A Transactions | C36: 3 operaciones (histórico; no defendible)
A37: AE 1 · Etapa 1 | B37: PDF académico | C37: Perfil, historia, gobierno corporativo, estructura de capital, dividendos
A38: Reportes trimestrales | B38: Soriana 2T25–2T26 (BMV) | C38: Estados financieros trimestrales capturados en el Excel
A39: Fuente: Excel PRO auditado · hoja Fuentes

Sheet 04 Inflación y escenarios macro
A1: 4. Inflación y escenarios macro
A2: Tablas numeradas como en el reporte técnico PDF. Caso base del Excel (inflación Base).
A3: Tabla 5. Escenarios oficiales y referencia
A4: Escenario | B4: 2026E | C4: 2027E | D4: 2028E | E4: 2029E | F4: 2030E | G4: Precio DCF | H4: Naturaleza | I4: Fuente
A5: Cautela | B5: 0.0326 | C5: 0.0326 | D5: 0.0326 | E5: 0.0326 | F5: 0.0326 | G5: 37.93 | H5: Escenario derivado de la tendencia larga | I5: Valor documentado en el Dossier ("ventana 2023-2026, trimestral 3.26%") y en Avances (escenario Cautela). Construcción de clase más cercana: fila 36 (3.268%). Modelos de tendencia larga calculados aquí: fila 34.
A6: Base · activo | B6: 0.0351 | C6: 0.0351 | D6: 0.0351 | E6: 0.0351 | F6: 0.0351 | G6: 38.34 | H6: Forecast / resultado de modelo | I6: Fila 33 redondeada a 2 decimales en %. Reproduce el 3.51% del Dossier ("4.0327e^(−0.028x) → 3.51%") y de Avances. Horizonte: siguiente trimestre; su extensión a 2026–30 es un supuesto.
A7: Alcista | B7: 0.04 | C7: 0.04 | D7: 0.04 | E7: 0.04 | F7: 0.04 | G7: 39.14 | H7: Supuesto de escenario (no es pronóstico estadístico) | I7: Avances de valuación intrínseca: "Alcista: inflación 4.0%". No proviene de ningún modelo. Referencia de contexto: el promedio trimestral máximo del último año fue 4.33% (fila 38).
A8: Trayectoria Citi — Referencia | B8: 0.0393 | C8: 0.0383 | D8: 0.0375 | E8: 0.0375 | F8: 0.0375 | G8: 38.82 | H8: Referencia histórica (no es escenario) | I8: Encuesta Citi de Expectativas, 22-sep-2026: cierre 2026 3.93%, 2027 3.83%, promedio 2028–32 3.75% (comentario original de Proyección Final!C10). Pronóstico de consenso por año: REFERENCIA HISTÓRICA del modelo anterior, no escenario oficial.
A9: Tres escenarios oficiales; la trayectoria Citi es una referencia histórica (no es escenario). Cada uno re-ejecuta el modelo completo. Los escenarios constantes extienden a 2026E–2030E un pronóstico de un periodo: es un supuesto documentado. Mayor inflación eleva el valor porque el WACC nominal no cambia (no hay relación documentada inflación → Rf/WACC/beta/g).
A10: Fuente: Excel maestro · hoja Inflación §1 y §4 · Unidades: % anual · MXN por acción
A12: Tabla 6. Transmisión de la inflación a las ventas (escenario activo)
A13: Concepto | B13: 2026E | C13: 2027E | D13: 2028E | E13: 2029E | F13: 2030E
A14: Inflación aplicada | B14: 0.0351 | C14: 0.0351 | D14: 0.0351 | E14: 0.0351 | F14: 0.0351
A15: Crecimiento nominal del mercado | B15: 0.0021 | C15: 0.0291 | D15: 0.0401 | E15: 0.0451 | F15: 0.0451
A16: Crecimiento por variables externas | B16: -0.0389 | C16: 0.0061 | D16: 0.0346 | E16: 0.0441 | F16: 0.0466
A17: Crecimiento por mínimos cuadrados | B17: -0.0678 | C17: 0.0351 | D17: 0.0351 | E17: 0.0351 | F17: 0.0351
A18: Peso de variables externas | B18: 0.7 | C18: 0.7 | D18: 0.75 | E18: 0.8 | F18: 0.85
A19: Crecimiento final de ventas | B19: -0.0476 | C19: 0.0148 | D19: 0.0347 | E19: 0.0423 | F19: 0.0449
A20: Ventas | B20: 169070.4 | C20: 171572.6 | D20: 177530.5 | E20: 185040 | F20: 193343.7
A21: Margen EBIT (sin término de inflación) | B21: 0.0439 | C21: 0.0437 | D21: 0.0439 | E21: 0.0441 | F21: 0.0443
A22: Capex | B22: 3864.6 | C22: 3428.9 | D22: 3535.2 | E22: 3671.5 | F22: 3822.4
A23: FCF | B23: 5567.8 | C23: 5889.1 | D23: 6423.8 | E23: 6381.5 | F23: 6704.4
A24: Inflación → crecimiento nominal del mercado → variables externas → ponderación con mínimos cuadrados → ventas → FCF. Inflación aplicada (Inflación!B13:F13) Proyección Final!C10:G10 · → Crecimiento nominal del mercado Proyección Final!C14 · → Crecimiento por variables externas Proyección Final!C23 · → Ventas por mínimos cuadrados 2027E–2030E Proyección Final!D26:G26 · → Crecimiento final de ventas Proyección Final!C28 · → Ventas, costos, EBIT, impuestos, capital de trabajo Proyección Final!C67:G117 · → Valor (WACC no cambia con la inflación) Proyección Final!B265
A25: Fuente: Motor ValuFlow · réplica de Proyección Final filas 10–28 · Unidades: % · mdp
A27: Tabla 7. Modelos exponenciales de clase y = a·e^(b·x)
A28: Modelo | B28: n | C28: a | D28: b | E28: R² | F28: x siguiente | G28: Proyección (app) | H28: Excel
A29: Inmediata (último año, quincenal) | B29: 25 | C29: 3.9951 | D29: -0.005044 | E29: 0.104 | F29: 26 | G29: 0.03504 | H29: 0.03504
A30: Trimestral (4 promedios) → forecast Base | B30: 4 | C30: 4.0302 | D30: -0.027713 | E30: 0.092 | F30: 5 | G30: 0.03509 | H30: 0.03509
A31: Ventana larga 2023–2026 | B31: 89 | C31: 5.8812 | D31: -0.006334 | E31: 0.623 | F31: 90 | G31: 0.03326 | H31: 0.03326
A32: Libro de clase (coeficientes redondeados) | C32: 5.8812 | D32: -0.006 | G32: 0.03427 | H32: 0.03427
A33: Construcción de clase S113 (≈ Cautela) | G33: 0.03268 | H33: 0.03268
A34: Escenario Base = trimestral redondeado | G34: 0.0351 | H34: 0.0351
A35: Calculados por la app con la serie de Banxico y comparados contra el Excel. b = SLOPE(ln y, x); a = EXP(INTERCEPT(ln y, x)); R² = RSQ. R² bajo en los modelos de corto plazo: la tendencia explica poco de la variación.
A36: Fuente: Banxico SP74833 · Excel maestro hoja Inflación §3 · Unidades: n · coeficientes · %

Sheet 05 Beta y costo de la deuda
A1: 5. Beta y costo de la deuda
A2: Tablas numeradas como en el reporte técnico PDF. Caso base del Excel (inflación Base).
A3: Tabla 8. Beta del WACC: regresión semanal desapalancada (oficial)
A4: Concepto | B4: Valor | C4: Lectura
A5: Beta apalancada observada (βL, pendiente de la regresión) | B5: 0.2178 | C5: Regresión semanal (Investing.com); error típico 0.1269, t 1.716, p 0.0874, IC 95% −0.032 a 0.468
A6: Deuda / capitalización de la regresión | B6: 23,618 / 59,580 | C6: D/E 0.3964 · tasa 30%
A7: Beta desapalancada derivada (βU) | B7: 0.1705 | C7: βU = βL / [1 + (1 − t) × D/E] = 0.2178 / [1 + (1 − 30%) × 0.3964]. Supuesto oficial del WACC.
A8: βL observada de la regresión → βU con la estructura de capital de la propia regresión → se reapalanca con la del modelo (sin volver a usar la βL observada).
A9: Fuente: Excel maestro · hoja Beta y Kd §2 · Unidades: x · mdp · %
A11: Tabla 9. Beta sectorial de Damodaran (referencia, no usada)
A12: Concepto | B12: Valor | C12: Lectura
A13: Industria | B13: Retail (Grocery and Food) | C13: 215 empresas · muestra global
A14: Beta apalancada de la industria (βL) | B14: 0.87 | C14: Refleja la estructura de capital promedio de la industria (D/E 45.96%), no la de la empresa.
A15: Beta desapalancada (βU) | B15: 0.65 | C15: βU = βL / [1 + (1 − t) × D/E] con t marginal 25.37% → 0.6478 (control)
A16: βU corregida por caja | B16: 0.69 | C16: Beta oficial del equipo hasta el 19-oct-2026; hoy es referencia.
A17: βU heredada del modelo anterior | B17: 0.8 | C17: Solo reproduce el baseline histórico.
A18: Aswath Damodaran, NYU Stern Betas by Sector · Enero de 2026 · Retail (Grocery and Food) BETA DESAPALANCADA USADA EN EL WACC (βU) — regresión semanal desapalancada Menor βU → menor βL y Ke → menor WACC → mayor EV y precio. El cambio no altera los flujos (FCF) ni el puente. La βU de regresión se reapalanca con la D/E de este libro; la βL observada (0.2178) no se usa directamente. Referencia (NO usada): Ke con la βL de la industria 0.87 sin reapalancar
A19: Fuente: Damodaran (NYU Stern) · Excel maestro hoja Beta y Kd §1 · Unidades: x · %
A21: Tabla 10. Reapalancamiento con la estructura de capital de la empresa
A22: Concepto | B22: A valor de mercado | C22: Iterado al valor DCF
A23: βU usada | B23: 0.17 | C23: 0.17
A24: D/E | B24: 0.3919 | C24: 0.3283
A25: Tasa fiscal | B25: 0.3 | C25: 0.3
A26: βL reapalancada | B26: 0.2173 | C26: 0.2097
A27: Ke | B27: 0.1044 | C27: 0.104
A28: WACC | B28: 0.1006 | C28: 0.0956
A29: βL = βU × [1 + (1 − t) × D/E]; Ke = Rf + βL × PRM.
A30: Fuente: Motor ValuFlow · réplica de Beta y Kd §3 · Unidades: x · %
A32: Tabla 11. Impacto del cambio de beta (supuestos activos)
A33: Concepto | B33: βU 0.69 (Damodaran) | C33: βU 0.1705 | D33: Cambio
A34: βL iterada | B34: 0.9071 | C34: 0.2097 | D34: -0.6974
A35: Ke | B35: 0.1335 | C35: 0.104 | D35: −2.95 pp
A36: WACC | B36: 0.1138 | C36: 0.0956 | D36: −1.82 pp
A37: EV ponderado | B37: 67198.4 | C37: 79382.7 | D37: 12184.3
A38: Equity a la fecha de valuación | B38: 56910.4 | C38: 69012.1 | D38: 12101.7
A39: Precio DCF | B39: 31.62 | C39: 38.34 | D39: 6.72
A40: Recalculado con el modelo completo: misma proyección, distinta beta. La columna de referencia es la beta oficial anterior.
A41: Fuente: Motor ValuFlow · réplica de Beta y Kd §4 · Unidades: % · mdp · MXN
A43: Tabla 12. Costo de la deuda (Kd)
A44: Concepto | B44: Valor | C44: Lectura
...

Sheet 06 CAPM y WACC
A1: 6. CAPM y WACC
A2: Tablas numeradas como en el reporte técnico PDF. Caso base del Excel (inflación Base).
A3: Tabla 14. WACC · mercado vs. iterado
A4: Componente | B4: Valor de mercado | C4: Iterado al DCF
A5: Tasa libre de riesgo (Rf) | B5: 0.0952 | C5: 0.0952
A6: Prima de riesgo de mercado | B6: 0.0423 | C6: 0.0423
A7: Beta desapalancada (βU) | B7: 0.17 | C7: 0.17
A8: Deuda (D) | B8: 23618 | C8: 23618
A9: Capital (E) | B9: 60,264.0 · mercado | C9: 71,948.1 · DCF
A10: D / E | B10: 0.392 | C10: 0.328
A11: Beta apalancada βL | B11: 0.2173 | C11: 0.2097
A12: Ke = Rf + βL × PRM | B12: 0.1044 | C12: 0.104
A13: Kd antes de impuestos | B13: 0.1302 | C13: 0.1
A14: Tasa fiscal | B14: 0.3 | C14: 0.3
A15: Kd después de impuestos | B15: 0.0911 | C15: 0.07
A16: E / (D + E) | B16: 0.7184 | C16: 0.7529
A17: D / (D + E) | B17: 0.2816 | C17: 0.2471
A18: WACC | B18: 0.1006 | C18: 0.0956
A19: Componentes del costo de capital en ambos enfoques. Activo en el modelo: WACC iterado.
A20: Fuente: Excel · WACC e iteración · Unidades: % · mdp
A22: Tabla 15. Iteraciones
A23: Iteración | B23: WACC entrada | C23: Equity DCF | D23: D / E | E23: Beta | F23: Ke | G23: WACC salida
A24: Iteración 0 | B24: 0.1006 | C24: 65552.8 | D24: 0.3603 | E24: 0.2135 | F24: 0.1042 | G24: 0.0951
A25: Iteración 1 | B25: 0.0951 | C25: 72623.6 | D25: 0.3252 | E25: 0.2093 | F25: 0.104 | G25: 0.0957
A26: Iteración 2 | B26: 0.0957 | C26: 71882.5 | D26: 0.3286 | E26: 0.2097 | F26: 0.104 | G26: 0.0956
A27: Iteración 3 | B27: 0.0956 | C27: 71954.4 | D27: 0.3282 | E27: 0.2097 | F27: 0.104 | G27: 0.0956
A28: Iteración 4 | B28: 0.0956 | C28: 71947.4 | D28: 0.3283 | E28: 0.2097 | F28: 0.104 | G28: 0.0956
A29: Iteración 5 | B29: 0.0956 | C29: 71948.1 | D29: 0.3283 | E29: 0.2097 | F29: 0.104 | G29: 0.0956
A30: El equity del DCF alimenta D/E hasta converger.
A31: Fuente: Motor ValuFlow · Unidades: %

Sheet 07 Proyecciones operativas y FC
A1: 7. Proyecciones operativas y FCFF
A2: Tablas numeradas como en el reporte técnico PDF. Caso base del Excel (inflación Base).
A3: Tabla 16. Proyección de estados financieros
A4: Concepto | B4: 2025A | C4: 2026E | D4: 2027E | E4: 2028E | F4: 2029E | G4: 2030E
A5: Estado de resultados
A6: Ventas | B6: — | C6: 169070.4 | D6: 171572.6 | E6: 177530.5 | F6: 185040 | G6: 193343.7
A7: Costo de ventas | B7: — | C7: -127817.2 | D7: -129880.5 | E7: -134568.1 | F7: -140260.3 | G7: -146554.5
A8: Utilidad bruta | B8: — | C8: 41253.2 | D8: 41692.1 | E8: 42962.4 | F8: 44779.7 | G8: 46789.2
A9: Gastos de operación (sin D&A) | B9: — | C9: -29698.5 | D9: -30002.5 | E9: -30833.7 | F9: -32097.8 | G9: -33490.5
A10: EBITDA | B10: — | C10: 11554.6 | D10: 11689.6 | E10: 12128.7 | F10: 12681.8 | G10: 13298.7
A11: Depreciación y amortización | B11: — | C11: -4130.1 | D11: -4191.3 | E11: -4337.7 | F11: -4522.2 | G11: -4726.1
A12: Utilidad de operación (EBIT) | B12: — | C12: 7424.5 | D12: 7498.3 | E12: 7790.9 | F12: 8159.6 | G12: 8572.5
A13: Gastos financieros | B13: — | C13: -2361.8 | D13: -2302.8 | E13: -2156.5 | F13: -2010.3 | G13: -1864
A14: Utilidad antes de impuestos | B14: — | C14: 5062.7 | D14: 5195.6 | E14: 5634.4 | F14: 6149.4 | G14: 6708.5
A15: Impuestos a la utilidad | B15: — | C15: -1519.8 | D15: -1577.9 | E15: -1712.4 | F15: -1870.2 | G15: -2041.7
A16: Utilidad neta | B16: — | C16: 3542.9 | D16: 3617.7 | E16: 3922 | F16: 4279.2 | G16: 4666.8
A17: Dividendos pagados | B17: — | C17: -1063.4 | D17: -1085.8 | E17: -1177.2 | F17: -1284.4 | G17: -1400.7
A18: Balance general
A19: Efectivo y equivalentes | B19: — | C19: 12146.7 | D19: 13846.5 | E19: 16092 | F19: 18290.3 | G19: 20797.3
A20: Inventarios | B20: — | C20: 30816.2 | D20: 31313.6 | E20: 32075.1 | F20: 33431.9 | G20: 34932.2
A21: Otros activos circulantes | B21: — | C21: 6620.3 | D21: 6718.3 | E21: 6951.6 | F21: 7245.7 | G21: 7570.8
A22: Activo no circulante | B22: — | C22: 107243.5 | D22: 106481.1 | E22: 105678.5 | F22: 104827.8 | G22: 103924
A23: Activo total | B23: — | C23: 156826.7 | D23: 158359.5 | E23: 160797.3 | F23: 163795.7 | G23: 167224.4
A24: Pasivo circulante operativo | B24: — | C24: 33852.2 | D24: 34353.2 | E24: 35546.1 | F24: 37049.7 | G24: 38712.3
A25: Deuda bursátil y bancaria | B25: — | C25: 11500 | D25: 10000 | E25: 8500 | F25: 7000 | G25: 5500
A26: Pasivo por arrendamiento | B26: — | C26: 12118 | D26: 12118 | E26: 12118 | F26: 12118 | G26: 12118
A27: Otros pasivos a largo plazo | B27: — | C27: 12145 | D27: 12145 | E27: 12145 | F27: 12145 | G27: 12145
A28: Pasivo total | B28: — | C28: 69615.2 | D28: 68616.2 | E28: 68309.1 | F28: 68312.7 | G28: 68475.3
A29: Capital contable | B29: — | C29: 87211.5 | D29: 89743.3 | E29: 92488.2 | F29: 95483 | G29: 98749.1
A30: Comprobación (A − P − C) | B30: — | C30: 0 | D30: 0 | E30: 0 | F30: 0 | G30: 0
A31: Recalculada en vivo desde los drivers del Excel · inflación: Base.
A32: Fuente: Motor ValuFlow · réplica de Proyección Final · Unidades: mdp
A34: Tabla 17. Ponderación de métodos y supuestos finales
A35: Concepto | B35: 2026E | C35: 2027E | D35: 2028E | E35: 2029E | F35: 2030E
A36: Peso de variables externas | B36: 0.7 | C36: 0.7 | D36: 0.75 | E36: 0.8 | F36: 0.85
A37: Peso de mínimos cuadrados | B37: 0.3 | C37: 0.3 | D37: 0.25 | E37: 0.2 | F37: 0.15
A38: Crecimiento de ventas
A39: Variables externas | B39: -0.0389 | C39: 0.0061 | D39: 0.0346 | E39: 0.0441 | F39: 0.0466
A40: Mínimos cuadrados | B40: -0.0678 | C40: 0.0351 | D40: 0.0351 | E40: 0.0351 | F40: 0.0351
A41: Final (ponderado) | B41: -0.0476 | C41: 0.0148 | D41: 0.0347 | E41: 0.0423 | F41: 0.0449
...

Sheet 08 Valor terminal
A1: 8. Valor terminal
A2: Tablas numeradas como en el reporte técnico PDF. Caso base del Excel (inflación Base).
A3: Tabla 21. Valor terminal y su peso
A4: Concepto | B4: mdp
A5: FCF normalizado 2030E | B5: 5800.7
A6: Valor terminal Gordon | B6: 99025.3
A7: VP Gordon | B7: 62723.6
A8: Valor terminal múltiplo | B8: 77275.4
A9: VP múltiplo | B9: 48947
A10: VP valor terminal ponderado | B10: 55835.3
A11: Peso del valor terminal en el EV | B11: 0.703
A12: Fuente: Motor ValuFlow · Excel PRO auditado hoja Proyección Final

Sheet 09 Del Enterprise Value al prec
A1: 9. Del Enterprise Value al precio por acción
A2: Tablas numeradas como en el reporte técnico PDF. Caso base del Excel (inflación Base).
A3: Tabla 22. Del flujo al valor por acción
A4: Concepto | B4: Valor
A5: VPN de los FCF | B5: 23547.4
A6: FCF 2030E normalizado (NOPAT − ΔNWC) × (1 + g) | B6: 6003.7
A7: Valor terminal (Gordon) | B7: 99025.3
A8: VP del valor terminal (Gordon) | B8: 62723.6
A9: EV · Gordon | B9: 86271
A10: EBITDA 2030E × 5.81x | B10: 77275.4
A11: VP del valor terminal (múltiplo) | B11: 48947
A12: EV · múltiplos | B12: 72494.4
A13: EV ponderado (50% Gordon) | B13: 79382.7
A14: (−) Deuda bursátil y bancaria | B14: -11500
A15: (−) Pasivo por arrendamiento | B15: -12118
A16: (+) Efectivo | B16: 9295
... A27: Valor intrínseco por acción | B27: 38.34
A28: Puente completo de valuación.
A29: Fuente: Motor ValuFlow · Unidades: mdp

Sheet 10 Trading Comps
A1: 10. Trading Comps
A2: Tablas numeradas como en el reporte técnico PDF. Caso base del Excel (inflación Base).
A3: Tabla 23. Muestra y criterios: grupo comparable
A4: Empresa | B4: País | C4: Industria (CIQ) | D4: Clasificación | E4: Incluir | F4: Mg EBITDA | G4: Crec. ventas | H4: EV/Ventas | I4: EV/EBITDA | J4: EV/EBIT | K4: P/U | L4: Razón
A5: Grupo Comercial Chedraui, S.A.B. de C.V. (BMV:CHDRAUI B) | B5: Mexico | C5: Food Retail | D5: Incluir | E5: ✓ Sí | F5: 0.064 | G5: -0.034 | H5: 0.5 | I5: 5.7 | J5: 8.8 | K5: 13.1 | L5: Par más cercano: mismo formato y país; margen EBITDA (6.4%) y crecimiento (−3.4%) casi iguales a los de Soriana.
A6: Grupo Mateus S.A. (BOVESPA:GMAT3) | B6: Brazil | C6: Consumer Staples Merchandise Retail | D6: Incluir con reserva | E6: ✓ Sí | F6: 0.059 | G6: 0.187 | H6: 0.4 | I6: 5.3 | J6: 6.6 | K6: 4.7 | L6: Formato comparable; geografía (Brasil) y crecimiento (18.7%) distintos; P/U 4.7x atípico.
A7: El Puerto de Liverpool, S.A.B. de C.V. (BMV:LIVEPOL C-1) | B7: Mexico | C7: Broadline Retail | D7: Excluir | E7: — No | F7: 0.142 | G7: 0.03 | H7: 0.8 | I7: 4.9 | J7: 5.9 | K7: 8.2 | L7: Industria distinta (Broadline Retail); negocio financiero; margen EBITDA del doble (14.2%).
A8: Wal-Mart de México, S.A.B. de C.V. (BMV:WALMEX *) | B8: Mexico | C8: Consumer Staples Merchandise Retail | D8: Incluir con reserva | E8: ✓ Sí | F8: 0.096 | G8: 0.029 | H8: 0.9 | I8: 9.1 | J8: 12 | K8: 17.8 | L8: Competidor directo; 12 veces el tamaño de Soriana y líder del mercado (prima de múltiplo).
A9: La Comer, S.A.B. de C.V. (BMV:LACOMER UBC) | B9: Mexico | C9: Food Retail | D9: Incluir con reserva | E9: ✓ Sí | F9: 0.1 | G9: 0.086 | H9: 0.8 | I9: 7.4 | J9: 10.7 | K9: 14.6 | L9: Competidor directo; más pequeña, formato premium, más rentable (10.0%) y sin deuda neta.
A10: Sendas Distribuidora S.A. (BOVESPA:ASAI3) | B10: Brazil | C10: Consumer Staples Merchandise Retail | D10: Incluir con reserva | E10: ✓ Sí | F10: 0.078 | G10: 0.017 | H10: 0.4 | I10: 5.5 | J10: 7.6 | K10: 16.8 | L10: Formato comparable a City Club; Brasil; apalancamiento alto (4.0x) distorsiona P/U.
A11: Cencosud S.A. (SNSE:CENCOSUD) | B11: Chile | C11: Consumer Staples Merchandise Retail | D11: Incluir con reserva | E11: ✓ Sí | F11: 0.056 | G11: -0.016 | H11: 0.7 | I11: 9.3 | J11: 14 | K11: 21 | L11: Diversificada (Chile); EBITDA LTM −29.5% infla EV/EBITDA y EV/EBIT.
A12: InRetail Perú Corp. (BVL:INRETC1) | B12: Peru | C12: Consumer Staples Merchandise Retail | D12: Incluir con reserva | E12: ✓ Sí | F12: 0.11 | G12: 0.079 | H12: 0.9 | I12: 7 | J12: 10 | K12: 13.6 | L12: Multiformato (Perú) con negocios no comparables (farmacia, inmobiliario).
A13: Fomento Económico Mexicano, S.A.B. de C.V. (BMV:FEMSA UBD) | B13: Mexico | C13: Soft Drinks and Non-alcoholic Beverages | D13: Excluir | E13: — No | F13: 0.118 | G13: 0.074 | H13: 1.1 | I13: 7.5 | J13: 11.1 | K13: 25.9 | L13: Industria distinta (Soft Drinks); P/U 25.9x.
A14: Falabella S.A. (SNSE:FALABELLA) | B14: Chile | C14: Broadline Retail | D14: Excluir | E14: — No | F14: 0.127 | G14: 0.089 | H14: 1.5 | I14: 10.4 | J14: 12.8 | K14: 10.4 | L14: Industria distinta (Broadline Retail); negocio financiero.
A15: Revisión de comparabilidad por empresa (1 incluida, 6 con reserva, 3 excluidas). Solo las incluidas entran a los estadísticos. Clasificación del análisis de comparabilidad (Excel maestro, hoja Trading Comps). Múltiplos publicados por CIQ; no se recalculan ni se convierten divisas (los múltiplos no tienen unidades). NA = dato no disponible.
A16: Fuente: S&P Capital IQ · as-of 2026-06-30 · Unidades: múltiplos LTM (x) · márgenes %
A18: Tabla 24. Múltiplos: selección
A19: Múltiplo | B19: Tipo | C19: Métrica de Soriana | D19: Usar | E19: Estado | F19: Justificación
A20: EV/EBITDA LTM | B20: EV | C20: 11810.87 | D20: ✓ Sí | E20: Usado | F20: Múltiplo principal del sector (EV incluye arrendamientos; EBITDA post-NIIF 16).
A21: EV/EBIT LTM | B21: EV | C21: 7631 | D21: ✓ Sí | E21: Usado | F21: Complementa EV/EBITDA con la depreciación.
A22: P/U LTM | B22: P | C22: 2.12 | D22: ✓ Sí | E22: Usado | F22: Múltiplo de capital; utilidades LTM.
A23: EV/Ventas LTM | B23: EV | C23: 174278 | D23: — No | E23: Excluido | F23: Excluido: ignora el margen (los pares tienen márgenes EBITDA de 5.6% a 11%).
A24: P/VL tangible | B24: P | C24: NA | D24: NA | E24: NA | F24: Sin dato en la fuente.
A25: EV/EBITDA NTM | B25: EV | C25: NA | D25: NA | E25: NA | F25: Sin dato en la fuente.
A26: P/U NTM | B26: P | C26: NA | D26: NA | E26: NA | F26: Sin dato en la fuente.
A27: NM = calculable pero sin utilidad analítica (p. ej. capital implícito ≤ 0) · NA = falta el dato.
A28: Fuente: Excel maestro · Trading Comps §3
A30: Tabla 25. Estadísticos y precio implícito
A31: Estadístico | B31: EV/Ventas | C31: EV/EBITDA | D31: EV/EBIT | E31: P/U | F31: Precio EV/Ventas | G31: Precio EV/EBITDA | H31: Precio EV/EBIT | I31: Precio P/U
A32: Mínimo | B32: 0.4 | C32: 5.3 | D32: 6.6 | E32: 4.7 | F32: 29.37 | G32: 25.42 | H32: 18.62 | I32: 9.96
A33: Percentil 25 | B33: 0.45 | C33: 5.6 | D33: 8.2 | E33: 13.4 | F33: 34.21 | G33: 27.39 | H33: 25.4 | I33: 28.3
A34: Media | B34: 0.66 | C34: 7.04 | D34: 9.96 | E34: 14.5 | F34: 54.27 | G34: 36.85 | H34: 32.85 | I34: 30.77
A35: Mediana | B35: 0.7 | C35: 7 | D35: 10 | E35: 14.6 | F35: 58.42 | G35: 36.57 | H35: 33.04 | I35: 30.95
A36: Percentil 75 | B36: 0.85 | C36: 8.25 | D36: 11.4 | E36: 17.3 | F36: 72.94 | G36: 44.77 | H36: 38.76 | I36: 36.68
A37: Máximo | B37: 0.9 | C37: 9.3 | D37: 14 | E37: 21 | F37: 77.78 | G37: 51.66 | H37: 49.99 | I37: 44.52
A38: n | B38: 7 | C38: 7 | D38: 7 | E38: 7
A39: Precio = (múltiplo × métrica + ajuste neto) ÷ acciones; múltiplos de precio: múltiplo × UPA. Percentiles inclusivos. En gris: múltiplos no usados en el valor del método (se muestran para transparencia).
A40: Fuente: Motor ValuFlow · réplica de Trading Comps §4 · Unidades: x · MXN por acción
A42: Tabla 26. Del múltiplo al precio (a la media)
A43: Paso | B43: EV/Ventas | C43: EV/EBITDA | D43: EV/EBIT | E43: P/U
...

Sheet 11 Precedent Transactions (LSEG
A1: 11. Precedent Transactions (LSEG/SDC)
A2: Tablas numeradas como en el reporte técnico PDF. Caso base del Excel (inflación Base).
A3: Tabla 28. Búsqueda y selección de la muestra
A4: Paso | B4: Criterio | C4: Resultado
A5: Búsqueda inicial | B5: M&A de los últimos 3 años, autoservicio en México | C5: 0 operaciones con múltiplos: solo FEMSA como comprador (Delek, objetivo en EE.UU.) y Nutrisa, sin múltiplos.
A6: Primera ampliación | B6: Subir un nivel en la industria (Retail: Food & Beverage + Discount and Department Store) | C6: Sigue sin operaciones mexicanas con múltiplos.
A7: Segunda ampliación | B7: Eliminar el filtro geográfico → pantalla global | C7: 166 operaciones en la pantalla (Retail: Food & Beverage Retailing 130, Discount and Department Store Retailing 34, Food & Beverage 2). La subindustria de SDC mezcla restaurantes, servicios de alimentos y departamentales.
A8: Filtro del analista | B8: Objetivo que opera autoservicio, supermercados o mayoreo de alimentos | C8: 23 operaciones evaluadas abajo (19 de la versión original + 4 agregadas en la auditoría).
A9: Criterios objetivos | B9: Ventana de 3 años, ≥ 2 múltiplos, no recompra propia | C9: Columnas X–Z (fórmulas).
A10: Juicio del analista | B10: Adquisición real con control o participación estratégica relevante; calidad del dato; sin sanciones ni reestructura judicial | C10: Columna AA (naranja) y motivo.
A11: Ventana | B11: 3 años: 2023-10-01 a 2026-10-01 (fecha de valuación) | C11: 20 de 23 operaciones evaluadas dentro.
A12: Datos mínimos | B12: ≥ 2 múltiplos de valor (EV/EBITDA, P/E, EV/Ventas) | C12: 22 de 23 cumplen.
A13: Tipo de cambio | B13: 18.48 MXN por USD | C13: Implícito en S&P Capital IQ: capitalización 59,580 mdp / 3,223.7 USD mm al cierre del 7-oct-2026 (reporte comparativo, p. 1 y 25). Equivalente MXN solo informativo: los múltiplos no requieren conversión.
A14: Primero se buscó autoservicio en México; al no haber operaciones con múltiplos, se amplió la industria y luego la geografía (decisión metodológica documentada).
A15: Fuente: LSEG/SDC (Refinitiv) · GridExport_October_19_2026_9_29_57.pdf (2026-10-19 09:29:57)
A17: Tabla 29. Tabla definitiva de transacciones LSEG/SDC
A18: Objetivo | B18: Anuncio | C18: País | D18: Comprador | E18: Valor operación (USD mm) | F18: EV (USD mm) | G18: EV (MXN mm) | H18: EV/EBITDA | I18: EV/Ventas | J18: P/E | K18: Decisión
A19: Almacenes Exito SA | B19: 2023-10-16 | C19: Colombia | D19: Cama Commercial Group Corp | E19: 1020 | F19: 1744.5 | G19: 32238 | H19: 4.98 | I19: 0.34 | J19: NA | K19: Incluida
A20: Profi Rom Food Srl | B20: 2023-10-30 | C20: Romania | D20: Koninklijke Ahold Delhaize NV | E20: 1703.4 | F20: 1711.7 | G20: 31632 | H20: 21.3 | I20: 0.69 | J20: NA | K20: Incluida
A21: Lawson Inc | B21: 2024-02-06 | C21: Japan | D21: KDDI CORP | E21: 3339.6 | F21: 11027.1 | G21: 203780 | H21: 3.24 | I21: 0.9 | J21: 13.7 | K21: Incluida
A22: KANSAI FOOD MARKET LTD | B22: 2024-05-15 | C22: Japan | D22: H2O RETAILING CORP | E22: 234.3 | F22: 700.3 | G22: 12941 | H22: 7.64 | I22: 0.28 | J22: 18.5 | K22: Incluida
A23: Yonghui Superstores Co Ltd | B23: 2024-09-23 | C23: China (Mainland) | D23: Guangdong Juncai International Trading Co Ltd | E23: 889.3 | F23: 5614.1 | G23: 103748 | H23: 12.8 | I23: 0.53 | J23: NA | K23: Incluida
A24: Sun Art Retail Group Ltd | B24: 2025-01-01 | C24: Hong Kong | D24: Paragon Shine Ltd | E24: 1333.8 | F24: 824.1 | G24: 15229 | H24: 2.2 | I24: 0.08 | J24: NA | K24: Incluida
A25: METRO AG | B25: 2025-02-05 | C25: Germany | D25: EP Global Commerce GmbH | E25: 294.1 | F25: 5048.6 | G25: 93298 | H25: 5.11 | I25: 0.16 | J25: NA | K25: Incluida
A26: Seiyu Co Ltd | B26: 2025-03-05 | C26: Japan | D26: Trial Holdings Inc | E26: 2536.7 | F26: 2552.4 | G26: 47168 | H26: NA | I26: 0.69 | J26: 3.88 | K26: Incluida
A27: Chengdu Hongqi Chain Co Ltd | B27: 2023-12-21 | C27: China (Mainland) | D27: Sichuan Shangtou Investment Co Ltd | E27: 182.3 | F27: 957.3 | G27: 17692 | H27: 4.97 | I27: 0.67 | J27: 13.4 | K27: Incluida
A28: Seven & i Holdings Co Ltd | B28: 2023-11-30 | C28: Japan | D28: Seven & i Holdings Co Ltd | E28: 747.1 | F28: 23898.3 | G28: 441640 | H28: 3.36 | I28: 0.31 | J28: 11.1 | K28: Excluida
A29: Carrefour SA | B29: 2024-03-26 | C29: France | D29: Carrefour SA | E29: 395.5 | F29: 25430.6 | G29: 469957 | H29: 5.16 | I29: 0.28 | J29: 11.6 | K29: Excluida
A30: Seven & i Holdings Co Ltd | B30: 2025-04-09 | C30: Japan | D30: Seven & i Holdings Co Ltd | E30: 4101.7 | F30: 57481.8 | G30: 1062264 | H30: 8.74 | I30: 0.78 | J30: 17.4 | K30: Excluida
A31: J Sainsbury PLC | B31: 2025-11-07 | C31: United Kingdom | D31: J Sainsbury PLC | E31: 120.9 | F31: 13917.3 | G31: 257191 | H31: 4.71 | I31: 0.32 | J31: 17.5 | K31: Excluida
A32: YAOKO Co Ltd | B32: 2025-01-14 | C32: Japan | D32: YAOKO Co Ltd | E32: 2412.7 | F32: 2864.3 | G32: 52932 | H32: 10.7 | I32: 0.73 | J32: 20.8 | K32: Excluida
A33: Magnit PJSC | B33: 2023-10-10 | C33: Russia | D33: Magnit PJSC | E33: 180.4 | F33: 7977.5 | G33: 147424 | H33: 3.63 | I33: 0.32 | J33: 6.67 | K33: Excluida
A34: Gorodskoi Supermarket OOO | B34: 2025-04-30 | C34: Russia | D34: Tander AO | E34: 361.7 | F34: 478.1 | G34: 8835 | H34: NA | I34: 0.45 | J34: 44.8 | K34: Excluida
A35: Better Life Commercial Chain Share Co Ltd | B35: 2024-04-09 | C35: China (Mainland) | D35: Investor Group | E35: 345.7 | F35: 2318.3 | G35: 42841 | H35: 46 | I35: 5.64 | J35: NA | K35: Excluida
A36: Wincommerce General Commercial Services JSC | B36: 2024-09-04 | C36: Vietnam | D36: Masan Consumer Holdings Co Ltd | E36: 200 | F36: 2951.1 | G36: 54537 | H36: 323.1 | I36: 2.45 | J36: NA | K36: Excluida
A37: Prosol Gestion SAS | B37: 2025-12-16 | C37: France | D37: Apollo Global Management Inc | E37: 1727.5 | F37: 2464.1 | G37: 45537 | H37: NA | I37: 44.5 | J37: 33.8 | K37: Excluida
A38: Inageya Co Ltd | B38: 2023-04-25 | C38: Japan | D38: AEON CO LTD | E38: 170.1 | F38: 463.8 | G38: 8570 | H38: 10.3 | I38: 0.24 | J38: NA | K38: Excluida
A39: Casino Guichard-Perrachon SA | B39: 2023-04-24 | C39: France | D39: Investor Group | E39: 1347.2 | F39: 12843.1 | G39: 237341 | H39: 6.38 | I39: 0.4 | J39: NA | K39: Excluida
A40: Dia Portugal Supermercados SA | B40: 2023-08-03 | C40: Portugal | D40: Auchan Retail Portugal Sa | E40: 186 | F40: 186.2 | G40: 3440 | H40: 46.8 | I40: 0.29 | J40: NA | K40: Excluida
A41: Rimi Baltic AB | B41: 2025-03-05 | C41: Latvia | D41: Salling Group A/S | E41: 1381.1 | F41: NA | G41: NA | H41: NA | I41: NA | J41: 27.8 | K41: Excluida
...

Sheet 12 Contraste con S&P Capital IQ
A1: 12. Contraste con S&P Capital IQ y LSEG Refinitiv
A2: Tablas numeradas como en el reporte técnico PDF. Caso base del Excel (inflación Base).
A3: Tabla 34. Contraste con S&P Capital IQ, LSEG Refinitiv y otros modelos
A4: Fuente | B4: Método | C4: Fecha | D4: Precio por acción | E4: Rango | F4: Precio de referencia | G4: Diferencia | H4: ¿Entra al precio oficial? | I4: Supuestos principales | J4: Calidad y limitaciones | K4: Pág.
A5: Modelo del equipo (este libro) | B5: DCF (FCFF, 50% Gordon / 50% múltiplo, a la fecha de valuación) | C5: 01-oct-2026 | D5: 38.34 | E5: $37.93 – $39.14 | F5: $33.48 (25-sep-2026) | G5: 0.145 | H5: Sí (50%) | I5: βU 0.1705 (regresión semanal desapalancada; βL observada 0.2178), WACC iterado, g 3.5%, múltiplo de salida 5.81x | J5: Rango = escenarios de inflación Cautela–Alcista. | K5: —
A6: Modelo del equipo (este libro) | B6: Trading Comps (7 pares CIQ, promedio de 3 múltiplos a la media) | C6: 30-jun-2026 | D6: 33.49 | E6: $27.03 – $40.07 | F6: $33.48 (25-sep-2026) | G6: 0 | H6: Sí (50%) | I6: EV/EBITDA, EV/EBIT y P/U LTM; puente al 2T26 | J6: Múltiplos CIQ al 30-jun-2026; precio de mercado de otra fecha. | K6: —
