Workbook

Sheet Comparativo
A4: 1. VALUACIÓN (DCF, base FY2025) | B4: Soriana | C4: Walmex | D4: Chedraui | E4: La Comer
A5: WACC | B5: =Valuación!B15 -> 0.10063018 | C5: =Valuación!B53 -> 0.10255747 | D5: =Valuación!B91 -> 0.082995961 | E5: =Valuación!B129 -> 0.1009772
A6: Crecimiento perpetuo (g) | B6: =Valuación!B16 -> 0.035 | C6: =Valuación!B54 -> 0.035 | D6: =Valuación!B92 -> 0.035 | E6: =Valuación!B130 -> 0.035
A7: FCF 2025A (flujo libre de efectivo) | B7: =Valuación!B27 -> 6761.4 | C7: =Valuación!B65 -> 40916.76 | D7: =Valuación!B103 -> 12113.9 | E7: =Valuación!B141 -> 302.92442
A8: VPN de los FCF 2026E–2030E | B8: =Valuación!B31 -> 27698.206 | C8: =Valuación!B69 -> 169911.77 | D8: =Valuación!B107 -> 52976.897 | E8: =Valuación!B145 -> 1263.1284
A9: Valor terminal (TV) al 2030 | B9: =Valuación!B33 -> 124303.41 | C9: =Valuación!B71 -> 744509.04 | D9: =Valuación!B109 -> 310256.86 | E9: =Valuación!B147 -> 5643.9411
A10: Valor presente del TV | B10: =Valuación!B34 -> 76961.93 | C10: =Valuación!B72 -> 456944.87 | D10: =Valuación!B110 -> 208251.06 | E10: =Valuación!B148 -> 3488.9186
A11: Enterprise Value (EV) | B11: =Valuación!B35 -> 104660.14 | C11: =Valuación!B73 -> 626856.64 | D11: =Valuación!B111 -> 261227.95 | E11: =Valuación!B149 -> 4752.047
A12: Deuda total (bancaria/bursátil + arrendamientos) | B12: =-Valuación!B36 -> 23618 | C12: =-Valuación!B74 -> 80848.1 | D12: =-Valuación!B112 -> 56744.34 | E12: =-Valuación!B150 -> 2441.8
A13: Efectivo y equivalentes | B13: =Valuación!B37 -> 9295 | C13: =Valuación!B75 -> 28591.2 | D13: =Valuación!B113 -> 14640.16 | E13: =Valuación!B151 -> 2962.8
A14: Equity Value (valor para los accionistas) | B14: =Valuación!B39 -> 90337.136 | C14: =Valuación!B77 -> 574599.74 | D14: =Valuación!B115 -> 219123.77 | E14: =Valuación!B153 -> 5273.047
A15: Valor intrínseco por acción (MXN) | B15: =Valuación!B41 -> 50.187298 | C15: =Valuación!B79 -> 32.910034 | D15: =Valuación!B117 -> 228.19351 | E15: =Valuación!B155 -> 4.9476264
A16: Precio actual en bolsa (MXN) | B16: =Valuación!B42 -> 33.48 | C16: =Valuación!B80 -> 46.6 | D16: =Valuación!B118 -> 92.94 | E16: =Valuación!B156 -> 32.08
A17: Potencial de apreciación / (baja) | B17: =Valuación!B43 -> 0.49902323 | C17: =Valuación!B81 -> -0.29377609 | D17: =Valuación!B119 -> 1.4552777 | E17: =Valuación!B157 -> -0.84577224
A18: Precio objetivo consenso de analistas (MXN) | B18: =Generales!B24 -> 23.357 | C18: 60.094 | D18: 128.933 | E18: 47.67
A19: Recomendación consenso de analistas | B19: Venta (0 C / 1 M / 6 V) | C19: Neutral (5 C / 10 M / 3 V) | D19: Neutral (3 C / 12 M / 0 V) | E19: Compra (5 C / 4 M / 0 V)
A21: 2. RAZONES FINANCIERAS – PROMEDIO DE LOS ÚLTIMOS 5 TRIMESTRES | B21: Soriana | C21: Walmex | D21: Chedraui | E21: La Comer
A22: Circulante | B22: =Razones!G7 -> 1.2541889 | C22: =Razones!G23 -> 0.9768759 | D22: =Razones!G39 -> 0.933732 | E22: =Razones!G55 -> 1.2290463
A23: Prueba ácida | B23: =Razones!G8 -> 0.35473781 | C23: =Razones!G24 -> 0.34704511 | D23: =Razones!G40 -> 0.40675641 | E23: =Razones!G56 -> 0.48041577
A24: Deuda / Activo total | B24: =Razones!G9 -> 0.45505378 | C24: =Razones!G25 -> 0.52855776 | D24: =Razones!G41 -> 0.66310269 | E24: =Razones!G57 -> 0.2578378
A25: Capitalización a largo plazo | B25: =Razones!G10 -> 0.20654207 | C25: =Razones!G26 -> 0.18040972 | D25: =Razones!G42 -> 0.38012988 | E25: =Razones!G58 -> 0.064547002
A26: Cobertura de intereses | B26: =Razones!G11 -> 2.8984196 | C26: =Razones!G27 -> 6.6453315 | D26: =Razones!G43 -> 4.1504186 | E26: =Razones!G59 -> 11.844746
A27: Rotación del inventario (trimestral) | B27: =Razones!G12 -> 0.95612726 | C27: =Razones!G28 -> 1.7752133 | D27: =Razones!G44 -> 2.3833504 | E27: =Razones!G60 -> 1.3488695
A28: Rotación del inventario en días | B28: =Razones!G13 -> 96.032436 | C28: =Razones!G29 -> 51.658042 | D28: =Razones!G45 -> 38.380088 | E28: =Razones!G61 -> 67.850681
A29: Rotación del activo total (trimestral) | B29: =Razones!G14 -> 0.28166407 | C29: =Razones!G30 -> 0.51157675 | D29: =Razones!G46 -> 0.46365336 | E29: =Razones!G62 -> 0.2764494
A30: Margen bruto | B30: =Razones!G15 -> 0.24566153 | C30: =Razones!G31 -> 0.24235015 | D30: =Razones!G47 -> 0.23527548 | E30: =Razones!G63 -> 0.29672069
A31: Margen neto | B31: =Razones!G16 -> 0.020605935 | C31: =Razones!G32 -> 0.048260538 | D31: =Razones!G48 -> 0.023418786 | E31: =Razones!G64 -> 0.05488254
A32: ROA (trimestral) | B32: =Razones!G17 -> 0.005843019 | C32: =Razones!G33 -> 0.024728482 | D32: =Razones!G49 -> 0.010867202 | E32: =Razones!G65 -> 0.015156869
A33: ROE (trimestral) | B33: =Razones!G18 -> 0.010703389 | C33: =Razones!G34 -> 0.052476921 | D33: =Razones!G50 -> 0.032240332 | E33: =Razones!G66 -> 0.02043965
A34: ROI (trimestral) | B34: =Razones!G19 -> 0.012031436 | C34: =Razones!G35 -> 0.042432022 | D34: =Razones!G51 -> 0.024290294 | E34: =Razones!G67 -> 0.017861415
A36: 3. RAZONES FINANCIERAS ANUALES FY2025 (incluye Chedraui) | B36: Soriana | C36: Walmex | D36: Chedraui | E36: La Comer
A37: Circulante | B37: =IFERROR(Datos!G19/Datos!G21,"n.d.") -> 1.2373849 | C37: =IFERROR(Datos!G45/Datos!G47,"n.d.") -> 0.96696082 | D37: =IFERROR(Datos!G71/Datos!G73,"n.d.") -> 0.92079667 | E37: =IFERROR(Datos!G97/Datos!G99,"n.d.") -> 1.2070372
A38: Prueba ácida | B38: =IFERROR((Datos!G19-Datos!G18)/Datos!G21,"n.d.") -> 0.414238 | C38: =IFERROR((Datos!G45-Datos!G44)/Datos!G47,"n.d.") -> 0.33384163 | D38: =IFERROR((Datos!G71-Datos!G70)/Datos!G73,"n.d.") -> 0.43735523 | E38: =IFERROR((Datos!G97-Datos!G96)/Datos!G99,"n.d.") -> 0.50008921
A39: Deuda / Activo total | B39: =IFERROR(Datos!G23/Datos!G20,"n.d.") -> 0.45697843 | C39: =IFERROR(Datos!G49/Datos!G46,"n.d.") -> 0.52434323 | D39: =IFERROR(Datos!G75/Datos!G72,"n.d.") -> 0.67356639 | E39: =IFERROR(Datos!G101/Datos!G98,"n.d.") -> 0.2544825
A40: Capitalización a largo plazo | B40: =IFERROR(Datos!G22/Datos!G20,"n.d.") -> 0.2056294 | C40: =IFERROR(Datos!G48/Datos!G46,"n.d.") -> 0.1816704 | D40: =IFERROR(Datos!G74/Datos!G72,"n.d.") -> 0.37134872 | E40: =IFERROR(Datos!G100/Datos!G98,"n.d.") -> 0.06423617
A41: Cobertura de intereses | B41: =IFERROR(Datos!G9/Datos!G10,"n.d.") -> 2.4567339 | C41: =IFERROR(Datos!G35/Datos!G36,"n.d.") -> 6.8465638 | D41: =IFERROR(Datos!G61/Datos!G62,"n.d.") -> 3.9247028 | E41: =IFERROR(Datos!G87/Datos!G88,"n.d.") -> 13.400737
A42: Rotación del inventario (anual) | B42: =IFERROR(Datos!G7/Datos!G18,"n.d.") -> 4.1740854 | C42: =IFERROR(Datos!G33/Datos!G44,"n.d.") -> 7.1325601 | D42: =IFERROR(Datos!G59/Datos!G70,"n.d.") -> 9.7102302 | E42: =IFERROR(Datos!G85/Datos!G96,"n.d.") -> 5.6268631
A43: Rotación del inventario en días (365) | B43: =IFERROR(365*Datos!G18/Datos!G7,"n.d.") -> 87.444305 | C43: =IFERROR(365*Datos!G44/Datos!G33,"n.d.") -> 51.173772 | D43: =IFERROR(365*Datos!G70/Datos!G59,"n.d.") -> 37.589222 | E43: =IFERROR(365*Datos!G96/Datos!G85,"n.d.") -> 64.867404
A44: Rotación del activo total (anual) | B44: =IFERROR(Datos!G6/Datos!G20,"n.d.") -> 1.1376395 | C44: =IFERROR(Datos!G32/Datos!G46,"n.d.") -> 2.0425044 | D44: =IFERROR(Datos!G58/Datos!G72,"n.d.") -> 1.8415047 | E44: =IFERROR(Datos!G84/Datos!G98,"n.d.") -> 1.0755432
A45: Margen bruto | B45: =IFERROR(Datos!G8/Datos!G6,"n.d.") -> 0.24090359 | C45: =IFERROR(Datos!G34/Datos!G32,"n.d.") -> 0.24238672 | D45: =IFERROR(Datos!G60/Datos!G58,"n.d.") -> 0.22959264 | E45: =IFERROR(Datos!G86/Datos!G84,"n.d.") -> 0.29637336
...

Sheet Generales
A4: 1. INFORMACIÓN GENERAL DE LA EMPRESA | B4: Dato
A5: Clave de cotización | B5: SORIANA B (BMV, cotiza desde 1987)
A6: Fundación | B6: 1968, Torreón, Coahuila
A7: Sede corporativa | B7: Monterrey, Nuevo León
A8: Giro | B8: Tiendas de autoservicio y clubes de membresía (multiformato)
A9: Tiendas en operación (2T26) | B9: 812
A10: Colaboradores (jun-2026) | B10: 82064
A11: Acciones en circulación (millones) | B11: =WACC!B17 -> 1800
A12: Capitalización de mercado a precio actual (mdp) | B12: =WACC!B18 -> 60264
A14: 2. NOTICIAS Y ANÁLISIS RECIENTES | B14: Fecha
A15: Resultados 2T26: menos ventas, más utilidad | B15: 31-jul-2026
A16: Cierre de 20 tiendas en 2026 | B16: 26-ago-2026
A17: Reducción de plantilla y automatización | B17: 2-sep-2026
A18: Plan de inversión 2S26 | B18: sep-2026
A19: Sector: Walmart, Soriana y Chedraui sufren por ingresos e inflación | B19: 2026
A21: 3. CALIFICACIÓN Y CONSENSO DE ANALISTAS | B21: Dato
A22: Calificación crediticia (HR Ratings) | B22: HR+1 (corto plazo)
A23: Consenso de analistas | B23: Venta
A24: Precio objetivo promedio 12 meses (MXN) | B24: 23.357
A26: 4. ANÁLISIS FUNDAMENTAL – RESUMEN FINANCIERO FY2025 (mdp) | B26: Valor
A27: Ingresos totales | B27: =Datos!G6 -> 177515
A28: Utilidad bruta | B28: =Datos!G8 -> 42764
A29: Utilidad de operación (EBIT) | B29: =Datos!G9 -> 7552
A30: Utilidad neta consolidada | B30: =Datos!G13 -> 3334
A31: Margen bruto | B31: =Datos!G8/Datos!G6 -> 0.24090359
A32: Margen de operación | B32: =Datos!G9/Datos!G6 -> 0.042542884
A33: Margen neto | B33: =Datos!G13/Datos!G6 -> 0.018781511
A35: 5. CUENTA DE RESULTADOS – ÚLTIMO TRIMESTRE (2T26 vs 2T25, mdp) | B35: 2T26
A36: Ingresos totales | B36: =Datos!F6 -> 43559
A37: Costo de ventas | B37: =Datos!F7 -> 32919
A38: Utilidad bruta | B38: =Datos!F8 -> 10640
A39: Utilidad de operación | B39: =Datos!F9 -> 1855
A40: Gastos financieros | B40: =Datos!F10 -> 582
A41: Utilidad neta | B41: =Datos!F13 -> 1090
A43: 6. BALANCE (cierre 2025 vs 1T26, mdp) | B43: Dic-2025
A44: Activo total | B44: =Datos!G20 -> 156038
A45: Pasivo total | B45: =Datos!G23 -> 71306
A46: Capital contable | B46: =Datos!G24 -> 84732
A47: Deuda bancaria y bursátil | B47: =Datos!G25+Datos!G26 -> 11500
A48: Efectivo | B48: =Datos!G17 -> 9295
...

Sheet Datos
A5: ORGANIZACIÓN SORIANA (SORIANA B) | B5: 2T25 | C5: 3T25 | D5: 4T25 | E5: 1T26 | F5: 2T26 | G5: FY2025
A6: Ingresos totales | B6: 45810 | C6: 42683 | D6: 47592 | E6: 40444 | F6: 43559 | G6: 177515
A7: Costo de ventas | B7: 34856 | C7: 31998 | D7: 35795 | E7: 30466 | F7: 32919 | G7: 134752
A8: Utilidad bruta | B8: 10954 | C8: 10685 | D8: 11797 | E8: 9978 | F8: 10640 | G8: 42764
A9: Utilidad de operación (EBIT) | B9: 1909 | C9: 1468 | D9: 2486 | E9: 1822 | F9: 1855 | G9: 7552
A10: Gastos financieros (intereses) | B10: 829 | C10: 786 | D10: 616 | E10: 588 | F10: 582 | G10: 3074
A11: Utilidad antes de impuestos | B11: 1203 | C11: 764 | D11: 1763 | E11: 1326 | F11: 1372 | G11: 4766
A12: Impuestos a la utilidad | B12: 461 | C12: 179 | D12: 455 | E12: 492 | F12: 282 | G12: 1433
A13: Utilidad neta consolidada | B13: 743 | C13: 584 | D13: 1308 | E13: 834 | F13: 1090 | G13: 3334
A14: Depreciación y amortización | B14: 1105.905 | C14: 1049.349 | D14: 1051 | E14: 1048.889 | F14: 1030.633 | G14: 4342
A15: Flujo neto de operación (CFO) | B15: 4013.113 | C15: -205.9 | D15: 13017 | E15: -3565.6 | F15: 3916.003 | G15: 13738
A16: Capex (inmuebles, equipo e intangibles) | B16: =SUM(B110:B112) -> 663.2 | C16: =SUM(C110:C112) -> 775.2 | D16: =SUM(D110:D112) -> 816 | E16: =SUM(E110:E112) -> 501 | F16: =SUM(F110:F112) -> 909.9 | G16: 2867
A17: Efectivo y equivalentes | B17: 7540 | C17: 5798 | D17: 9295 | E17: 4589 | F17: 6875.384 | G17: =D17 -> 9295
A18: Inventarios | B18: 37421 | C18: 36394 | D18: 32283 | E18: 32635 | F18: 35486.661 | G18: =D18 -> 32283
A19: Activo circulante | B19: 52131 | C19: 49767 | D19: 48529 | E19: 43562 | F19: 49259.847 | G19: =D19 -> 48529
A20: Activo total | B20: 159842 | C20: 157502 | D20: 156038 | E20: 150941 | F20: =F23+F24 -> 156813 | G20: =D20 -> 156038
A21: Pasivo circulante | B21: 41065 | C21: 38190 | D21: 39219 | E21: 33850 | F21: 41957.933 | G21: =D21 -> 39219
A22: Pasivo a largo plazo | B22: 34801 | C22: 34753 | D22: 32086 | E22: 31527 | F22: =F23-F21 -> 28201.067 | G22: =D22 -> 32086
A23: Pasivo total | B23: 75866 | C23: 72943 | D23: 71306 | E23: 65377 | F23: 70159 | G23: =D23 -> 71306
A24: Capital contable | B24: 83976 | C24: 84559 | D24: 84732 | E24: 85564 | F24: 86654 | G24: =D24 -> 84732
A25: Deuda bursátil y bancaria CP | B25: 6627 | C25: 6553 | D25: 3000 | E25: 3000 | F25: 6500 | G25: =D25 -> 3000
A26: Deuda bursátil y bancaria LP | B26: 11500 | C26: 11500 | D26: 8500 | E26: 8500 | F26: 5000 | G26: =D26 -> 8500
A27: Pasivo por arrendamiento CP | B27: 638 | C27: 659 | D27: 676 | E27: 683 | F27: 639.968 | G27: =D27 -> 676
A28: Pasivo por arrendamiento LP | B28: 11389 | C28: 11506 | D28: 11442 | E28: 11540 | F28: 11580.62 | G28: =D28 -> 11442
A29: Deuda total (financiera + arrendamientos) | B29: =IF(COUNT(B25:B28)=4,SUM(B25:B28),"n.d.") -> 30154 | C29: =IF(COUNT(C25:C28)=4,SUM(C25:C28),"n.d.") -> 30218 | D29: =IF(COUNT(D25:D28)=4,SUM(D25:D28),"n.d.") -> 23618 | E29: =IF(COUNT(E25:E28)=4,SUM(E25:E28),"n.d.") -> 23723 | F29: =IF(COUNT(F25:F28)=4,SUM(F25:F28),"n.d.") -> 23720.588 | G29: =IF(COUNT(G25:G28)=4,SUM(G25:G28),"n.d.") -> 23618
A31: WALMART DE MÉXICO (WALMEX) | B31: 2T25 | C31: 3T25 | D31: 4T25 | E31: 1T26 | F31: 2T26 | G31: FY2025
A32: Ingresos totales | B32: 246253.8 | C32: 241520.2 | D32: 282849.3 | E32: 245018.5 | F32: 250947.8 | G32: 1011597.9
A33: Costo de ventas | B33: 186848.1 | C33: 181746.3 | D33: 214905.4 | E33: 185425.3 | F33: 190822.8 | G33: 766400
A34: Utilidad bruta | B34: 59405.7 | C34: 59773.8 | D34: 67943.9 | E34: 59593.2 | F34: 60125 | G34: 245197.9
A35: Utilidad de operación (EBIT) | B35: 17267.1 | C35: 19020.8 | D35: 23317 | E35: 18471.6 | F35: 17019.7 | G35: 78493.8
A36: Gastos financieros (intereses) | B36: 2646.3 | C36: 3223.3 | D36: 2795.1 | E36: 2895.6 | F36: 2799.6 | G36: 11464.7
A37: Utilidad antes de impuestos | B37: 15076.8 | C37: 16328 | D37: 21053.3 | E37: 16176.4 | F37: 14754.6 | G37: 68876.6
A38: Impuestos a la utilidad | B38: 3849.9 | C38: 4580.7 | D38: 6453.5 | E38: 3676.9 | F38: 3602.2 | G38: 18985.9
A39: Utilidad neta consolidada | B39: 11226.9 | C39: 11747.3 | D39: 14599.8 | E39: 12499.6 | F39: 11152.4 | G39: 49890.7
A40: Depreciación y amortización | B40: 6227.732 | C40: 6245.37 | D40: 6277.929 | E40: 6506.919 | F40: 6620.741 | G40: 24953.1
A41: Flujo neto de operación (CFO) | B41: 21549.377 | C41: 22017.152 | D41: 43314.63 | E41: 4955.647 | F41: 18326.104 | G41: 82437.7
A42: Capex (inmuebles, equipo e intangibles) | B42: =SUM(B113:B115) -> 7989.7 | C42: =SUM(C113:C115) -> 11746.3 | D42: =SUM(D113:D115) -> 15831.8 | E42: =SUM(E113:E115) -> 2436.5 | F42: =SUM(F113:F115) -> 9264.9 | G42: 38982
A43: Efectivo y equivalentes | B43: 32443.8 | C43: 35181.7 | D43: 28591.2 | E43: 28085.1 | F43: 30118.3 | G43: =D43 -> 28591.2
A44: Inventarios | B44: 106742.4 | C44: 113238.4 | D44: 107450.9 | E44: 106202 | F44: 107528.9 | G44: =D44 -> 107450.9
A45: Activo circulante | B45: 166663.9 | C45: 176974.1 | D45: 164109.4 | E45: 163317.9 | F45: 168653.5 | G45: =D45 -> 164109.4
...

Sheet Razones
A3: Días del trimestre | B3: 91.25
A6: ORGANIZACIÓN SORIANA | B6: 2T25 | C6: 3T25 | D6: 4T25 | E6: 1T26 | F6: 2T26 | G6: Promedio 5T
A7: Circulante | B7: =Datos!B19/Datos!B21 -> 1.2694752 | C7: =Datos!C19/Datos!C21 -> 1.3031422 | D7: =Datos!D19/Datos!D21 -> 1.2373849 | E7: =Datos!E19/Datos!E21 -> 1.2869129 | F7: =Datos!F19/Datos!F21 -> 1.1740294 | G7: =AVERAGE(B7:F7) -> 1.2541889
A8: Prueba ácida | B8: =(Datos!B19-Datos!B18)/Datos!B21 -> 0.35821259 | C8: =(Datos!C19-Datos!C18)/Datos!C21 -> 0.3501702 | D8: =(Datos!D19-Datos!D18)/Datos!D21 -> 0.414238 | E8: =(Datos!E19-Datos!E18)/Datos!E21 -> 0.3228065 | F8: =(Datos!F19-Datos!F18)/Datos!F21 -> 0.32826179 | G8: =AVERAGE(B8:F8) -> 0.35473781
A9: Deuda / Activo total | B9: =Datos!B23/Datos!B20 -> 0.4746312 | C9: =Datos!C23/Datos!C20 -> 0.46312428 | D9: =Datos!D23/Datos!D20 -> 0.45697843 | E9: =Datos!E23/Datos!E20 -> 0.4331295 | F9: =Datos!F23/Datos!F20 -> 0.44740551 | G9: =AVERAGE(B9:F9) -> 0.45505378
A10: Capitalización a largo plazo | B10: =Datos!B22/Datos!B20 -> 0.21772125 | C10: =Datos!C22/Datos!C20 -> 0.22065117 | D10: =Datos!D22/Datos!D20 -> 0.2056294 | E10: =Datos!E22/Datos!E20 -> 0.20886969 | F10: =Datos!F22/Datos!F20 -> 0.17983883 | G10: =AVERAGE(B10:F10) -> 0.20654207
A11: Cobertura de intereses | B11: =Datos!B9/Datos!B10 -> 2.3027744 | C11: =Datos!C9/Datos!C10 -> 1.8676845 | D11: =Datos!D9/Datos!D10 -> 4.0357143 | E11: =Datos!E9/Datos!E10 -> 3.0986395 | F11: =Datos!F9/Datos!F10 -> 3.1872852 | G11: =AVERAGE(B11:F11) -> 2.8984196
A12: Rotación del inventario | B12: =Datos!B7/Datos!B18 -> 0.9314556 | C12: =Datos!C7/Datos!C18 -> 0.87921086 | D12: =Datos!D7/Datos!D18 -> 1.1087879 | E12: =Datos!E7/Datos!E18 -> 0.93353761 | F12: =Datos!F7/Datos!F18 -> 0.92764433 | G12: =AVERAGE(B12:F12) -> 0.95612726
A13: Rotación del inventario en días | B13: =$B$3*Datos!B18/Datos!B7 -> 97.964949 | C13: =$B$3*Datos!C18/Datos!C7 -> 103.78625 | D13: =$B$3*Datos!D18/Datos!D7 -> 82.297074 | E13: =$B$3*Datos!E18/Datos!E7 -> 97.746463 | F13: =$B$3*Datos!F18/Datos!F7 -> 98.367442 | G13: =AVERAGE(B13:F13) -> 96.032436
A14: Rotación del activo total | B14: =Datos!B6/Datos!B20 -> 0.28659551 | C14: =Datos!C6/Datos!C20 -> 0.27099973 | D14: =Datos!D6/Datos!D20 -> 0.30500263 | E14: =Datos!E6/Datos!E20 -> 0.26794575 | F14: =Datos!F6/Datos!F20 -> 0.27777671 | G14: =AVERAGE(B14:F14) -> 0.28166407
A15: Margen bruto | B15: =Datos!B8/Datos!B6 -> 0.2391181 | C15: =Datos!C8/Datos!C6 -> 0.25033386 | D15: =Datos!D8/Datos!D6 -> 0.24787779 | E15: =Datos!E8/Datos!E6 -> 0.2467115 | F15: =Datos!F8/Datos!F6 -> 0.2442664 | G15: =AVERAGE(B15:F15) -> 0.24566153
A16: Margen neto | B16: =Datos!B13/Datos!B6 -> 0.016219166 | C16: =Datos!C13/Datos!C6 -> 0.013682262 | D16: =Datos!D13/Datos!D6 -> 0.027483611 | E16: =Datos!E13/Datos!E6 -> 0.020621106 | F16: =Datos!F13/Datos!F6 -> 0.025023531 | G16: =AVERAGE(B16:F16) -> 0.020605935
A17: Rentabilidad sobre activos (ROA) | B17: =Datos!B13/Datos!B20 -> 0.0046483402 | C17: =Datos!C13/Datos!C20 -> 0.0037078894 | D17: =Datos!D13/Datos!D20 -> 0.0083825735 | E17: =Datos!E13/Datos!E20 -> 0.0055253377 | F17: =Datos!F13/Datos!F20 -> 0.0069509543 | G17: =AVERAGE(B17:F17) -> 0.005843019
A18: Rentabilidad sobre capital (ROE) | B18: =Datos!B13/Datos!B24 -> 0.008847766 | C18: =Datos!C13/Datos!C24 -> 0.0069064204 | D18: =Datos!D13/Datos!D24 -> 0.015436907 | E18: =Datos!E13/Datos!E24 -> 0.0097470899 | F18: =Datos!F13/Datos!F24 -> 0.012578762 | G18: =AVERAGE(B18:F18) -> 0.010703389
A19: ROI (rendimiento sobre la inversión) | B19: =Datos!B9*(1-WACC!$B$10)/(Datos!B24+Datos!B29) -> 0.011708578 | C19: =Datos!C9*(1-WACC!$B$10)/(Datos!C24+Datos!C29) -> 0.0089530132 | D19: =Datos!D9*(1-WACC!$B$10)/(Datos!D24+Datos!D29) -> 0.016060914 | E19: =Datos!E9*(1-WACC!$B$10)/(Datos!E24+Datos!E29) -> 0.01167019 | F19: =Datos!F9*(1-WACC!$B$10)/(Datos!F24+Datos!F29) -> 0.011764483 | G19: =AVERAGE(B19:F19) -> 0.012031436
A22: WALMART DE MÉXICO | B22: 2T25 | C22: 3T25 | D22: 4T25 | E22: 1T26 | F22: 2T26 | G22: Promedio 5T
A23: Circulante | B23: =Datos!B45/Datos!B47 -> 0.94074612 | C23: =Datos!C45/Datos!C47 -> 0.94965349 | D23: =Datos!D45/Datos!D47 -> 0.96696082 | E23: =Datos!E45/Datos!E47 -> 1.0628517 | F23: =Datos!F45/Datos!F47 -> 0.96416733 | G23: =AVERAGE(B23:F23) -> 0.9768759
A24: Prueba ácida | B24: =(Datos!B45-Datos!B44)/Datos!B47 -> 0.33823113 | C24: =(Datos!C45-Datos!C44)/Datos!C47 -> 0.34200954 | D24: =(Datos!D45-Datos!D44)/Datos!D47 -> 0.33384163 | E24: =(Datos!E45-Datos!E44)/Datos!E47 -> 0.37170287 | F24: =(Datos!F45-Datos!F44)/Datos!F47 -> 0.34944038 | G24: =AVERAGE(B24:F24) -> 0.34704511
A25: Deuda / Activo total | B25: =Datos!B49/Datos!B46 -> 0.54768727 | C25: =Datos!C49/Datos!C46 -> 0.55072672 | D25: =Datos!D49/Datos!D46 -> 0.52434323 | E25: =Datos!E49/Datos!E46 -> 0.49165014 | F25: =Datos!F49/Datos!F46 -> 0.52838145 | G25: =AVERAGE(B25:F25) -> 0.52855776
A26: Capitalización a largo plazo | B26: =Datos!B48/Datos!B46 -> 0.1793358 | C26: =Datos!C48/Datos!C46 -> 0.17601614 | D26: =Datos!D48/Datos!D46 -> 0.1816704 | E26: =Datos!E48/Datos!E46 -> 0.18237576 | F26: =Datos!F48/Datos!F46 -> 0.1826505 | G26: =AVERAGE(B26:F26) -> 0.18040972
A27: Cobertura de intereses | B27: =Datos!B35/Datos!B36 -> 6.5249972 | C27: =Datos!C35/Datos!C36 -> 5.9010331 | D27: =Datos!D35/Datos!D36 -> 8.3420987 | E27: =Datos!E35/Datos!E36 -> 6.379196 | F27: =Datos!F35/Datos!F36 -> 6.0793328 | G27: =AVERAGE(B27:F27) -> 6.6453315
A28: Rotación del inventario | B28: =Datos!B33/Datos!B44 -> 1.7504581 | C28: =Datos!C33/Datos!C44 -> 1.6049882 | D28: =Datos!D33/Datos!D44 -> 2.0000335 | E28: =Datos!E33/Datos!E44 -> 1.7459681 | F28: =Datos!F33/Datos!F44 -> 1.7746187 | G28: =AVERAGE(B28:F28) -> 1.7752133
A29: Rotación del inventario en días | B29: =$B$3*Datos!B44/Datos!B33 -> 52.129211 | C29: =$B$3*Datos!C44/Datos!C33 -> 56.853999 | D29: =$B$3*Datos!D44/Datos!D33 -> 45.624236 | E29: =$B$3*Datos!E44/Datos!E33 -> 52.26327 | F29: =$B$3*Datos!F44/Datos!F33 -> 51.419496 | G29: =AVERAGE(B29:F29) -> 51.658042
A30: Rotación del activo total | B30: =Datos!B32/Datos!B46 -> 0.5120074 | C30: =Datos!C32/Datos!C46 -> 0.48562929 | D30: =Datos!D32/Datos!D46 -> 0.57109741 | E30: =Datos!E32/Datos!E46 -> 0.49315304 | F30: =Datos!F32/Datos!F46 -> 0.49599661 | G30: =AVERAGE(B30:F30) -> 0.51157675
A31: Margen bruto | B31: =Datos!B34/Datos!B32 -> 0.2412377 | C31: =Datos!C34/Datos!C32 -> 0.24748986 | D31: =Datos!D34/Datos!D32 -> 0.24021237 | E31: =Datos!E34/Datos!E32 -> 0.24321919 | F31: =Datos!F34/Datos!F32 -> 0.23959166 | G31: =AVERAGE(B31:F31) -> 0.24235015
A32: Margen neto | B32: =Datos!B39/Datos!B32 -> 0.045590769 | C32: =Datos!C39/Datos!C32 -> 0.048638996 | D32: =Datos!D39/Datos!D32 -> 0.051616886 | E32: =Datos!E39/Datos!E32 -> 0.051014923 | F32: =Datos!F39/Datos!F32 -> 0.044441115 | G32: =AVERAGE(B32:F32) -> 0.048260538
A33: Rentabilidad sobre activos (ROA) | B33: =Datos!B39/Datos!B46 -> 0.023342811 | C33: =Datos!C39/Datos!C46 -> 0.023620521 | D33: =Datos!D39/Datos!D46 -> 0.02947827 | E33: =Datos!E39/Datos!E46 -> 0.025158164 | F33: =Datos!F39/Datos!F46 -> 0.022042642 | G33: =AVERAGE(B33:F33) -> 0.024728482
A34: Rentabilidad sobre capital (ROE) | B34: =Datos!B39/Datos!B50 -> 0.051607681 | C34: =Datos!C39/Datos!C50 -> 0.052574952 | D34: =Datos!D39/Datos!D50 -> 0.061973825 | E34: =Datos!E39/Datos!E50 -> 0.049489862 | F34: =Datos!F39/Datos!F50 -> 0.046738286 | G34: =AVERAGE(B34:F34) -> 0.052476921
A35: ROI (rendimiento sobre la inversión) | B35: =Datos!B35*(1-WACC!$B$10)/(Datos!B50+Datos!B55) -> 0.040789751 | C35: =Datos!C35*(1-WACC!$B$10)/(Datos!C50+Datos!C55) -> 0.044024636 | D35: =Datos!D35*(1-WACC!$B$10)/(Datos!D50+Datos!D55) -> 0.051581686 | E35: =Datos!E35*(1-WACC!$B$10)/(Datos!E50+Datos!E55) -> 0.038731558 | F35: =Datos!F35*(1-WACC!$B$10)/(Datos!F50+Datos!F55) -> 0.037032482 | G35: =AVERAGE(B35:F35) -> 0.042432022
A38: GRUPO COMERCIAL CHEDRAUI | B38: 2T25 | C38: 3T25 | D38: 4T25 | E38: 1T26 | F38: 2T26 | G38: Promedio 5T
A39: Circulante | B39: =Datos!B71/Datos!B73 -> 0.93752294 | C39: =Datos!C71/Datos!C73 -> 0.95713938 | D39: =Datos!D71/Datos!D73 -> 0.92079666 | E39: =Datos!E71/Datos!E73 -> 0.9544518 | F39: =Datos!F71/Datos!F73 -> 0.89874924 | G39: =AVERAGE(B39:F39) -> 0.933732
A40: Prueba ácida | B40: =(Datos!B71-Datos!B70)/Datos!B73 -> 0.39513349 | C40: =(Datos!C71-Datos!C70)/Datos!C73 -> 0.41636525 | D40: =(Datos!D71-Datos!D70)/Datos!D73 -> 0.4373552 | E40: =(Datos!E71-Datos!E70)/Datos!E73 -> 0.40756856 | F40: =(Datos!F71-Datos!F70)/Datos!F73 -> 0.37735957 | G40: =AVERAGE(B40:F40) -> 0.40675641
A41: Deuda / Activo total | B41: =Datos!B75/Datos!B72 -> 0.66825911 | C41: =Datos!C75/Datos!C72 -> 0.66779606 | D41: =Datos!D75/Datos!D72 -> 0.67356636 | E41: =Datos!E75/Datos!E72 -> 0.65443675 | F41: =Datos!F75/Datos!F72 -> 0.65145515 | G41: =AVERAGE(B41:F41) -> 0.66310269
A42: Capitalización a largo plazo | B42: =Datos!B74/Datos!B72 -> 0.39551004 | C42: =Datos!C74/Datos!C72 -> 0.38822334 | D42: =Datos!D74/Datos!D72 -> 0.37134872 | E42: =Datos!E74/Datos!E72 -> 0.37751111 | F42: =Datos!F74/Datos!F72 -> 0.36805622 | G42: =AVERAGE(B42:F42) -> 0.38012988
A43: Cobertura de intereses | B43: =Datos!B61/Datos!B62 -> 4.8239802 | C43: =Datos!C61/Datos!C62 -> 3.9665961 | D43: =Datos!D61/Datos!D62 -> 3.3924674 | E43: =Datos!E61/Datos!E62 -> 4.0683276 | F43: =Datos!F61/Datos!F62 -> 4.5007216 | G43: =AVERAGE(B43:F43) -> 4.1504186
A44: Rotación del inventario | B44: =Datos!B59/Datos!B70 -> 2.4460256 | C44: =Datos!C59/Datos!C70 -> 2.3003665 | D44: =Datos!D59/Datos!D70 -> 2.5751122 | E44: =Datos!E59/Datos!E70 -> 2.2333551 | F44: =Datos!F59/Datos!F70 -> 2.3618924 | G44: =AVERAGE(B44:F44) -> 2.3833504
A45: Rotación del inventario en días | B45: =$B$3*Datos!B70/Datos!B59 -> 37.305414 | C45: =$B$3*Datos!C70/Datos!C59 -> 39.667592 | D45: =$B$3*Datos!D70/Datos!D59 -> 35.435349 | E45: =$B$3*Datos!E70/Datos!E59 -> 40.857811 | F45: =$B$3*Datos!F70/Datos!F59 -> 38.634275 | G45: =AVERAGE(B45:F45) -> 38.380088
A46: Rotación del activo total | B46: =Datos!B58/Datos!B72 -> 0.47699053 | C46: =Datos!C58/Datos!C72 -> 0.46117305 | D46: =Datos!D58/Datos!D72 -> 0.46906086 | E46: =Datos!E58/Datos!E72 -> 0.44674119 | F46: =Datos!F58/Datos!F72 -> 0.46430118 | G46: =AVERAGE(B46:F46) -> 0.46365336
A47: Margen bruto | B47: =Datos!B60/Datos!B58 -> 0.24137742 | C47: =Datos!C60/Datos!C58 -> 0.24587416 | D47: =Datos!D60/Datos!D58 -> 0.19789599 | E47: =Datos!E60/Datos!E58 -> 0.24288897 | F47: =Datos!F60/Datos!F58 -> 0.24834085 | G47: =AVERAGE(B47:F47) -> 0.23527548
A48: Margen neto | B48: =Datos!B65/Datos!B58 -> 0.027913029 | C48: =Datos!C65/Datos!C58 -> 0.022940047 | D48: =Datos!D65/Datos!D58 -> 0.017869485 | E48: =Datos!E65/Datos!E58 -> 0.02268417 | F48: =Datos!F65/Datos!F58 -> 0.025687198 | G48: =AVERAGE(B48:F48) -> 0.023418786
...

Sheet WACC
A3: Concepto | B3: Soriana | C3: Walmex | D3: Chedraui | E3: La Comer
A4: PARÁMETROS DE MERCADO
A5: Tasa libre de riesgo (Bono M 10 años) | B5: 0.09517 | C5: =$B$5 -> 0.09517 | D5: =$B$5 -> 0.09517 | E5: =$B$5 -> 0.09517
A6: Prima de riesgo de mercado madura | B6: 0.0423 | C6: =$B$6 -> 0.0423 | D6: =$B$6 -> 0.0423 | E6: =$B$6 -> 0.0423
A7: Prima de riesgo país México (referencia) | B7: 0.0246 | C7: =$B$7 -> 0.0246 | D7: =$B$7 -> 0.0246 | E7: =$B$7 -> 0.0246
A8: Prima de riesgo de mercado aplicada (PRM) | B8: =B6 -> 0.0423 | C8: =C6 -> 0.0423 | D8: =D6 -> 0.0423 | E8: =E6 -> 0.0423
A9: Beta desapalancada usada (regresión semanal Soriana B vs. IPC, desapalancada; ver hoja 'Beta y Kd' §2). Damodaran 0.69 queda como referencia | B9: ='Beta y Kd'!B19 -> 0.17052082 | C9: =$B$9 -> 0.17052082 | D9: =$B$9 -> 0.17052082 | E9: =$B$9 -> 0.17052082 | F9: Beta histórica del estudio (regresión): ver hoja Inflación, sección 6.
A10: Tasa de impuestos (ISR) | B10: 0.3 | C10: =$B$10 -> 0.3 | D10: =$B$10 -> 0.3 | E10: =$B$10 -> 0.3
A12: DATOS DE MERCADO
A13: Precio actual por acción (MXN) | B13: 33.48 | C13: 46.6 | D13: 92.94 | E13: 32.08
A14: Fecha del precio | B14: 46290 | C14: 46266 | D14: 21-ago-2026 | E14: 46266
A15: Capitalización de mercado reportada | B15: 54180 | C15: 801750 | D15: 89150 | E15: 34190
A16: Precio de cierre asociado a esa capitalización (MXN) | B16: 30.1 | C16: 45.92 | D16: 92.84 | E16: 32.08
A17: Acciones en circulación (millones) | B17: =B15/B16 -> 1800 | C17: =C15/C16 -> 17459.713 | D17: =D15/D16 -> 960.2542 | E17: =E15/E16 -> 1065.7731
A18: Valor de mercado del capital (E) | B18: =B17*B13 -> 60264 | C18: =C17*C13 -> 813622.6 | D18: =D17*D13 -> 89246.025 | E18: =E17*E13 -> 34190
A20: ESTRUCTURA DE CAPITAL (cierre 2025)
A21: Deuda total (D) = bancaria/bursátil + arrendamientos | B21: =Datos!G29 -> 23618 | C21: =Datos!G55 -> 80848.1 | D21: =Datos!G81 -> 56744.34 | E21: =Datos!G107 -> 2441.8
A22: Efectivo y equivalentes | B22: =Datos!G17 -> 9295 | C22: =Datos!G43 -> 28591.2 | D22: =Datos!G69 -> 14640.16 | E22: =Datos!G95 -> 2962.8
A23: D / E | B23: =B21/B18 -> 0.39190893 | C23: =C21/C18 -> 0.09936806 | D23: =D21/D18 -> 0.63581924 | E23: =E21/E18 -> 0.071418543
A24: Peso de la deuda D/(D+E) | B24: =B21/(B21+B18) -> 0.28156219 | C24: =C21/(C21+C18) -> 0.090386526 | D24: =D21/(D21+D18) -> 0.38868551 | E24: =E21/(E21+E18) -> 0.066657931
A25: Peso del capital E/(D+E) | B25: =B18/(B21+B18) -> 0.71843781 | C25: =C18/(C21+C18) -> 0.90961347 | D25: =D18/(D21+D18) -> 0.61131449 | E25: =E18/(E21+E18) -> 0.93334207
A27: COSTO DE CAPITAL
A28: Beta apalancada βL = βU × [1 + (1−t)·D/E] | B28: =B9*(1+(1-B10)*B23) -> 0.21730086 | C28: =C9*(1+(1-C10)*C23) -> 0.18238184 | D28: =D9*(1+(1-D10)*D23) -> 0.24641511 | E28: =E9*(1+(1-E10)*E23) -> 0.17904566
A29: Costo del capital propio Ke = Rf + βL × PRM | B29: =B5+B28*B8 -> 0.10436183 | C29: =C5+C28*C8 -> 0.10288475 | D29: =D5+D28*D8 -> 0.10559336 | E29: =E5+E28*E8 -> 0.10274363
A30: Gastos financieros FY2025 | B30: =Datos!G10 -> 3074 | C30: =Datos!G36 -> 11464.7 | D30: =Datos!G62 -> 3846.89 | E30: =Datos!G88 -> 265.96
A31: Costo de la deuda antes de impuestos Kd | B31: =B30/B21 -> 0.13015497 | C31: =C30/C21 -> 0.14180544 | D31: =D30/D21 -> 0.067793369 | E31: =E30/E21 -> 0.10891965
A32: Costo de la deuda después de impuestos Kd(1−t) | B32: =B31*(1-B10) -> 0.091108477 | C32: =C31*(1-C10) -> 0.099263805 | D32: =D31*(1-D10) -> 0.047455359 | E32: =E31*(1-E10) -> 0.076243755
A33: WACC = E/(D+E)·Ke + D/(D+E)·Kd(1−t) | B33: =B25*B29+B24*B32 -> 0.10063018 | C33: =C25*C29+C24*C32 -> 0.10255747 | D33: =D25*D29+D24*D32 -> 0.082995961 | E33: =E25*E29+E24*E32 -> 0.1009772
A35: CONCILIACIÓN CON EL WACC OFICIAL DEL DCF
A36: WACC oficial (iterado al valor DCF, Kd prospectivo) — usado en la valuación | B36: ='Proyección Final Soriana'!B126 -> 0.095627784
A37: WACC de referencia a valor de mercado (esta hoja, Kd histórico) | B37: =B33 -> 0.10063018
A38: Diferencia (referencia − oficial) | B38: =B37-B36 -> 0.0050023999
A39: Kd histórico FY2025 = gastos financieros / deuda | B39: =B31 -> 0.13015497
A40: Kd prospectivo usado en el DCF | B40: ='Proyección Final Soriana'!B206 -> 0.1
A41: Kd implícito 1S26 = (intereses 1T26 + 2T26) × 2 / deuda | B41: =(Datos!E10+Datos!F10)*2/B21 -> 0.099076975
A42: Lectura: el WACC oficial es el iterado. El de esta hoja usa pesos de mercado y el Kd de 2025 (tasas más altas); el Kd implícito del 1S26 respalda el 10% prospectivo.

Sheet Valuación
A4: Crecimiento perpetuo (g) para valor terminal | B4: 0.035
A5: Crecimiento anual de ventas 2026E–2030E (supuesto base) | B5: 0.035
A8: ORGANIZACIÓN SORIANA | B8: 2025A | C8: 2026E | D8: 2027E | E8: 2028E | F8: 2029E | G8: 2030E
A9: Crecimiento anual de ventas (explícito) | B9: =$B$5 -> 0.035
A10: Margen EBIT | B10: =Datos!G9/Datos!G6 -> 0.042542884
A11: Depreciación y amortización (% ventas) | B11: =Datos!G14/Datos!G6 -> 0.024459905
A12: Capex (% ventas) | B12: =Datos!G16/Datos!G6 -> 0.016150748
A13: Inversión en capital de trabajo (% del incremento en ventas) | B13: =-SUM('Proyección Soriana'!C64:G64)/('Proyección Soriana'!G19-'Proyección Soriana'!B19) -> 0.020792609
A14: Tasa de impuestos | B14: =WACC!B10 -> 0.3
A15: WACC | B15: =WACC!B33 -> 0.10063018
A16: Crecimiento perpetuo (g) | B16: =$B$4 -> 0.035
A18: PROYECCIÓN DEL FLUJO LIBRE DE EFECTIVO (FCF) | B18: 2025A | C18: 2026E | D18: 2027E | E18: 2028E | F18: 2029E | G18: 2030E
A19: Periodo (n) | B19: 0 | C19: 1 | D19: 2 | E19: 3 | F19: 4 | G19: 5
A20: Ventas | B20: =Datos!G6 -> 177515 | C20: =B20*(1+$B$9) -> 183728.02 | D20: =C20*(1+$B$9) -> 190158.51 | E20: =D20*(1+$B$9) -> 196814.05 | F20: =E20*(1+$B$9) -> 203702.55 | G20: =F20*(1+$B$9) -> 210832.13
A21: Utilidad de operación (EBIT) | B21: =Datos!G9 -> 7552 | C21: =C20*$B$10 -> 7816.32 | D21: =D20*$B$10 -> 8089.8912 | E21: =E20*$B$10 -> 8373.0374 | F21: =F20*$B$10 -> 8666.0937 | G21: =G20*$B$10 -> 8969.407
A22: (−) Impuestos sobre EBIT | B22: =-B21*$B$14 -> -2265.6 | C22: =-C21*$B$14 -> -2344.896 | D22: =-D21*$B$14 -> -2426.9674 | E22: =-E21*$B$14 -> -2511.9112 | F22: =-F21*$B$14 -> -2599.8281 | G22: =-G21*$B$14 -> -2690.8221
A23: NOPAT (EBIT después de impuestos) | B23: =B21+B22 -> 5286.4 | C23: =C21+C22 -> 5471.424 | D23: =D21+D22 -> 5662.9238 | E23: =E21+E22 -> 5861.1262 | F23: =F21+F22 -> 6066.2656 | G23: =G21+G22 -> 6278.5849
A24: (+) Depreciación y amortización | B24: =Datos!G14 -> 4342 | C24: =C20*$B$11 -> 4493.97 | D24: =D20*$B$11 -> 4651.259 | E24: =E20*$B$11 -> 4814.053 | F24: =F20*$B$11 -> 4982.5449 | G24: =G20*$B$11 -> 5156.9339
A25: (−) Capex | B25: =-Datos!G16 -> -2867 | C25: =-C20*$B$12 -> -2967.345 | D25: =-D20*$B$12 -> -3071.2021 | E25: =-E20*$B$12 -> -3178.6941 | F25: =-F20*$B$12 -> -3289.9484 | G25: =-G20*$B$12 -> -3405.0966
A26: (−) Inversión en capital de trabajo | B26: 0 | C26: =-(C20-B20)*$B$13 -> -129.185 | D26: =-(D20-C20)*$B$13 -> -133.70648 | E26: =-(E20-D20)*$B$13 -> -138.3862 | F26: =-(F20-E20)*$B$13 -> -143.22972 | G26: =-(G20-F20)*$B$13 -> -148.24276
A27: FCF – Flujo libre de efectivo | B27: =B23+B24+B25+B26 -> 6761.4 | C27: =C23+C24+C25+C26 -> 6868.864 | D27: =D23+D24+D25+D26 -> 7109.2742 | E27: =E23+E24+E25+E26 -> 7358.0988 | F27: =F23+F24+F25+F26 -> 7615.6323 | G27: =G23+G24+G25+G26 -> 7882.1794
A28: Factor de descuento 1/(1+WACC)^n | C28: =1/(1+$B$15)^C19 -> 0.90857039 | D28: =1/(1+$B$15)^D19 -> 0.82550016 | E28: =1/(1+$B$15)^E19 -> 0.75002501 | F28: =1/(1+$B$15)^F19 -> 0.68145052 | G28: =1/(1+$B$15)^G19 -> 0.61914576
A29: Valor presente del FCF | C29: =C27*C28 -> 6240.8465 | D29: =D27*D28 -> 5868.707 | E29: =E27*E28 -> 5518.7581 | F29: =F27*F28 -> 5189.6766 | G29: =G27*G28 -> 4880.218
A31: VPN de los FCF 2026E–2030E | B31: =SUM(C29:G29) -> 27698.206
A32: FCF del año 6 (2031E) | B32: =G27*(1+B16) -> 8158.0557
A33: Valor terminal (TV) al cierre de 2030 | B33: =B32/(B15-B16) -> 124303.41
A34: Valor presente del TV | B34: =B33*G28 -> 76961.93
A35: ENTERPRISE VALUE (EV) | B35: =B31+B34 -> 104660.14
A36: (−) Deuda total (bancaria/bursátil + arrendamientos) | B36: =-WACC!B21 -> -23618
A37: (+) Efectivo y equivalentes | B37: =WACC!B22 -> 9295
A38: Deuda neta | B38: =-(B36+B37) -> 14323
A39: EQUITY VALUE (valor para los accionistas) | B39: =B35+B36+B37 -> 90337.136
A40: Acciones en circulación (millones) | B40: =WACC!B17 -> 1800
A41: Valor intrínseco por acción (MXN) | B41: =B39/B40 -> 50.187298 | D41: Precio modelo integrado | E41: ='Proyección Soriana'!B85 -> 50.181165
A42: Precio actual en bolsa (MXN) | B42: =WACC!B13 -> 33.48 | D42: Diferencia vs integrado | E42: =B41-E41 -> 0.0061328489
A43: Potencial de apreciación / (baja) | B43: =B41/B42-1 -> 0.49902323 | D43: Diferencia (%) | E43: =B41/E41-1 -> 0.00012221416
A44: Peso del valor terminal en el EV | B44: =B34/B35 -> 0.73535094
A46: WALMART DE MÉXICO | B46: 2025A | C46: 2026E | D46: 2027E | E46: 2028E | F46: 2029E | G46: 2030E
A47: Crecimiento anual de ventas (explícito) | B47: =$B$5 -> 0.035
A48: Margen EBIT | B48: =Datos!G35/Datos!G32 -> 0.077593874
...

Sheet Proyección Soriana
A3: SUPUESTOS | B3: 2025A | C3: 2026E | D3: 2027E | E3: 2028E | F3: 2029E | G3: 2030E
A4: Crecimiento de ventas | C4: =Valuación!$B$9 -> 0.035 | D4: =Valuación!$B$9 -> 0.035 | E4: =Valuación!$B$9 -> 0.035 | F4: =Valuación!$B$9 -> 0.035 | G4: =Valuación!$B$9 -> 0.035
A5: Costo de ventas (% ventas) | B5: =-B20/B19 -> 0.75910205 | C5: =$B5 -> 0.75910205 | D5: =$B5 -> 0.75910205 | E5: =$B5 -> 0.75910205 | F5: =$B5 -> 0.75910205 | G5: =$B5 -> 0.75910205
A6: Gastos de operación sin D&A (% ventas) | B6: =-B22/B19 -> 0.1739008 | C6: =$B6 -> 0.1739008 | D6: =$B6 -> 0.1739008 | E6: =$B6 -> 0.1739008 | F6: =$B6 -> 0.1739008 | G6: =$B6 -> 0.1739008
A7: Depreciación y amortización (% ventas) | B7: =-B24/B19 -> 0.024459905 | C7: =$B7 -> 0.024459905 | D7: =$B7 -> 0.024459905 | E7: =$B7 -> 0.024459905 | F7: =$B7 -> 0.024459905 | G7: =$B7 -> 0.024459905
A8: Capex (% ventas) | B8: =Datos!G16/Datos!G6 -> 0.016150748 | C8: =$B8 -> 0.016150748 | D8: =$B8 -> 0.016150748 | E8: =$B8 -> 0.016150748 | F8: =$B8 -> 0.016150748 | G8: =$B8 -> 0.016150748
A9: Tasa de interés implícita (% deuda + arrendamientos) | B9: =-B26/(B41+B42) -> 0.13015497 | C9: =$B9 -> 0.13015497 | D9: =$B9 -> 0.13015497 | E9: =$B9 -> 0.13015497 | F9: =$B9 -> 0.13015497 | G9: =$B9 -> 0.13015497
A10: Tasa de impuestos | B10: =Valuación!$B$14 -> 0.3 | C10: =$B10 -> 0.3 | D10: =$B10 -> 0.3 | E10: =$B10 -> 0.3 | F10: =$B10 -> 0.3 | G10: =$B10 -> 0.3
A11: Días de inventario (sobre costo de ventas) | B11: =-B35/B20*365 -> 87.444305 | C11: =$B11 -> 87.444305 | D11: =$B11 -> 87.444305 | E11: =$B11 -> 87.444305 | F11: =$B11 -> 87.444305 | G11: =$B11 -> 87.444305
A12: Otros activos circulantes (% ventas) | B12: =B36/B19 -> 0.039157254 | C12: =$B12 -> 0.039157254 | D12: =$B12 -> 0.039157254 | E12: =$B12 -> 0.039157254 | F12: =$B12 -> 0.039157254 | G12: =$B12 -> 0.039157254
A13: Pasivo circulante operativo (% ventas) | B13: =B40/B19 -> 0.20022533 | C13: =$B13 -> 0.20022533 | D13: =$B13 -> 0.20022533 | E13: =$B13 -> 0.20022533 | F13: =$B13 -> 0.20022533 | G13: =$B13 -> 0.20022533
A14: Dividendos (% utilidad neta) | B14: =Generales!B62*Valuación!B40/B30 -> 0.30014406 | C14: =$B14 -> 0.30014406 | D14: =$B14 -> 0.30014406 | E14: =$B14 -> 0.30014406 | F14: =$B14 -> 0.30014406 | G14: =$B14 -> 0.30014406
A15: WACC | C15: =Valuación!$B$15 -> 0.10063018 | D15: =Valuación!$B$15 -> 0.10063018 | E15: =Valuación!$B$15 -> 0.10063018 | F15: =Valuación!$B$15 -> 0.10063018 | G15: =Valuación!$B$15 -> 0.10063018
A16: Crecimiento perpetuo (g) | C16: =Valuación!$B$16 -> 0.035 | D16: =Valuación!$B$16 -> 0.035 | E16: =Valuación!$B$16 -> 0.035 | F16: =Valuación!$B$16 -> 0.035 | G16: =Valuación!$B$16 -> 0.035
A18: 1. ESTADO DE RESULTADOS | B18: 2025A | C18: 2026E | D18: 2027E | E18: 2028E | F18: 2029E | G18: 2030E
A19: Ventas | B19: =Datos!G6 -> 177515 | C19: =B19*(1+C4) -> 183728.02 | D19: =C19*(1+D4) -> 190158.51 | E19: =D19*(1+E4) -> 196814.05 | F19: =E19*(1+F4) -> 203702.55 | G19: =F19*(1+G4) -> 210832.13
A20: Costo de ventas | B20: =-Datos!G7 -> -134752 | C20: =-C19*C5 -> -139468.32 | D20: =-D19*D5 -> -144349.71 | E20: =-E19*E5 -> -149401.95 | F20: =-F19*F5 -> -154631.02 | G20: =-G19*G5 -> -160043.11
A21: Utilidad bruta | B21: =B19+B20 -> 42763 | C21: =C19+C20 -> 44259.705 | D21: =D19+D20 -> 45808.795 | E21: =E19+E20 -> 47412.102 | F21: =F19+F20 -> 49071.526 | G21: =G19+G20 -> 50789.029
A22: Gastos de operación (sin D&A) | B22: =-(Datos!G8-Datos!G9-Datos!G14) -> -30870 | C22: =-C19*C6 -> -31950.45 | D22: =-D19*D6 -> -33068.716 | E22: =-E19*E6 -> -34226.121 | F22: =-F19*F6 -> -35424.035 | G22: =-G19*G6 -> -36663.876
A23: EBITDA | B23: =B21+B22 -> 11893 | C23: =C21+C22 -> 12309.255 | D23: =D21+D22 -> 12740.079 | E23: =E21+E22 -> 13185.982 | F23: =F21+F22 -> 13647.491 | G23: =G21+G22 -> 14125.153
A24: Depreciación y amortización | B24: =-Datos!G14 -> -4342 | C24: =-C19*C7 -> -4493.97 | D24: =-D19*D7 -> -4651.259 | E24: =-E19*E7 -> -4814.053 | F24: =-F19*F7 -> -4982.5449 | G24: =-G19*G7 -> -5156.9339
A25: Utilidad de operación (EBIT) | B25: =B23+B24 -> 7551 | C25: =C23+C24 -> 7815.285 | D25: =D23+D24 -> 8088.82 | E25: =E23+E24 -> 8371.9287 | F25: =F23+F24 -> 8664.9462 | G25: =G23+G24 -> 8968.2193
A26: Gastos financieros | B26: =-Datos!G10 -> -3074 | C26: =-C9*(B41+B42) -> -3074 | D26: =-D9*(C41+C42) -> -3074 | E26: =-E9*(D41+D42) -> -3074 | F26: =-F9*(E41+E42) -> -3074 | G26: =-G9*(F41+F42) -> -3074
A27: Otros ingresos (gastos) netos | B27: =Datos!G11-Datos!G9+Datos!G10 -> 288 | C27: 0 | D27: 0 | E27: 0 | F27: 0 | G27: 0
A28: Utilidad antes de impuestos | B28: =B25+B26+B27 -> 4765 | C28: =C25+C26+C27 -> 4741.285 | D28: =D25+D26+D27 -> 5014.82 | E28: =E25+E26+E27 -> 5297.9287 | F28: =F25+F26+F27 -> 5590.9462 | G28: =G25+G26+G27 -> 5894.2193
A29: Impuestos a la utilidad | B29: =-Datos!G12 -> -1433 | C29: =-C28*C10 -> -1422.3855 | D29: =-D28*D10 -> -1504.446 | E29: =-E28*E10 -> -1589.3786 | F29: =-F28*F10 -> -1677.2839 | G29: =-G28*G10 -> -1768.2658
A30: Utilidad neta | B30: =B28+B29 -> 3332 | C30: =C28+C29 -> 3318.8995 | D30: =D28+D29 -> 3510.374 | E30: =E28+E29 -> 3708.5501 | F30: =F28+F29 -> 3913.6623 | G30: =G28+G29 -> 4125.9535
A31: Dividendos pagados | C31: =-C30*C14 -> -996.14796 | D31: =-D30*D14 -> -1053.6179 | E31: =-E30*E14 -> -1113.0993 | F31: =-F30*F14 -> -1174.6625 | G31: =-G30*G14 -> -1238.3804
A33: 2. BALANCE GENERAL | B33: 2025A | C33: 2026E | D33: 2027E | E33: 2028E | F33: 2029E | G33: 2030E
A34: Efectivo y equivalentes | B34: =Datos!G17 -> 9295 | C34: =B34+C56 -> 13015.192 | D34: =C34+D56 -> 16918.298 | E34: =D34+E56 -> 21010.721 | F34: =E34+F56 -> 25299.088 | G34: =F34+G56 -> 29790.256
A35: Inventarios | B35: =Datos!G18 -> 32283 | C35: =-C20*C11/365 -> 33412.905 | D35: =-D20*D11/365 -> 34582.357 | E35: =-E20*E11/365 -> 35792.739 | F35: =-F20*F11/365 -> 37045.485 | G35: =-G20*G11/365 -> 38342.077
A36: Otros activos circulantes | B36: =Datos!G19-Datos!G17-Datos!G18 -> 6951 | C36: =C19*C12 -> 7194.285 | D36: =D19*D12 -> 7446.085 | E36: =E19*E12 -> 7706.6979 | F36: =F19*F12 -> 7976.4324 | G36: =G19*G12 -> 8255.6075
A37: Activo circulante | B37: =SUM(B34:B36) -> 48529 | C37: =SUM(C34:C36) -> 53622.382 | D37: =SUM(D34:D36) -> 58946.74 | E37: =SUM(E34:E36) -> 64510.159 | F37: =SUM(F34:F36) -> 70321.005 | G37: =SUM(G34:G36) -> 76387.94
A38: Activo no circulante | B38: =Datos!G20-Datos!G19 -> 107509 | C38: =B38-C54+C24 -> 105982.38 | D38: =C38-D54+D24 -> 104402.32 | E38: =D38-E54+E24 -> 102766.96 | F38: =E38-F54+F24 -> 101074.36 | G38: =F38-G54+G24 -> 99322.526
A39: Activo total | B39: =B37+B38 -> 156038 | C39: =C37+C38 -> 159604.76 | D39: =D37+D38 -> 163349.06 | E39: =E37+E38 -> 167277.12 | F39: =F37+F38 -> 171395.37 | G39: =G37+G38 -> 175710.47
A40: Pasivo circulante operativo (proveedores y otros) | B40: =Datos!G21-Datos!G25-Datos!G27 -> 35543 | C40: =C19*C13 -> 36787.005 | D40: =D19*D13 -> 38074.55 | E40: =E19*E13 -> 39407.159 | F40: =F19*F13 -> 40786.41 | G40: =G19*G13 -> 42213.934
A41: Deuda bursátil y bancaria | B41: =Datos!G25+Datos!G26 -> 11500 | C41: =B41 -> 11500 | D41: =C41 -> 11500 | E41: =D41 -> 11500 | F41: =E41 -> 11500 | G41: =F41 -> 11500
A42: Pasivo por arrendamiento | B42: =Datos!G27+Datos!G28 -> 12118 | C42: =B42 -> 12118 | D42: =C42 -> 12118 | E42: =D42 -> 12118 | F42: =E42 -> 12118 | G42: =F42 -> 12118
A43: Otros pasivos a largo plazo | B43: =Datos!G23-Datos!G21-Datos!G26-Datos!G28 -> 12145 | C43: =B43 -> 12145 | D43: =C43 -> 12145 | E43: =D43 -> 12145 | F43: =E43 -> 12145 | G43: =F43 -> 12145
A44: Pasivo total | B44: =SUM(B40:B43) -> 71306 | C44: =SUM(C40:C43) -> 72550.005 | D44: =SUM(D40:D43) -> 73837.55 | E44: =SUM(E40:E43) -> 75170.159 | F44: =SUM(F40:F43) -> 76549.41 | G44: =SUM(G40:G43) -> 77976.934
...

Sheet MC Soriana
A3: 1. FCFF PROYECTADO — MÍNIMOS CUADRADOS (sin ajustes externos)
A4: Concepto | B4: 3T26 | C4: 4T26 | D4: 1T27 | E4: 2T27 | F4: LTM proyectado (3T26–2T27) | G4: LTM actual (3T25–2T26) | H4: Variación vs. LTM actual
A5: X (pronóstico) | B5: =I39 -> 3 | C5: =I40 -> 4 | D5: =I41 -> 5 | E5: =I42 -> 6
A6: Ventas | B6: =J39 -> 41995.3 | C6: =J40 -> 41321.2 | D6: =J41 -> 40647.1 | E6: =J42 -> 39973 | F6: =SUM(B6:E6) -> 163936.6 | G6: =SUM(Datos!C6:F6) -> 174278 | H6: =IFERROR((F6-G6)/ABS(G6),"") -> -0.059338528
A7: Costos y gastos operativos | B7: =J56 -> 40013.5 | C7: =J57 -> 39314.8 | D7: =J58 -> 38616.1 | E7: =J59 -> 37917.4 | F7: =SUM(B7:E7) -> 155861.8 | G7: =SUM(Datos!C6:F6)-SUM(Datos!C9:F9) -> 166647 | H7: =IFERROR((F7-G7)/ABS(G7),"") -> -0.064718837
A8: EBIT | B8: =B6-B7 -> 1981.8 | C8: =C6-C7 -> 2006.4 | D8: =D6-D7 -> 2031 | E8: =E6-E7 -> 2055.6 | F8: =SUM(B8:E8) -> 8074.8 | G8: =G6-G7 -> 7631 | H8: =IFERROR((F8-G8)/ABS(G8),"") -> 0.058157515
A9: Margen EBIT | B9: =B8/B6 -> 0.047190995 | C9: =C8/C6 -> 0.048556189 | D9: =D8/D6 -> 0.049966664 | E9: =E8/E6 -> 0.051424712 | F9: =F8/F6 -> 0.049255627 | G9: =G8/G6 -> 0.043786364
A10: Tasa de impuesto | B10: =J73 -> 0.22485563 | C10: =J74 -> 0.20299653 | D10: =J75 -> 0.18113743 | E10: =J76 -> 0.15927832 | F10: =1-F11/F8 -> 0.19173401 | G10: =SUM(Datos!C12:F12)/SUM(Datos!C11:F11) -> 0.26947368
A11: EBIT (1 − T) | B11: =B8*(1-B10) -> 1536.1811 | C11: =C8*(1-C10) -> 1599.1078 | D11: =D8*(1-D10) -> 1663.1099 | E11: =E8*(1-E10) -> 1728.1875 | F11: =SUM(B11:E11) -> 6526.5862 | G11: =G8*(1-G10) -> 5574.6463 | H11: =IFERROR((F11-G11)/ABS(G11),"") -> 0.17076239
A12: (+) Depreciación y amortización | B12: =J90 -> 1011.854 | C12: =J91 -> 996.7536 | D12: =J92 -> 981.6532 | E12: =J93 -> 966.5528 | F12: =SUM(B12:E12) -> 3956.8136 | G12: =SUM(Datos!C14:F14) -> 4179.871 | H12: =IFERROR((F12-G12)/ABS(G12),"") -> -0.053364661
A13: (−) Capex | B13: =J107 -> 798.82 | C13: =J108 -> 820.74 | D13: =J109 -> 842.66 | E13: =J110 -> 864.58 | F13: =SUM(B13:E13) -> 3326.8 | G13: =SUM(Datos!C16:F16) -> 3002.1 | H13: =IFERROR((F13-G13)/ABS(G13),"") -> 0.10815762
A14: Capital de trabajo neto (cierre) | B14: =J124 -> 6975.4312 | C14: =J125 -> 6036.114 | D14: =J126 -> 5096.7968 | E14: =J127 -> 4157.4796 | F14: =E14 -> 4157.4796 | G14: =Datos!F19-Datos!F21 -> 7301.914
A15: (−) ΔNWC (cambio en capital de trabajo) | B15: =B14-(Datos!$F$19-Datos!$F$21) -> -326.4828 | C15: =C14-B14 -> -939.3172 | D15: =D14-C14 -> -939.3172 | E15: =E14-D14 -> -939.3172 | F15: =SUM(B15:E15) -> -3144.4344 | G15: =(Datos!F19-Datos!F21)-(Datos!B19-Datos!B21) -> -3764.086
A16: FCFF = EBIT(1−T) + D&A − Capex − ΔNWC | B16: =B11+B12-B13-B15 -> 2075.6979 | C16: =C11+C12-C13-C15 -> 2714.4386 | D16: =D11+D12-D13-D15 -> 2741.4203 | E16: =E11+E12-E13-E15 -> 2769.4775 | F16: =F11+F12-F13-F15 -> 10301.034 | G16: =G11+G12-G13-G15 -> 10516.503 | H16: =IFERROR((F16-G16)/ABS(G16),"") -> -0.020488662
A18: 2. FCFF PROYECTADO AJUSTADO POR VARIABLES EXTERNAS
A19: Ajuste neto a ventas | B19: ='Variables Externas'!H22 -> -0.009
A20: Ajuste neto a costos y gastos | B20: ='Variables Externas'!I22 -> 0.0052
A21: Ajuste neto a capex | B21: ='Variables Externas'!J22 -> 0.025
A23: Concepto | B23: 3T26 | C23: 4T26 | D23: 1T27 | E23: 2T27 | F23: LTM ajustado (3T26–2T27) | G23: LTM proyectado sin ajuste | H23: Variación vs. sin ajuste
A24: Ventas | B24: =B6*(1+$B$19) -> 41617.342 | C24: =C6*(1+$B$19) -> 40949.309 | D24: =D6*(1+$B$19) -> 40281.276 | E24: =E6*(1+$B$19) -> 39613.243 | F24: =SUM(B24:E24) -> 162461.17 | G24: =F6 -> 163936.6 | H24: =IFERROR((F24-G24)/ABS(G24),"") -> -0.009
A25: Costos y gastos operativos | B25: =B7*(1+$B$19)*(1+$B$20) -> 39859.576 | C25: =C7*(1+$B$19)*(1+$B$20) -> 39163.564 | D25: =D7*(1+$B$19)*(1+$B$20) -> 38467.552 | E25: =E7*(1+$B$19)*(1+$B$20) -> 37771.539 | F25: =SUM(B25:E25) -> 155262.23 | G25: =F7 -> 155861.8 | H25: =IFERROR((F25-G25)/ABS(G25),"") -> -0.0038468
A26: EBIT | B26: =B24-B25 -> 1757.7662 | C26: =C24-C25 -> 1785.7454 | D26: =D24-D25 -> 1813.7245 | E26: =E24-E25 -> 1841.7037 | F26: =SUM(B26:E26) -> 7198.9398 | G26: =F8 -> 8074.8 | H26: =IFERROR((F26-G26)/ABS(G26),"") -> -0.10846835
A27: Margen EBIT | B27: =B26/B24 -> 0.042236388 | C27: =C26/C24 -> 0.043608681 | D27: =D26/D24 -> 0.045026491 | E27: =E26/E24 -> 0.04649212 | F27: =F26/F24 -> 0.044311756 | G27: =F9 -> 0.049255627
A28: Tasa de impuesto | B28: =B10 -> 0.22485563 | C28: =C10 -> 0.20299653 | D28: =D10 -> 0.18113743 | E28: =E10 -> 0.15927832 | F28: =1-F29/F26 -> 0.19164219 | G28: =F10 -> 0.19173401
A29: EBIT (1 − T) | B29: =B26*(1-B28) -> 1362.5226 | C29: =C26*(1-C28) -> 1423.2453 | D29: =D26*(1-D28) -> 1485.1911 | E29: =E26*(1-E28) -> 1548.3602 | F29: =SUM(B29:E29) -> 5819.3192 | G29: =F11 -> 6526.5862 | H29: =IFERROR((F29-G29)/ABS(G29),"") -> -0.10836708
A30: (+) Depreciación y amortización | B30: =B12 -> 1011.854 | C30: =C12 -> 996.7536 | D30: =D12 -> 981.6532 | E30: =E12 -> 966.5528 | F30: =SUM(B30:E30) -> 3956.8136 | G30: =F12 -> 3956.8136 | H30: =IFERROR((F30-G30)/ABS(G30),"") -> 0
A31: (−) Capex | B31: =B13*(1+$B$21) -> 818.7905 | C31: =C13*(1+$B$21) -> 841.2585 | D31: =D13*(1+$B$21) -> 863.7265 | E31: =E13*(1+$B$21) -> 886.1945 | F31: =SUM(B31:E31) -> 3409.97 | G31: =F13 -> 3326.8 | H31: =IFERROR((F31-G31)/ABS(G31),"") -> 0.025
A32: (−) ΔNWC | B32: =B15 -> -326.4828 | C32: =C15 -> -939.3172 | D32: =D15 -> -939.3172 | E32: =E15 -> -939.3172 | F32: =SUM(B32:E32) -> -3144.4344 | G32: =F15 -> -3144.4344
A33: FCFF ajustado | B33: =B29+B30-B31-B32 -> 1882.0689 | C33: =C29+C30-C31-C32 -> 2518.0576 | D33: =D29+D30-D31-D32 -> 2542.435 | E33: =E29+E30-E31-E32 -> 2568.0357 | F33: =SUM(B33:E33) -> 9510.5972 | G33: =F16 -> 10301.034 | H33: =IFERROR((F33-G33)/ABS(G33),"") -> -0.076733759
A35: DETALLE DE MÍNIMOS CUADRADOS POR PARTIDA DEL FCFF
A37: 1. VENTAS (ingresos totales)
A38: Trimestre | B38: n | C38: X = n − (N+1)/2 | D38: Y (mdp) | E38: XY | F38: X² | H38: Trimestre a pronosticar | I38: X (pronóstico) | J38: Y pronosticada
A39: =Datos!B$5 -> 2T25 | B39: 1 | C39: =B39-(COUNT($B$39:$B$43)+1)/2 -> -2 | D39: =Datos!B6 -> 45810 | E39: =C39*D39 -> -91620 | F39: =C39^2 -> 4 | H39: 3T26 | I39: =MAX($C$39:$C$43)+1 -> 3 | J39: =$B$48+$B$47*I39 -> 41995.3
A40: =Datos!C$5 -> 3T25 | B40: 2 | C40: =B40-(COUNT($B$39:$B$43)+1)/2 -> -1 | D40: =Datos!C6 -> 42683 | E40: =C40*D40 -> -42683 | F40: =C40^2 -> 1 | H40: 4T26 | I40: =I39+1 -> 4 | J40: =$B$48+$B$47*I40 -> 41321.2
A41: =Datos!D$5 -> 4T25 | B41: 3 | C41: =B41-(COUNT($B$39:$B$43)+1)/2 -> 0 | D41: =Datos!D6 -> 47592 | E41: =C41*D41 -> 0 | F41: =C41^2 -> 0 | H41: 1T27 | I41: =I40+1 -> 5 | J41: =$B$48+$B$47*I41 -> 40647.1
A42: =Datos!E$5 -> 1T26 | B42: 4 | C42: =B42-(COUNT($B$39:$B$43)+1)/2 -> 1 | D42: =Datos!E6 -> 40444 | E42: =C42*D42 -> 40444 | F42: =C42^2 -> 1 | H42: 2T27 | I42: =I41+1 -> 6 | J42: =$B$48+$B$47*I42 -> 39973
A43: =Datos!F$5 -> 2T26 | B43: 5 | C43: =B43-(COUNT($B$39:$B$43)+1)/2 -> 2 | D43: =Datos!F6 -> 43559 | E43: =C43*D43 -> 87118 | F43: =C43^2 -> 4
A44: Σ (sumas) | C44: =SUM(C39:C43) -> 0 | D44: =SUM(D39:D43) -> 220088 | E44: =SUM(E39:E43) -> -6741 | F44: =SUM(F39:F43) -> 10 | H44: ="Ecuación: Y = "&TEXT(B48,"#,##0.0000")&" + ("&TEXT(B47,"#,##0.0000")&")·X" -> Ecuación: Y = 44,017.6000 + (-674.1000)·X
A45: N (trimestres) | B45: =COUNT(B39:B43) -> 5
A46: X̄ = ΣX / N | B46: =C44/B45 -> 0
...

Sheet Variables Externas
A4: # | B4: Categoría | C4: Variable | D4: Dato observado | E4: Canal de transmisión a Soriana | F4: Partida del FCFF afectada | G4: Efecto | H4: Ajuste a ventas (%) | I4: Ajuste a costos y gastos (%) | J4: Ajuste a capex (%)
A5: 1 | B5: Macroeconomía México | C5: Crecimiento del PIB | D5: Banxico (Informe abr–jun 2026): PIB 2026 1.5% (rango 1.0–2.0%); 2027 2.0% (rango 1.2–2.8%) | E5: Banxico espera que el consumo privado retome tendencia positiva tras la debilidad de inicio de 2026: más volumen en autoservicio | F5: Ventas | G5: + | H5: 0.005 | I5: 0 | J5: 0
A6: 2 | B6: Macroeconomía México | C6: Inflación | D6: General 3.42% y subyacente 3.79% (1a quincena sep-2026); convergencia a 3% hasta 4T27 | E6: Eleva ventas nominales y costo de mercancía en proporción similar; efecto casi neutral en margen (ya capturado en la tendencia) | F6: Ventas y costos | G6: Neutral | H6: 0 | I6: 0 | J6: 0
A7: 3 | B7: Política monetaria | C7: Tasa objetivo Banxico / Fed | D7: Banxico mantuvo 6.50% (24-sep-2026, unánime); la Fed subió 25 pb en septiembre | E7: Afecta costo de deuda y WACC (descuento del FCFF), no el FCFF operativo; crédito al consumo sigue caro | F7: WACC / gastos financieros | G7: − (valuación) | H7: 0 | I7: 0 | J7: 0
A8: 4 | B8: Macroeconomía México | C8: Tipo de cambio | D8: 18.08 MXN/USD al cierre del 30-sep-2026; el peso perdió 6.38% en septiembre | E8: Encarece mercancía general importada (electrónica, línea blanca) y equipo/refrigeración del programa de capex | F8: Costos y capex | G8: − | H8: 0 | I8: 0.001 | J8: 0.01
A9: 5 | B9: Macroeconomía México | C9: Remesas | D9: 2025: USD 61,791 mm (−4.6%), primera caída anual en 11 años; 1T26 +1.4% | E9: Menor ingreso de hogares en Bajío, Occidente y Norte (regiones clave de Soriana) por política migratoria de EU | F9: Ventas | G9: − | H9: -0.003 | I9: 0 | J9: 0
A10: 6 | B10: Política México (laboral) | C10: Salario mínimo 2026 | D10: +13%: de 278.80 a 315.04 $/día (frontera norte +5%: 440.87 $/día); meta 2.5 canastas básicas a 2030 | E10: Sube la nómina operativa de tiendas, pero también el ingreso disponible del cliente de bajos ingresos | F10: Costos (+) y ventas (+) | G10: Mixto | H10: 0.002 | I10: 0.0015 | J10: 0
A11: 7 | B11: Política México (laboral) | C11: Jornada laboral de 40 horas | D11: Reducción gradual de 48 a 40 h; 2026 es periodo de adecuación y los cambios inician en 2027 | E11: Requiere más turnos/plantilla en tiendas de horario extendido o más automatización | F11: Costos | G11: − | H11: 0 | I11: 0.0005 | J11: 0
A12: 8 | B12: Política México (fiscal) | C12: IEPS a bebidas y tabaco | D12: Bebidas azucaradas de 1.64 a 3.08 $/litro; tabaco de 160% a 200% ad valorem (2026) | E12: Menor volumen en categorías de alta rotación (refrescos, tabaco) dentro del ticket del autoservicio | F12: Ventas | G12: − | H12: -0.002 | I12: 0 | J12: 0
A13: 9 | B13: Política comercial México | C13: Aranceles a países sin tratado | D13: Aranceles nuevos o mayores de hasta 50% a importaciones de China, Corea del Sur, India, Vietnam, etc. desde 1-ene-2026 | E13: Encarece ropa, juguetes, electrónicos y equipo de tienda de origen asiático | F13: Costos y capex | G13: − | H13: 0 | I13: 0.0005 | J13: 0.005
A14: 10 | B14: T-MEC | C14: Revisión del T-MEC | D14: EU activó el mecanismo de revisiones anuales (no hubo extensión en jul-2026); Banxico prevé inversión débil por la incertidumbre comercial | E14: Frena inversión y empleo formal en el Norte industrial, base de clientes de Soriana (Coahuila, NL, Chihuahua) | F14: Ventas | G14: − | H14: -0.003 | I14: 0 | J14: 0
A15: 11 | B15: T-MEC / aranceles de EU | C15: Aranceles de EU a sectores estratégicos | D15: Persisten aranceles de EU a acero, aluminio y automotriz; bienes con origen T-MEC conservan exención; exportaciones a EU +7.7% acumulado a mayo | E15: Presión sobre empleo manufacturero (autopartes, acero) en ciudades del Norte donde Soriana concentra tiendas | F15: Ventas | G15: − | H15: -0.002 | I15: 0 | J15: 0
A16: 12 | B16: Geopolítica | C16: Conflicto en Medio Oriente / petróleo | D16: Petróleo por encima de USD 100, dólar fuerte e incertidumbre geopolítica presionan al peso (sep-2026) | E16: Encarece energía de tiendas, diésel y fletes de la logística; riesgo inflacionario | F16: Costos | G16: − | H16: 0 | I16: 0.0005 | J16: 0
... A21: 17 | B21: Inmobiliario y arrendamientos | C21: Ocupación de centros comerciales (FIBRAs) | D21: Los 10 jugadores institucionales con ocupación arriba de 91% (algunos 99%) al 2T26, rentas al alza y spreads de renovación altos | E21: Alta demanda por espacio facilita monetizar/subarrendar las áreas liberadas por cierres y reducción de tiendas | F21: Ventas (otros ingresos) | G21: + | H21: 0.001 | I21: 0 | J21: 0
A22: TOTAL | C22: Ajuste neto aplicado a la proyección | H22: =SUM(H5:H21) -> -0.009 | I22: =SUM(I5:I21) -> 0.0052 | J22: =SUM(J5:J21) -> 0.025

Sheet Proyección Final Soriana
A5: A. PONDERACIÓN DE MÉTODOS | B5: 2025A | C5: 2026E | D5: 2027E | E5: 2028E | F5: 2029E | G5: 2030E
A6: Peso de variables externas | C6: 0.7 | D6: 0.7 | E6: 0.75 | F6: 0.8 | G6: 0.85
A7: Peso de mínimos cuadrados | C7: =1-C6 -> 0.3 | D7: =1-D6 -> 0.3 | E7: =1-E6 -> 0.25 | F7: =1-F6 -> 0.2 | G7: =1-G6 -> 0.15
A9: B. CRECIMIENTO DE VENTAS — VARIABLES EXTERNAS | B9: 2025A | C9: 2026E | D9: 2027E | E9: 2028E | F9: 2029E | G9: 2030E
A10: Inflación esperada (INPC) — escenario de la hoja Inflación | C10: =Inflación!B13 -> 0.0351 | D10: =Inflación!C13 -> 0.0351 | E10: =Inflación!D13 -> 0.0351 | F10: =Inflación!E13 -> 0.0351 | G10: =Inflación!F13 -> 0.0351
A11: Crecimiento real del PIB de México | C11: 0.014 | D11: 0.018 | E11: 0.02 | F11: 0.02 | G11: 0.02
A12: Elasticidad del volumen de autoservicio al PIB (x) | C12: 0.5 | D12: 0.5 | E12: 0.5 | F12: 0.5 | G12: 0.5
A13: Ajuste por debilidad del consumo | C13: -0.04 | D13: -0.015 | E13: -0.005 | F13: 0 | G13: 0
A14: Crecimiento nominal del mercado de autoservicio | C14: =C10+C11*C12+C13 -> 0.0021 | D14: =D10+D11*D12+D13 -> 0.0291 | E14: =E10+E11*E12+E13 -> 0.0401 | F14: =F10+F11*F12+F13 -> 0.0451 | G14: =G10+G11*G12+G13 -> 0.0451
A15: (±) Pérdida de participación (hard discount y competidores) | C15: -0.03 | D15: -0.02 | E15: -0.0125 | F15: -0.01 | G15: -0.0075
A16: (±) Cierre y reducción de tiendas | C16: -0.01 | D16: -0.005 | E16: 0 | F16: 0 | G16: 0
A17: (±) Remesas y política migratoria de EU | C17: -0.003 | D17: -0.002 | E17: -0.001 | F17: 0 | G17: 0
A18: (±) T-MEC y aranceles de EU (empleo industrial del Norte) | C18: -0.002 | D18: -0.003 | E18: -0.001 | F18: 0 | G18: 0
A19: (±) Programas sociales y salario mínimo (ingreso disponible) | C19: 0.002 | D19: 0.003 | E19: 0.003 | F19: 0.002 | G19: 0.002
A20: (±) Omnicanalidad y ventas digitales | C20: 0.003 | D20: 0.004 | E20: 0.005 | F20: 0.005 | G20: 0.005
A21: (±) PACIC e IEPS (precio tope y menor volumen) | C21: -0.002 | D21: -0.002 | E21: -0.001 | F21: 0 | G21: 0
A22: (±) Ingresos inmobiliarios y financieros (m² liberados, Sofipo) | C22: 0.001 | D22: 0.002 | E22: 0.002 | F22: 0.002 | G22: 0.002
A23: Crecimiento de ventas — variables externas | C23: =C14+SUM(C15:C22) -> -0.0389 | D23: =D14+SUM(D15:D22) -> 0.0061 | E23: =E14+SUM(E15:E22) -> 0.0346 | F23: =F14+SUM(F15:F22) -> 0.0441 | G23: =G14+SUM(G15:G22) -> 0.0466
A25: C. CRECIMIENTO DE VENTAS — MÍNIMOS CUADRADOS | B25: 2025A | C25: 2026E | D25: 2027E | E25: 2028E | F25: 2029E | G25: 2030E
A26: Ventas por mínimos cuadrados (regresión solo 2026E; 2027E–2030E crecen con la inflación) | B26: ='MC Soriana'!G6 -> 174278 | C26: ='MC Soriana'!F24 -> 162461.17 | D26: =C26*(1+D10) -> 168163.56 | E26: =D26*(1+E10) -> 174066.1 | F26: =E26*(1+F10) -> 180175.82 | G26: =F26*(1+G10) -> 186499.99
A27: Crecimiento de ventas — mínimos cuadrados | C27: =C26/B26-1 -> -0.067804481 | D27: =D26/C26-1 -> 0.0351 | E27: =E26/D26-1 -> 0.0351 | F27: =F26/E26-1 -> 0.0351 | G27: =G26/F26-1 -> 0.0351
A28: CRECIMIENTO DE VENTAS FINAL (ponderado) | C28: =C$6*C23+C$7*C27 -> -0.047571344 | D28: =D$6*D23+D$7*D27 -> 0.0148 | E28: =E$6*E23+E$7*E27 -> 0.034725 | F28: =F$6*F23+F$7*F27 -> 0.0423 | G28: =G$6*G23+G$7*G27 -> 0.044875
A30: D. MARGEN EBIT | B30: 2025A | C30: 2026E | D30: 2027E | E30: 2028E | F30: 2029E | G30: 2030E
A31: Margen EBIT — variables externas (acumulado) | B31: =Valuación!B10 -> 0.042542884 | C31: =B31+SUM(C32:C39) -> 0.043742884 | D31: =C31+SUM(D32:D39) -> 0.043442884 | E31: =D31+SUM(E32:E39) -> 0.043742884 | F31: =E31+SUM(F32:F39) -> 0.044042884 | G31: =F31+SUM(G32:G39) -> 0.044342884
A32: (±) Austeridad, cierres y eficiencias | C32: 0.0055 | D32: 0.003 | E32: 0.002 | F32: 0.001 | G32: 0.001
A33: (±) Salario mínimo +13% y jornada de 40 h | C33: -0.001 | D33: -0.0015 | E33: -0.0015 | F33: -0.001 | G33: -0.001
A34: (±) Inversión en precio (hard discount, PACIC) | C34: -0.0015 | D34: -0.001 | E34: -0.001 | F34: -0.0005 | G34: 0
A35: (±) Tipo de cambio y aranceles a importaciones de Asia | C35: -0.0005 | D35: -0.0005 | E35: 0 | F35: 0 | G35: 0
A36: (±) Energía, combustibles y fletes | C36: -0.0005 | D36: -0.0005 | E36: 0 | F36: 0 | G36: 0
A37: (±) Rentas comerciales (tiendas arrendadas) | C37: -0.0003 | D37: -0.0003 | E37: -0.0002 | F37: -0.0002 | G37: -0.0002
A38: (±) Ingresos inmobiliarios y servicios financieros | C38: 0.0005 | D38: 0.001 | E38: 0.001 | F38: 0.001 | G38: 0.0005
A39: (±) Desapalancamiento operativo por menores ventas | C39: -0.001 | D39: -0.0005 | E39: 0 | F39: 0 | G39: 0
A40: Margen EBIT — mínimos cuadrados ajustado por variables externas | C40: ='MC Soriana'!$F$27 -> 0.044311756 | D40: ='MC Soriana'!$F$27 -> 0.044311756 | E40: ='MC Soriana'!$F$27 -> 0.044311756 | F40: ='MC Soriana'!$F$27 -> 0.044311756 | G40: ='MC Soriana'!$F$27 -> 0.044311756
A41: MARGEN EBIT FINAL (ponderado) | C41: =C$6*C31+C$7*C40 -> 0.043913545 | D41: =D$6*D31+D$7*D40 -> 0.043703545 | E41: =E$6*E31+E$7*E40 -> 0.043885102 | F41: =F$6*F31+F$7*F40 -> 0.044096658 | G41: =G$6*G31+G$7*G40 -> 0.044338215
A43: E. OTROS SUPUESTOS (FCF Y ESTADOS FINANCIEROS) | B43: 2025A | C43: 2026E | D43: 2027E | E43: 2028E | F43: 2029E | G43: 2030E
A44: D&A (% ventas) — variables externas / histórico | C44: =Valuación!$B$11 -> 0.024459905 | D44: =Valuación!$B$11 -> 0.024459905 | E44: =Valuación!$B$11 -> 0.024459905 | F44: =Valuación!$B$11 -> 0.024459905 | G44: =Valuación!$B$11 -> 0.024459905
