Workbook

Sheet Comparativo
A4: 1. VALUACIÓN (DCF, base FY2025) | B4: Soriana | C4: Walmex | D4: Chedraui | E4: La Comer
A5: WACC | B5: =Valuación!B15 -> 0.10061577 | C5: =Valuación!B53 -> 0.12228947 | D5: =Valuación!B91 -> 0.10091294 | E5: =Valuación!B129 -> 0.12085359
A6: Crecimiento perpetuo (g) | B6: =Valuación!B16 -> 0.035 | C6: =Valuación!B54 -> 0.035 | D6: =Valuación!B92 -> 0.035 | E6: =Valuación!B130 -> 0.035
A7: FCF 2025A (flujo libre de efectivo) | B7: =Valuación!B27 -> 6761.4 | C7: =Valuación!B65 -> 40916.76 | D7: =Valuación!B103 -> 12113.9 | E7: =Valuación!B141 -> 302.92442
A8: VPN de los FCF 2026E–2030E | B8: =Valuación!B31 -> 27699.25 | C8: =Valuación!B69 -> 161517.97 | D8: =Valuación!B107 -> 50520.788 | E8: =Valuación!B145 -> 1200.1425
A9: Valor terminal (TV) al 2030 | B9: =Valuación!B33 -> 124330.71 | C9: =Valuación!B71 -> 576210.9 | D9: =Valuación!B109 -> 225920.38 | E9: =Valuación!B147 -> 4337.2847
A10: Valor presente del TV | B10: =Valuación!B34 -> 76983.872 | C10: =Valuación!B72 -> 323636.15 | D10: =Valuación!B110 -> 139698.11 | E10: =Valuación!B148 -> 2451.7349
A11: Enterprise Value (EV) | B11: =Valuación!B35 -> 104683.12 | C11: =Valuación!B73 -> 485154.12 | D11: =Valuación!B111 -> 190218.9 | E11: =Valuación!B149 -> 3651.8774
A12: Deuda total (bancaria/bursátil + arrendamientos) | B12: =-Valuación!B36 -> 23618 | C12: =-Valuación!B74 -> 80848.1 | D12: =-Valuación!B112 -> 56744.34 | E12: =-Valuación!B150 -> 2441.8
A13: Efectivo y equivalentes | B13: =Valuación!B37 -> 9295 | C13: =Valuación!B75 -> 28591.2 | D13: =Valuación!B113 -> 14640.16 | E13: =Valuación!B151 -> 2962.8
A14: Equity Value (valor para los accionistas) | B14: =Valuación!B39 -> 90360.122 | C14: =Valuación!B77 -> 432897.22 | D14: =Valuación!B115 -> 148114.72 | E14: =Valuación!B153 -> 4172.8774
A15: Valor intrínseco por acción (MXN) | B15: =Valuación!B41 -> 50.200068 | C15: =Valuación!B79 -> 24.794063 | D15: =Valuación!B117 -> 154.24532 | E15: =Valuación!B155 -> 3.9153526
A16: Precio actual en bolsa (MXN) | B16: =Valuación!B42 -> 33.1 | C16: =Valuación!B80 -> 46.6 | D16: =Valuación!B118 -> 92.94 | E16: =Valuación!B156 -> 32.08
A17: Potencial de apreciación / (baja) | B17: =Valuación!B43 -> 0.51661836 | C17: =Valuación!B81 -> -0.46793856 | D17: =Valuación!B119 -> 0.65962259 | E17: =Valuación!B157 -> -0.87795036
A18: Precio objetivo consenso de analistas (MXN) | B18: =Generales!B24 -> 23.357 | C18: 60.094 | D18: 128.933 | E18: 47.67
A19: Recomendación consenso de analistas | B19: Venta (0 C / 1 M / 6 V) | C19: Neutral (5 C / 10 M / 3 V) | D19: Neutral (3 C / 12 M / 0 V) | E19: Compra (5 C / 4 M / 0 V)
A21: 2. RAZONES FINANCIERAS – PROMEDIO DE LOS ÚLTIMOS 5 TRIMESTRES | B21: Soriana | C21: Walmex | D21: Chedraui | E21: La Comer
A22: Circulante | B22: =Razones!G7 -> 1.2541889 | C22: =Razones!G23 -> 0.9768759 | D22: =Razones!G39 -> 0.933732 | E22: =Razones!G55 -> 1.2290463
A23: Prueba ácida | B23: =Razones!G8 -> 0.35473781 | C23: =Razones!G24 -> 0.34704511 | D23: =Razones!G40 -> 0.40675641 | E23: =Razones!G56 -> 0.48041577
A24: Deuda / Activo total | B24: =Razones!G9 -> 0.45505378 | C24: =Razones!G25 -> 0.52855776 | D24: =Razones!G41 -> 0.66310269 | E24: =Razones!G57 -> 0.2578378
A25: Capitalización a largo plazo | B25: =Razones!G10 -> 0.20654207 | C25: =Razones!G26 -> 0.18040972 | D25: =Razones!G42 -> 0.38012988 | E25: =Razones!G58 -> 0.064547002
A26: Cobertura de intereses | B26: =Razones!G11 -> 2.8984196 | C26: =Razones!G27 -> 6.6453315 | D26: =Razones!G43 -> 4.1504186 | E26: =Razones!G59 -> 11.844746
A27: Rotación del inventario (trimestral) | B27: =Razones!G12 -> 0.95612726 | C27: =Razones!G28 -> 1.7752133 | D27: =Razones!G44 -> 2.3833504 | E27: =Razones!G60 -> 1.3488695
A28: Rotación del inventario en días | B28: =Razones!G13 -> 96.032436 | C28: =Razones!G29 -> 51.658042 | D28: =Razones!G45 -> 38.380088 | E28: =Razones!G61 -> 67.850681
A29: Rotación del activo total (trimestral) | B29: =Razones!G14 -> 0.28166407 | C29: =Razones!G30 -> 0.51157675 | D29: =Razones!G46 -> 0.46365336 | E29: =Razones!G62 -> 0.2764494
A30: Margen bruto | B30: =Razones!G15 -> 0.24566153 | C30: =Razones!G31 -> 0.24235015 | D30: =Razones!G47 -> 0.23527548 | E30: =Razones!G63 -> 0.29672069
A31: Margen neto | B31: =Razones!G16 -> 0.020605935 | C31: =Razones!G32 -> 0.048260538 | D31: =Razones!G48 -> 0.023418786 | E31: =Razones!G64 -> 0.05488254
A32: ROA (trimestral) | B32: =Razones!G17 -> 0.005843019 | C32: =Razones!G33 -> 0.024728482 | D32: =Razones!G49 -> 0.010867202 | E32: =Razones!G65 -> 0.015156869
A33: ROE (trimestral) | B33: =Razones!G18 -> 0.010703389 | C33: =Razones!G34 -> 0.052476921 | D33: =Razones!G50 -> 0.032240332 | E33: =Razones!G66 -> 0.02043965
A34: ROI (trimestral) | B34: =Razones!G19 -> 0.012031436 | C34: =Razones!G35 -> 0.042432022 | D34: =Razones!G51 -> 0.024290294 | E34: =Razones!G67 -> 0.017861415
A36: 3. RAZONES FINANCIERAS ANUALES FY2025 (incluye Chedraui) | B36: Soriana | C36: Walmex | D36: Chedraui | E36: La Comer
A37: Circulante | B37: =IFERROR(Datos!G19/Datos!G21,"n.d.") -> 1.2373849 | C37: =IFERROR(Datos!G45/Datos!G47,"n.d.") -> 0.96696082 | D37: =IFERROR(Datos!G71/Datos!G73,"n.d.") -> 0.92079667 | E37: =IFERROR(Datos!G97/Datos!G99,"n.d.") -> 1.2070372
A38: Prueba ácida | B38: =IFERROR((Datos!G19-Datos!G18)/Datos!G21,"n.d.") -> 0.414238 | C38: =IFERROR((Datos!G45-Datos!G44)/Datos!G47,"n.d.") -> 0.33384163 | D38: =IFERROR((Datos!G71-Datos!G70)/Datos!G73,"n.d.") -> 0.43735523 | E38: =IFERROR((Datos!G97-Datos!G96)/Datos!G99,"n.d.") -> 0.50008921
A39: Deuda / Activo total | B39: =IFERROR(Datos!G23/Datos!G20,"n.d.") -> 0.45697843 | C39: =IFERROR(Datos!G49/Datos!G46,"n.d.") -> 0.52434323 | D39: =IFERROR(Datos!G75/Datos!G72,"n.d.") -> 0.67356639 | E39: =IFERROR(Datos!G101/Datos!G98,"n.d.") -> 0.2544825
A40: Capitalización a largo plazo | B40: =IFERROR(Datos!G22/Datos!G20,"n.d.") -> 0.2056294 | C40: =IFERROR(Datos!G48/Datos!G46,"n.d.") -> 0.1816704 | D40: =IFERROR(Datos!G74/Datos!G72,"n.d.") -> 0.37134872 | E40: =IFERROR(Datos!G100/Datos!G98,"n.d.") -> 0.06423617
A41: Cobertura de intereses | B41: =IFERROR(Datos!G9/Datos!G10,"n.d.") -> 2.4567339 | C41: =IFERROR(Datos!G35/Datos!G36,"n.d.") -> 6.8465638 | D41: =IFERROR(Datos!G61/Datos!G62,"n.d.") -> 3.9247028 | E41: =IFERROR(Datos!G87/Datos!G88,"n.d.") -> 13.400737
A42: Rotación del inventario (anual) | B42: =IFERROR(Datos!G7/Datos!G18,"n.d.") -> 4.1740854 | C42: =IFERROR(Datos!G33/Datos!G44,"n.d.") -> 7.1325601 | D42: =IFERROR(Datos!G59/Datos!G70,"n.d.") -> 9.7102302 | E42: =IFERROR(Datos!G85/Datos!G96,"n.d.") -> 5.6268631
A43: Rotación del inventario en días (365) | B43: =IFERROR(365*Datos!G18/Datos!G7,"n.d.") -> 87.444305 | C43: =IFERROR(365*Datos!G44/Datos!G33,"n.d.") -> 51.173772 | D43: =IFERROR(365*Datos!G70/Datos!G59,"n.d.") -> 37.589222 | E43: =IFERROR(365*Datos!G96/Datos!G85,"n.d.") -> 64.867404
A44: Rotación del activo total (anual) | B44: =IFERROR(Datos!G6/Datos!G20,"n.d.") -> 1.1376395 | C44: =IFERROR(Datos!G32/Datos!G46,"n.d.") -> 2.0425044 | D44: =IFERROR(Datos!G58/Datos!G72,"n.d.") -> 1.8415047 | E44: =IFERROR(Datos!G84/Datos!G98,"n.d.") -> 1.0755432
A45: Margen bruto | B45: =IFERROR(Datos!G8/Datos!G6,"n.d.") -> 0.24090359 | C45: =IFERROR(Datos!G34/Datos!G32,"n.d.") -> 0.24238672 | D45: =IFERROR(Datos!G60/Datos!G58,"n.d.") -> 0.22959264 | E45: =IFERROR(Datos!G86/Datos!G84,"n.d.") -> 0.29637336
...

Sheet Generales
A4: 1. INFORMACIÓN GENERAL DE LA EMPRESA | B4: Dato
A5: Clave de cotización | B5: SORIANA B (BMV, cotiza desde 1987)
A6: Fundación | B6: 1968, Torreón, Coahuila
A7: Sede corporativa | B7: Monterrey, Nuevo León
A8: Giro | B8: Tiendas de autoservicio y clubes de membresía (multiformato)
A9: Tiendas en operación (2T26) | B9: 812
A10: Colaboradores (jun-2026) | B10: 82064
A11: Acciones en circulación (millones) | B11: =WACC!B17 -> 1800
A12: Capitalización de mercado a precio actual (mdp) | B12: =WACC!B18 -> 59580
A14: 2. NOTICIAS Y ANÁLISIS RECIENTES | B14: Fecha
A15: Resultados 2T26: menos ventas, más utilidad | B15: 31-jul-2026
A16: Cierre de 20 tiendas en 2026 | B16: 26-ago-2026
A17: Reducción de plantilla y automatización | B17: 2-sep-2026
A18: Plan de inversión 2S26 | B18: sep-2026
A19: Sector: Walmart, Soriana y Chedraui sufren por ingresos e inflación | B19: 2026
A21: 3. CALIFICACIÓN Y CONSENSO DE ANALISTAS | B21: Dato
A22: Calificación crediticia (HR Ratings) | B22: HR+1 (corto plazo)
A23: Consenso de analistas | B23: Venta
A24: Precio objetivo promedio 12 meses (MXN) | B24: 23.357
A26: 4. ANÁLISIS FUNDAMENTAL – RESUMEN FINANCIERO FY2025 (mdp) | B26: Valor
A27: Ingresos totales | B27: =Datos!G6 -> 177515
A28: Utilidad bruta | B28: =Datos!G8 -> 42764
A29: Utilidad de operación (EBIT) | B29: =Datos!G9 -> 7552
A30: Utilidad neta consolidada | B30: =Datos!G13 -> 3334
A31: Margen bruto | B31: =Datos!G8/Datos!G6 -> 0.24090359
A32: Margen de operación | B32: =Datos!G9/Datos!G6 -> 0.042542884
A33: Margen neto | B33: =Datos!G13/Datos!G6 -> 0.018781511
A35: 5. CUENTA DE RESULTADOS – ÚLTIMO TRIMESTRE (2T26 vs 2T25, mdp) | B35: 2T26
A36: Ingresos totales | B36: =Datos!F6 -> 43559
A37: Costo de ventas | B37: =Datos!F7 -> 32919
A38: Utilidad bruta | B38: =Datos!F8 -> 10640
A39: Utilidad de operación | B39: =Datos!F9 -> 1855
A40: Gastos financieros | B40: =Datos!F10 -> 582
A41: Utilidad neta | B41: =Datos!F13 -> 1090
A43: 6. BALANCE (cierre 2025 vs 1T26, mdp) | B43: Dic-2025
A44: Activo total | B44: =Datos!G20 -> 156038
A45: Pasivo total | B45: =Datos!G23 -> 71306
A46: Capital contable | B46: =Datos!G24 -> 84732
A47: Deuda bancaria y bursátil | B47: =Datos!G25+Datos!G26 -> 11500
A48: Efectivo | B48: =Datos!G17 -> 9295
...

Sheet Datos
A5: ORGANIZACIÓN SORIANA (SORIANA B) | B5: 2T25 | C5: 3T25 | D5: 4T25 | E5: 1T26 | F5: 2T26 | G5: FY2025
A6: Ingresos totales | B6: 45810 | C6: 42683 | D6: 47592 | E6: 40444 | F6: 43559 | G6: 177515
A7: Costo de ventas | B7: 34856 | C7: 31998 | D7: 35795 | E7: 30466 | F7: 32919 | G7: 134752
A8: Utilidad bruta | B8: 10954 | C8: 10685 | D8: 11797 | E8: 9978 | F8: 10640 | G8: 42764
A9: Utilidad de operación (EBIT) | B9: 1909 | C9: 1468 | D9: 2486 | E9: 1822 | F9: 1855 | G9: 7552
A10: Gastos financieros (intereses) | B10: 829 | C10: 786 | D10: 616 | E10: 588 | F10: 582 | G10: 3074
A11: Utilidad antes de impuestos | B11: 1203 | C11: 764 | D11: 1763 | E11: 1326 | F11: 1372 | G11: 4766
A12: Impuestos a la utilidad | B12: 461 | C12: 179 | D12: 455 | E12: 492 | F12: 282 | G12: 1433
A13: Utilidad neta consolidada | B13: 743 | C13: 584 | D13: 1308 | E13: 834 | F13: 1090 | G13: 3334
A14: Depreciación y amortización | B14: 1105.905 | C14: 1049.349 | D14: 1051 | E14: 1048.889 | F14: 1030.633 | G14: 4342
A15: Flujo neto de operación (CFO) | B15: 4013.113 | C15: -205.9 | D15: 13017 | E15: -3565.6 | F15: 3916.003 | G15: 13738
A16: Capex (inmuebles, equipo e intangibles) | B16: =SUM(B110:B112) -> 663.2 | C16: =SUM(C110:C112) -> 775.2 | D16: =SUM(D110:D112) -> 816 | E16: =SUM(E110:E112) -> 501 | F16: =SUM(F110:F112) -> 909.9 | G16: 2867
A17: Efectivo y equivalentes | B17: 7540 | C17: 5798 | D17: 9295 | E17: 4589 | F17: 6875.384 | G17: =D17 -> 9295
A18: Inventarios | B18: 37421 | C18: 36394 | D18: 32283 | E18: 32635 | F18: 35486.661 | G18: =D18 -> 32283
A19: Activo circulante | B19: 52131 | C19: 49767 | D19: 48529 | E19: 43562 | F19: 49259.847 | G19: =D19 -> 48529
A20: Activo total | B20: 159842 | C20: 157502 | D20: 156038 | E20: 150941 | F20: =F23+F24 -> 156813 | G20: =D20 -> 156038
A21: Pasivo circulante | B21: 41065 | C21: 38190 | D21: 39219 | E21: 33850 | F21: 41957.933 | G21: =D21 -> 39219
A22: Pasivo a largo plazo | B22: 34801 | C22: 34753 | D22: 32086 | E22: 31527 | F22: =F23-F21 -> 28201.067 | G22: =D22 -> 32086
A23: Pasivo total | B23: 75866 | C23: 72943 | D23: 71306 | E23: 65377 | F23: 70159 | G23: =D23 -> 71306
A24: Capital contable | B24: 83976 | C24: 84559 | D24: 84732 | E24: 85564 | F24: 86654 | G24: =D24 -> 84732
A25: Deuda bursátil y bancaria CP | B25: 6627 | C25: 6553 | D25: 3000 | E25: 3000 | F25: 6500 | G25: =D25 -> 3000
A26: Deuda bursátil y bancaria LP | B26: 11500 | C26: 11500 | D26: 8500 | E26: 8500 | F26: 5000 | G26: =D26 -> 8500
A27: Pasivo por arrendamiento CP | B27: 638 | C27: 659 | D27: 676 | E27: 683 | F27: 639.968 | G27: =D27 -> 676
A28: Pasivo por arrendamiento LP | B28: 11389 | C28: 11506 | D28: 11442 | E28: 11540 | F28: 11580.62 | G28: =D28 -> 11442
A29: Deuda total (financiera + arrendamientos) | B29: =IF(COUNT(B25:B28)=4,SUM(B25:B28),"n.d.") -> 30154 | C29: =IF(COUNT(C25:C28)=4,SUM(C25:C28),"n.d.") -> 30218 | D29: =IF(COUNT(D25:D28)=4,SUM(D25:D28),"n.d.") -> 23618 | E29: =IF(COUNT(E25:E28)=4,SUM(E25:E28),"n.d.") -> 23723 | F29: =IF(COUNT(F25:F28)=4,SUM(F25:F28),"n.d.") -> 23720.588 | G29: =IF(COUNT(G25:G28)=4,SUM(G25:G28),"n.d.") -> 23618
A31: WALMART DE MÉXICO (WALMEX) | B31: 2T25 | C31: 3T25 | D31: 4T25 | E31: 1T26 | F31: 2T26 | G31: FY2025
A32: Ingresos totales | B32: 246253.8 | C32: 241520.2 | D32: 282849.3 | E32: 245018.5 | F32: 250947.8 | G32: 1011597.9
A33: Costo de ventas | B33: 186848.1 | C33: 181746.3 | D33: 214905.4 | E33: 185425.3 | F33: 190822.8 | G33: 766400
A34: Utilidad bruta | B34: 59405.7 | C34: 59773.8 | D34: 67943.9 | E34: 59593.2 | F34: 60125 | G34: 245197.9
A35: Utilidad de operación (EBIT) | B35: 17267.1 | C35: 19020.8 | D35: 23317 | E35: 18471.6 | F35: 17019.7 | G35: 78493.8
A36: Gastos financieros (intereses) | B36: 2646.3 | C36: 3223.3 | D36: 2795.1 | E36: 2895.6 | F36: 2799.6 | G36: 11464.7
A37: Utilidad antes de impuestos | B37: 15076.8 | C37: 16328 | D37: 21053.3 | E37: 16176.4 | F37: 14754.6 | G37: 68876.6
A38: Impuestos a la utilidad | B38: 3849.9 | C38: 4580.7 | D38: 6453.5 | E38: 3676.9 | F38: 3602.2 | G38: 18985.9
A39: Utilidad neta consolidada | B39: 11226.9 | C39: 11747.3 | D39: 14599.8 | E39: 12499.6 | F39: 11152.4 | G39: 49890.7
A40: Depreciación y amortización | B40: 6227.732 | C40: 6245.37 | D40: 6277.929 | E40: 6506.919 | F40: 6620.741 | G40: 24953.1
A41: Flujo neto de operación (CFO) | B41: 21549.377 | C41: 22017.152 | D41: 43314.63 | E41: 4955.647 | F41: 18326.104 | G41: 82437.7
A42: Capex (inmuebles, equipo e intangibles) | B42: =SUM(B113:B115) -> 7989.7 | C42: =SUM(C113:C115) -> 11746.3 | D42: =SUM(D113:D115) -> 15831.8 | E42: =SUM(E113:E115) -> 2436.5 | F42: =SUM(F113:F115) -> 9264.9 | G42: 38982
A43: Efectivo y equivalentes | B43: 32443.8 | C43: 35181.7 | D43: 28591.2 | E43: 28085.1 | F43: 30118.3 | G43: =D43 -> 28591.2
A44: Inventarios | B44: 106742.4 | C44: 113238.4 | D44: 107450.9 | E44: 106202 | F44: 107528.9 | G44: =D44 -> 107450.9
A45: Activo circulante | B45: 166663.9 | C45: 176974.1 | D45: 164109.4 | E45: 163317.9 | F45: 168653.5 | G45: =D45 -> 164109.4
...

Sheet Base de Datos
A1: BASE DE DATOS DE MERCADO
B3: =COUNT(Rendimientos!$AD$10:$AD$509) -> 63 | C3: Última fecha | D3: =IF(COUNT(Rendimientos!$AD$10:$AD$509)=0,"sin datos",MAX(Rendimientos!$AD$10:$AD$509)) -> 46302 | J3: =COUNT(Rendimientos!$AF$10:$AF$509) -> 73 | K3: Última fecha | L3: =IF(COUNT(Rendimientos!$AF$10:$AF$509)=0,"sin datos",MAX(Rendimientos!$AF$10:$AF$509)) -> 46307 | R3: =COUNT(Rendimientos!$AH$10:$AH$409) -> 259 | S3: Última fecha | T3: =IF(COUNT(Rendimientos!$AH$10:$AH$409)=0,"sin datos",MAX(Rendimientos!$AH$10:$AH$409)) -> 46299 | Z3: =COUNT(Rendimientos!$AJ$10:$AJ$409) -> 261 | AA3: Última fecha | AB3: =IF(COUNT(Rendimientos!$AJ$10:$AJ$409)=0,"sin datos",MAX(Rendimientos!$AJ$10:$AJ$409)) -> 46306 | AG3: Obs. válidas | AH3: =COUNT(Inflación!$CH$10:$CH$309) -> 113 | AI3: Última quincena | AJ3: =MAX(Inflación!$CH$10:$CH$309) -> 46266
A4: SORIANA DIARIO | I4: IPC DIARIO | Q4: SORIANA SEMANAL | Y4: IPC SEMANAL | AG4: INPC, variación anual quincenal (%). Banxico SIE, serie SP74833
A5: Fecha | B5: Último | C5: Apertura | D5: Máximo | E5: Mínimo | F5: Vol. | G5: % var. | I5: Fecha | J5: Último | K5: Apertura | L5: Máximo | M5: Mínimo | N5: Vol. | O5: % var. | Q5: Fecha | R5: Último | S5: Apertura | T5: Máximo | U5: Mínimo | V5: Vol. | W5: % var. | Y5: Fecha | Z5: Último | AA5: Apertura | AB5: Máximo | AC5: Mínimo | AD5: Vol. | AE5: % var. | AG5: Quincena | AH5: Inflación anual (%)
A6: 46029 | B6: 30.34 | C6: 29.64 | D6: 30.34 | E6: 29.5 | F6: 3.40K | G6: 0.003 | I6: 01.07.2026 | J6: 67247.79 | K6: 66966.68 | L6: 67435.72 | M6: 66614.42 | N6: 162.40M | O6: 0.0042 | Q6: 10/17/2021 | R6: 25 | S6: 25.29 | T6: 25.7 | U6: 24.15 | V6: 1.05M | W6: -0.0192 | Y6: 17.10.2021 | Z6: 51889.66 | AA6: 52834.71 | AB6: 52942.26 | AC6: 51521.94 | AD6: 699.14M | AE6: -0.0172 | AG6: 44562 | AH6: 7.13
A7: 46060 | B7: 30.7 | C7: 29.73 | D7: 30.9 | E7: 29.73 | F7: 3.17K | G7: 0.0119 | I7: 02.07.2026 | J7: 67071.11 | K7: 66990.87 | L7: 68044.67 | M7: 66976.91 | N7: 102.82M | O7: -0.0026 | Q7: 10/24/2021 | R7: 24.77 | S7: 24.4 | T7: 25.5 | U7: 23.6 | V7: 174.31K | W7: -0.0092 | Y7: 24.10.2021 | Z7: 51309.84 | AA7: 51892.32 | AB7: 52244.72 | AC7: 50997.11 | AD7: 678.31M | AE7: -0.0112 | AG7: 44577 | AH7: 7.01
A8: 46088 | B8: 29.91 | C8: 30.08 | D8: 30.08 | E8: 29.91 | F8: 1.20K | G8: -0.0257 | I8: 03.07.2026 | J8: 67060.49 | K8: 67352.67 | L8: 67402.75 | M8: 66816.77 | N8: 28.96M | O8: -0.0002 | Q8: 10/31/2021 | R8: 24.48 | S8: 24.77 | T8: 24.77 | U8: 24.02 | V8: 48.46K | W8: -0.0117 | Y8: 31.10.2021 | Z8: 51977.96 | AA8: 51353.61 | AB8: 52220.4 | AC8: 51338.69 | AD8: 674.32M | AE8: 0.013 | AG8: 44593 | AH8: 7.22
A9: 46180 | B9: 29.6 | C9: 30 | D9: 30 | E9: 29.51 | F9: 2.36K | G9: -0.0104 | I9: 06.07.2026 | J9: 67466.46 | K9: 67132.1 | L9: 67780.34 | M9: 67099.66 | N9: 154.90M | O9: 0.0061 | Q9: 44388 | R9: 23.77 | S9: 24.4 | T9: 24.5 | U9: 23.5 | V9: 104.02K | W9: -0.029 | Y9: 07.11.2021 | Z9: 51432.54 | AA9: 52000.21 | AB9: 52577.33 | AC9: 51350.36 | AD9: 831.59M | AE9: -0.0105 | AG9: 44608 | AH9: 7.34
A10: 46210 | B10: 30.29 | C10: 29.6 | D10: 30.49 | E10: 29.6 | F10: 0.85K | G10: 0.0233 | I10: 07.07.2026 | J10: 66674.7 | K10: 67450.26 | L10: 67666.07 | M10: 66526.12 | N10: 128.25M | O10: -0.0117 | Q10: 11/14/2021 | R10: 22.99 | S10: 23.99 | T10: 24.13 | U10: 22.92 | V10: 88.93K | W10: -0.0328 | Y10: 14.11.2021 | Z10: 50811.3 | AA10: 51422.13 | AB10: 51585.64 | AC10: 50535.11 | AD10: 652.74M | AE10: -0.0121 | AG10: 44621 | AH10: 7.29
A11: 46241 | B11: 30 | C11: 29.68 | D11: 30.65 | E11: 29.68 | F11: 1.26K | G11: -0.0096 | I11: 08.07.2026 | J11: 66609.64 | K11: 66526.65 | L11: 66763.02 | M11: 65846.95 | N11: 105.53M | O11: -0.001 | Q11: 11/21/2021 | R11: 22.73 | S11: 22.8 | T11: 24 | U11: 21.76 | V11: 228.56K | W11: -0.0113 | Y11: 21.11.2021 | Z11: 49492.52 | AA11: 50864.01 | AB11: 51236.58 | AC11: 49064.67 | AD11: 690.57M | AE11: -0.026 | AG11: 44636 | AH11: 7.62
A12: 46272 | B12: 30.76 | C12: 30.6 | D12: 30.76 | E12: 30.6 | F12: 0.83K | G12: 0.0253 | I12: 09.07.2026 | J12: 66107.28 | K12: 66831.04 | L12: 66945.12 | M12: 66019.15 | N12: 142.19M | O12: -0.0075 | Q12: 11/28/2021 | R12: 23.94 | S12: 22.7 | T12: 24.49 | U12: 22.54 | V12: 162.78K | W12: 0.0532 | Y12: 28.11.2021 | Z12: 50597.29 | AA12: 49520.3 | AB12: 51413.06 | AC12: 49116.94 | AD12: 1.65B | AE12: 0.0223 | AG12: 44652 | AH12: 7.72
A13: 46302 | B13: 30.6 | C13: 30.14 | D13: 30.65 | E13: 30.14 | F13: 1.12K | G13: -0.0052 | I13: 10.07.2026 | J13: 66496.1 | K13: 66140.53 | L13: 66798.05 | M13: 66140.53 | N13: 127.90M | O13: 0.0059 | Q13: 44328 | R13: 23.26 | S13: 23.9 | T13: 23.98 | U13: 22.82 | V13: 314.98K | W13: -0.0284 | Y13: 05.12.2021 | Z13: 51213.48 | AA13: 50590.86 | AB13: 51305.44 | AC13: 50445.25 | AD13: 720.22M | AE13: 0.0122 | AG13: 44667 | AH13: 7.65
A14: 07/13/2026 | B14: 30 | C14: 30.46 | D14: 30.57 | E14: 30 | F14: 1.75K | G14: -0.0196 | I14: 13.07.2026 | J14: 65973.08 | K14: 66345.02 | L14: 66614.98 | M14: 65875.46 | N14: 124.72M | O14: -0.0079 | Q14: 44542 | R14: 22.59 | S14: 23.44 | T14: 23.44 | U14: 22.19 | V14: 578.94K | W14: -0.0288 | Y14: 12.12.2021 | Z14: 52379.37 | AA14: 51214.61 | AB14: 52477.83 | AC14: 50291.02 | AD14: 1.32B | AE14: 0.0228 | AG14: 44682 | AH14: 7.58
A15: 07/15/2026 | B15: 30.04 | C15: 29.61 | D15: 30.2 | E15: 29.5 | F15: 1.37K | G15: 0.0013 | I15: 14.07.2026 | J15: 66514.3 | K15: 65930.2 | L15: 66984.89 | M15: 65930.2 | N15: 130.40M | O15: 0.0082 | Q15: 12/19/2021 | R15: 24.8 | S15: 22.59 | T15: 24.8 | U15: 22.33 | V15: 252.84K | W15: 0.0978 | Y15: 19.12.2021 | Z15: 52853.38 | AA15: 52333.26 | AB15: 52901.72 | AC15: 51319.55 | AD15: 481.82M | AE15: 0.009 | AG15: 44697 | AH15: 7.72
A16: 07/16/2026 | B16: 29.96 | C16: 30.18 | D16: 30.58 | E16: 29.96 | F16: 1.50K | G16: -0.0027 | I16: 15.07.2026 | J16: 66399.71 | K16: 66688.79 | L16: 66807.81 | M16: 66269.87 | N16: 134.99M | O16: -0.0017 | Q16: 12/26/2021 | R16: 25.98 | S16: 24.6 | T16: 26.15 | U16: 24.5 | V16: 228.19K | W16: 0.0476 | Y16: 26.12.2021 | Z16: 53272.44 | AA16: 52853.66 | AB16: 53630.53 | AC16: 52558.85 | AD16: 334.71M | AE16: 0.0079 | AG16: 44713 | AH16: 7.88
A17: 07/17/2026 | B17: 30.27 | C17: 30.27 | D17: 30.27 | E17: 30.27 | F17: 0.58K | G17: 0.0103 | I17: 16.07.2026 | J17: 66356.09 | K17: 66338.62 | L17: 66717.57 | M17: 65999.7 | N17: 113.88M | O17: -0.0007 | Q17: 44593 | R17: 24.04 | S17: 26.2 | T17: 26.2 | U17: 23.5 | V17: 162.67K | W17: -0.0747 | Y17: 02.01.2022 | Z17: 53202.11 | AA17: 53278.11 | AB17: 53603.83 | AC17: 52768.81 | AD17: 522.29M | AE17: -0.0013 | AG17: 44728 | AH17: 8.09
A18: 07/21/2026 | B18: 29.8 | C18: 29.99 | D18: 29.99 | E18: 29.8 | F18: 1.65K | G18: -0.0155 | I18: 17.07.2026 | J18: 66634.23 | K18: 66328.36 | L18: 66822.62 | M18: 65997.21 | N18: 140.85M | O18: 0.0042 | Q18: 44805 | R18: 23.98 | S18: 23.57 | T18: 24.9 | U18: 23.11 | V18: 62.43K | W18: -0.0025 | Y18: 09.01.2022 | Z18: 53744.92 | AA18: 53202.84 | AB18: 54102.49 | AC18: 52740.35 | AD18: 754.89M | AE18: 0.0102 | AG18: 44743 | AH18: 8.16
A19: 07/22/2026 | B19: 29.3 | C19: 29.3 | D19: 29.3 | E19: 29.3 | F19: 0.46K | G19: -0.0168 | I19: 20.07.2026 | J19: 66122.78 | K19: 66605.9 | L19: 67001.16 | M19: 66094.86 | N19: 111.58M | O19: -0.0077 | Q19: 01/16/2022 | R19: 22.92 | S19: 24.9 | T19: 24.9 | U19: 22.61 | V19: 30.66K | W19: -0.0442 | Y19: 16.01.2022 | Z19: 51599.38 | AA19: 53742.37 | AB19: 54219.14 | AC19: 51386.68 | AD19: 673.67M | AE19: -0.0399 | AG19: 44758 | AH19: 8.14
A20: 07/24/2026 | B20: 29.41 | C20: 30.26 | D20: 30.26 | E20: 29.41 | F20: 1.36K | G20: 0.0038 | I20: 21.07.2026 | J20: 66713.83 | K20: 66129.07 | L20: 66809.65 | M20: 66101.66 | N20: 109.35M | O20: 0.0089 | Q20: 01/23/2022 | R20: 22.39 | S20: 22.5 | T20: 23 | U20: 21.83 | V20: 534.04K | W20: -0.0231 | Y20: 23.01.2022 | Z20: 50661.86 | AA20: 51578.42 | AB20: 51578.42 | AC20: 49673.64 | AD20: 1.05B | AE20: -0.0182 | AG20: 44774 | AH20: 8.62
A21: 07/27/2026 | B21: 29.03 | C21: 29.35 | D21: 29.35 | E21: 29.03 | F21: 0.78K | G21: -0.0129 | I21: 22.07.2026 | J21: 67303.83 | K21: 66683.27 | L21: 67656.3 | M21: 66634.23 | N21: 115.68M | O21: 0.0088 | Q21: 01/30/2022 | R21: 23.24 | S21: 22.39 | T21: 23.31 | U21: 22.33 | V21: 99.04K | W21: 0.038 | Y21: 30.01.2022 | Z21: 51255.31 | AA21: 50670.28 | AB21: 52120.64 | AC21: 50631.62 | AD21: 647.19M | AE21: 0.0117 | AG21: 44789 | AH21: 8.77
A22: 07/28/2026 | B22: 29.5 | C22: 29.61 | D22: 29.61 | E22: 29.5 | F22: 1.09K | G22: 0.0162 | I22: 23.07.2026 | J22: 66266.01 | K22: 67369.19 | L22: 67369.19 | M22: 66181.08 | N22: 142.31M | O22: -0.0154 | Q22: 44714 | R22: 22.57 | S22: 22.78 | T22: 23 | U22: 21.98 | V22: 104.46K | W22: -0.0288 | Y22: 06.02.2022 | Z22: 53229.26 | AA22: 51281.26 | AB22: 53630.05 | AC22: 51011.87 | AD22: 798.15M | AE22: 0.0385 | AG22: 44805 | AH22: 8.76
A23: 07/29/2026 | B23: 29.6 | C23: 29.6 | D23: 29.6 | E23: 29.55 | F23: 0.83K | G23: 0.0034 | I23: 24.07.2026 | J23: 66383.26 | K23: 66290.18 | L23: 66748.08 | M23: 65759.85 | N23: 111.29M | O23: 0.0018 | Q23: 02/13/2022 | R23: 23.11 | S23: 22.26 | T23: 23.27 | U23: 22 | V23: 85.82K | W23: 0.0239 | Y23: 13.02.2022 | Z23: 52281.53 | AA23: 53232.26 | AB23: 53901.91 | AC23: 52161.67 | AD23: 853.91M | AE23: -0.0178 | AG23: 44820 | AH23: 8.64
A24: 07/31/2026 | B24: 29.59 | C24: 29.82 | D24: 29.82 | E24: 29.59 | F24: 1.36K | G24: -0.0003 | I24: 27.07.2026 | J24: 67157.91 | K24: 66342.71 | L24: 67427.57 | M24: 66342.71 | N24: 101.99M | O24: 0.0117 | Q24: 02/20/2022 | R24: 23.25 | S24: 23.29 | T24: 24.2 | U24: 22.75 | V24: 100.05K | W24: 0.0061 | Y24: 20.02.2022 | Z24: 52555.6 | AA24: 52281.53 | AB24: 52664.38 | AC24: 50003.09 | AD24: 927.82M | AE24: 0.0052 | AG24: 44835 | AH24: 8.53
A25: 46089 | B25: 29.8 | C25: 29.1 | D25: 29.8 | E25: 29.1 | F25: 0.80K | G25: 0.0071 | I25: 28.07.2026 | J25: 67307.54 | K25: 66998.96 | L25: 68457.09 | M25: 66676.41 | N25: 118.94M | O25: 0.0022 | Q25: 02/27/2022 | R25: 22.91 | S25: 22.85 | T25: 24.4 | U25: 22.71 | V25: 130.61K | W25: -0.0146 | Y25: 27.02.2022 | Z25: 53322.05 | AA25: 52528.71 | AB25: 54095.65 | AC25: 51990.91 | AD25: 1.78B | AE25: 0.0146 | AG25: 44850 | AH25: 8.28
A26: 46150 | B26: 29 | C26: 29.21 | D26: 29.21 | E26: 29 | F26: 1.77K | G26: -0.0268 | I26: 29.07.2026 | J26: 66479.89 | K26: 67332.48 | L26: 67432.33 | M26: 66353.78 | N26: 170.04M | O26: -0.0123 | Q26: 44715 | R26: 22.7 | S26: 23.19 | T26: 23.47 | U26: 22.2 | V26: 120.75K | W26: -0.0092 | Y26: 06.03.2022 | Z26: 53300.7 | AA26: 53354.94 | AB26: 54019.43 | AC26: 51884.08 | AD26: 1.07B | AE26: -0.0004 | AG26: 44866 | AH26: 8.14
A27: 46181 | B27: 29 | C27: 29.01 | D27: 29.01 | E27: 29 | F27: 1.00K | G27: 0 | I27: 30.07.2026 | J27: 67290.4 | K27: 66527.56 | L27: 67467.66 | M27: 66472.21 | N27: 112.07M | O27: 0.0122 | Q27: 03/13/2022 | R27: 21.62 | S27: 23.07 | T27: 23.07 | U27: 21 | V27: 181.81K | W27: -0.0476 | Y27: 13.03.2022 | Z27: 55467.06 | AA27: 53300.7 | AB27: 55788.87 | AC27: 52427.58 | AD27: 1.76B | AE27: 0.0406 | AG27: 44881 | AH27: 7.46
A28: 46211 | B28: 29.47 | C28: 29.45 | D28: 29.47 | E28: 29.45 | F28: 1.19K | G28: 0.0162 | I28: 31.07.2026 | J28: 66936.99 | K28: 67302.17 | L28: 67613.02 | M28: 66832.91 | N28: 138.50M | O28: -0.0053 | Q28: 03/20/2022 | R28: 22.13 | S28: 21.63 | T28: 22.7 | U28: 21.41 | V28: 276.61K | W28: 0.0236 | Y28: 20.03.2022 | Z28: 55436.05 | AA28: 55468.11 | AB28: 55907.49 | AC28: 54990.07 | AD28: 709.14M | AE28: -0.0006 | AG28: 44896 | AH28: 7.77
A29: 46303 | B29: 29.36 | C29: 29 | D29: 29.45 | E29: 29 | F29: 2.26K | G29: -0.0037 | I29: 03.08.2026 | J29: 66697.22 | K29: 66933.91 | L29: 67087.56 | M29: 66429.74 | N29: 96.86M | O29: -0.0036 | Q29: 03/27/2022 | R29: 22.31 | S29: 22.15 | T29: 22.5 | U29: 21.83 | V29: 363.74K | W29: 0.0081 | Y29: 27.03.2022 | Z29: 56609.54 | AA29: 55436.45 | AB29: 57064.16 | AC29: 55335.86 | AD29: 991.94M | AE29: 0.0212 | AG29: 44911 | AH29: 7.86
A30: 46334 | B30: 28.75 | C30: 29 | D30: 29 | E30: 28.71 | F30: 1.10K | G30: -0.0208 | I30: 04.08.2026 | J30: 66833.16 | K30: 66814.85 | L30: 67668.58 | M30: 66622.25 | N30: 119.77M | O30: 0.002 | Q30: 44624 | R30: 21.58 | S30: 22.07 | T30: 22.3 | U30: 21.2 | V30: 85.49K | W30: -0.0327 | Y30: 03.04.2022 | Z30: 54687.25 | AA30: 56610.03 | AB30: 56783.68 | AC30: 54591.73 | AD30: 829.89M | AE30: -0.034 | AG30: 44927 | AH30: 7.94
A31: 46364 | B31: 28.75 | C31: 28.75 | D31: 28.75 | E31: 28.75 | F31: 0.73K | G31: 0 | I31: 05.08.2026 | J31: 66525.18 | K31: 66833.38 | L31: 67168.39 | M31: 66432.18 | N31: 134.78M | O31: -0.0046 | Q31: 44838 | R31: 21.68 | S31: 21.56 | T31: 21.9 | U31: 21.19 | V31: 45.68K | W31: 0.0046 | Y31: 10.04.2022 | Z31: 54172.62 | AA31: 54678.05 | AB31: 54809.11 | AC31: 53697.42 | AD31: 403.99M | AE31: -0.0094 | AG31: 44942 | AH31: 7.88
A32: 08/13/2026 | B32: 27.95 | C32: 28.75 | D32: 28.75 | E32: 27.61 | F32: 10.40K | G32: -0.0278 | I32: 06.08.2026 | J32: 66396.15 | K32: 66432.36 | L32: 67247.56 | M32: 66336.76 | N32: 129.95M | O32: -0.0019 | Q32: 04/17/2022 | R32: 21.01 | S32: 21.72 | T32: 21.74 | U32: 21 | V32: 26.94K | W32: -0.0309 | Y32: 17.04.2022 | Z32: 53191.78 | AA32: 54172.62 | AB32: 54718.34 | AC32: 53027.2 | AD32: 739.48M | AE32: -0.0181 | AG32: 44958 | AH32: 7.76
A33: 08/14/2026 | B33: 27.5 | C33: 27.01 | D33: 27.93 | E33: 27.01 | F33: 5.43K | G33: -0.0161 | I33: 07.08.2026 | J33: 66938.64 | K33: 66394.89 | L33: 67185.88 | M33: 66394.89 | N33: 113.36M | O33: 0.0082 | Q33: 04/24/2022 | R33: 23.56 | S33: 21.01 | T33: 23.75 | U33: 21.01 | V33: 268.82K | W33: 0.1214 | Y33: 24.04.2022 | Z33: 51417.97 | AA33: 53183.12 | AB33: 53183.12 | AC33: 51315.04 | AD33: 975.60M | AE33: -0.0333 | AG33: 44973 | AH33: 7.48
A34: 08/17/2026 | B34: 27.5 | C34: 27.5 | D34: 27.5 | E34: 27.5 | F34: 0.61K | G34: 0 | I34: 10.08.2026 | J34: 66438.58 | K34: 66933.01 | L34: 66955.02 | M34: 66247 | N34: 97.22M | O34: -0.0075 | Q34: 44566 | R34: 22.07 | S34: 23.68 | T34: 23.68 | U34: 21.45 | V34: 35.68K | W34: -0.0632 | Y34: 01.05.2022 | Z34: 49541.81 | AA34: 51426.27 | AB34: 51922.71 | AC34: 49451.28 | AD34: 805.17M | AE34: -0.0365 | AG34: 44986 | AH34: 7.12
A35: 08/18/2026 | B35: 27.5 | C35: 27.5 | D35: 27.5 | E35: 27.5 | F35: 0.42K | G35: 0 | I35: 11.08.2026 | J35: 65564.76 | K35: 66398.29 | L35: 66459.17 | M35: 65509.9 | N35: 105.48M | O35: -0.0132 | Q35: 44778 | R35: 22 | S35: 21.52 | T35: 22.03 | U35: 20.97 | V35: 20.98K | W35: -0.0032 | Y35: 08.05.2022 | Z35: 49579.9 | AA35: 49419.02 | AB35: 49732.05 | AC35: 48669.21 | AD35: 1.12B | AE35: 0.0008 | AG35: 45001 | AH35: 6.58
A36: 08/19/2026 | B36: 27.49 | C36: 27.99 | D36: 27.99 | E36: 27.49 | F36: 0.79K | G36: -0.0004 | I36: 12.08.2026 | J36: 65755.97 | K36: 65746.89 | L36: 66120.72 | M36: 65404.51 | N36: 187.04M | O36: 0.0029 | Q36: 05/15/2022 | R36: 21.35 | S36: 21.5 | T36: 22.5 | U36: 21.04 | V36: 190.80K | W36: -0.0295 | Y36: 15.05.2022 | Z36: 51518.3 | AA36: 49604.95 | AB36: 51868.44 | AC36: 49472.51 | AD36: 1.13B | AE36: 0.0391 | AG36: 45017 | AH36: 6.24
A37: 08/20/2026 | B37: 27.49 | C37: 27.49 | D37: 27.49 | E37: 27.49 | F37: 0.94K | G37: 0 | I37: 13.08.2026 | J37: 64826.39 | K37: 65890.72 | L37: 65890.72 | M37: 64750.07 | N37: 204.09M | O37: -0.0141 | Q37: 05/22/2022 | R37: 21.34 | S37: 21.35 | T37: 22.12 | U37: 21.2 | V37: 125.95K | W37: -0.0005 | Y37: 22.05.2022 | Z37: 52463.55 | AA37: 51621.72 | AB37: 52617.31 | AC37: 50866.15 | AD37: 1.02B | AE37: 0.0183 | AG37: 45032 | AH37: 6.27
A38: 08/21/2026 | B38: 27.08 | C38: 27.4 | D38: 27.4 | E38: 26.6 | F38: 2.01K | G38: -0.0149 | I38: 14.08.2026 | J38: 64397.45 | K38: 65038.55 | L38: 65038.55 | M38: 64329.53 | N38: 93.51M | O38: -0.0066 | Q38: 05/29/2022 | R38: 21.27 | S38: 22.14 | T38: 22.14 | U38: 20.78 | V38: 118.27K | W38: -0.0033 | Y38: 29.05.2022 | Z38: 50689.05 | AA38: 52438.79 | AB38: 52745.98 | AC38: 50482.85 | AD38: 1.95B | AE38: -0.0338 | AG38: 45047 | AH38: 6
A39: 08/24/2026 | B39: 27.08 | C39: 27 | D39: 27.08 | E39: 27 | F39: 0.41K | G39: 0 | I39: 17.08.2026 | J39: 64254.98 | K39: 64457.26 | L39: 64534.98 | M39: 64024 | N39: 69.01M | O39: -0.0022 | Q39: 44687 | R39: 21.06 | S39: 21.29 | T39: 21.32 | U39: 20.86 | V39: 38.05K | W39: -0.0099 | Y39: 05.06.2022 | Z39: 48471.52 | AA39: 50723.91 | AB39: 51029.28 | AC39: 48398.78 | AD39: 711.74M | AE39: -0.0437 | AG39: 45062 | AH39: 5.67
A40: 08/25/2026 | B40: 27.29 | C40: 27.5 | D40: 27.5 | E40: 27.17 | F40: 1.40K | G40: 0.0078 | I40: 18.08.2026 | J40: 63933.69 | K40: 64289.47 | L40: 64665.94 | M40: 63841.29 | N40: 102.63M | O40: -0.005 | Q40: 44901 | R40: 19.21 | S40: 21 | T40: 21 | U40: 19.02 | V40: 158.20K | W40: -0.0878 | Y40: 12.06.2022 | Z40: 48016.23 | AA40: 48408.2 | AB40: 48717.67 | AC40: 47323.36 | AD40: 1.56B | AE40: -0.0094 | AG40: 45078 | AH40: 5.18
A41: 08/26/2026 | B41: 27.29 | C41: 26.51 | D41: 27.29 | E41: 26.51 | F41: 0.91K | G41: 0 | I41: 19.08.2026 | J41: 63999.26 | K41: 63990.05 | L41: 64584.42 | M41: 63924.2 | N41: 93.95M | O41: 0.001 | Q41: 06/19/2022 | R41: 21.24 | S41: 19 | T41: 21.35 | U41: 18.96 | V41: 421.74K | W41: 0.1057 | Y41: 19.06.2022 | Z41: 47741.5 | AA41: 47996.72 | AB41: 48321.17 | AC41: 46344.94 | AD41: 651.65M | AE41: -0.0057 | AG41: 45093 | AH41: 4.93
...

Sheet Rendimientos
A1: RENDIMIENTOS
B4: Soriana diario | C4: IPC diario | D4: Soriana semanal | E4: IPC semanal | G4: Precio actual de Soriana B para el modelo | H4: Valor
A5: Datos n | B5: =COUNT($AD$10:$AD$509) -> 63 | C5: =COUNT($AF$10:$AF$509) -> 73 | D5: =COUNT($AH$10:$AH$409) -> 259 | E5: =COUNT($AJ$10:$AJ$409) -> 261 | G5: Precio de cierre más reciente (MXN) | H5: =IF(B5>0,INDEX($T$10:$T$509,MATCH(MAX($S$10:$S$509),$S$10:$S$509,0)),IF(D5>0,INDEX($C$10:$C$409,MATCH(MAX($B$10:$B$409),$B$10:$B$409,0)),H8)) -> 33.1
A6: Primera fecha | B6: =IF(B5=0,"",MIN($AD$10:$AD$509)) -> 46204 | C6: =IF(C5=0,"",MIN($AF$10:$AF$509)) -> 46204 | D6: =IF(D5=0,"",MIN($AH$10:$AH$409)) -> 44486 | E6: =IF(E5=0,"",MIN($AJ$10:$AJ$409)) -> 44486 | G6: Fecha del precio | H6: =IF(B5>0,MAX($S$10:$S$509),IF(D5>0,MAX($B$10:$B$409),H9)) -> 46302
A7: Última fecha | B7: =IF(B5=0,"",MAX($AD$10:$AD$509)) -> 46302 | C7: =IF(C5=0,"",MAX($AF$10:$AF$509)) -> 46307 | D7: =IF(D5=0,"",MAX($AH$10:$AH$409)) -> 46299 | E7: =IF(E5=0,"",MAX($AJ$10:$AJ$409)) -> 46306 | G7: Fuente del precio | H7: =IF(B5>0,"Investing, diario",IF(D5>0,"Investing, semanal","RESPALDO: modelo anterior (25-sep-2026). Pega datos diarios en Base de Datos.")) -> Investing, diario
G8: Precio de respaldo (último registrado en el modelo anterior, MXN) | H8: 33.48 | AD8: LECTURA DE LO PEGADO
G9: Fecha de respaldo del precio | H9: 46290 | AD9: Fecha Soriana D | AE9: Último Soriana D | AF9: Fecha IPC D | AG9: Último IPC D | AH9: Fecha Soriana S | AI9: Último Soriana S | AJ9: Fecha IPC S | AK9: Último IPC S
G10: Fecha de valuación del modelo (= fecha del precio; respaldo 01-oct-2026) | H10: =IF(OR(B5>0,D5>0),H6,DATE(2026,10,1)) -> 46302 | AD10: =IF(ISNUMBER(AE10),IF(ISNUMBER('Base de Datos'!A6),IF('Base de Datos'!A6>20000,DATE(YEAR('Base de Datos'!A6),DAY('Base de Datos'!A6),MONTH('Base de Datos'!A6)),""),IF(TRIM('Base de Datos'!A6)="","",IFERROR(DATE(VALUE(RIGHT(TRIM('Base de Datos'!A6),4)),VALUE(LEFT(TRIM('Base de Datos'!A6),2)),VALUE(MID(TRIM('Base de Datos'!A6),4,2))),""))),"") -> 46204 | AE10: =IF(ISNUMBER('Base de Datos'!B6),'Base de Datos'!B6,IF(TRIM('Base de Datos'!B6)="","",IFERROR(IF(IFERROR(FIND("@",SUBSTITUTE(TRIM('Base de Datos'!B6),",","@",LEN(TRIM('Base de Datos'!B6))-LEN(SUBSTITUTE(TRIM('Base de Datos'!B6),",","")))),0)>IFERROR(FIND("@",SUBSTITUTE(TRIM('Base de Datos'!B6),".","@",LEN(TRIM('Base de Datos'!B6))-LEN(SUBSTITUTE(TRIM('Base de Datos'!B6),".","")))),0),_xlfn.NUMBERVALUE(SUBSTITUTE(SUBSTITUTE(TRIM('Base de Datos'!B6),".",""),",","."),".",","),_xlfn.NUMBERVALUE(SUBSTITUTE(TRIM('Base de Datos'!B6),",",""),".",",")),""))) -> 30.34 | AF10: =IF(ISNUMBER(AG10),IF(ISNUMBER('Base de Datos'!I6),IF('Base de Datos'!I6>20000,INT('Base de Datos'!I6),""),IF(TRIM('Base de Datos'!I6)="","",IFERROR(DATE(VALUE(RIGHT(TRIM('Base de Datos'!I6),4)),VALUE(MID(TRIM('Base de Datos'!I6),4,2)),VALUE(LEFT(TRIM('Base de Datos'!I6),2))),IFERROR(DATEVALUE(TRIM('Base de Datos'!I6)),"")))),"") -> 46204 | AG10: =IF(ISNUMBER('Base de Datos'!J6),'Base de Datos'!J6,IF(TRIM('Base de Datos'!J6)="","",IFERROR(IF(IFERROR(FIND("@",SUBSTITUTE(TRIM('Base de Datos'!J6),",","@",LEN(TRIM('Base de Datos'!J6))-LEN(SUBSTITUTE(TRIM('Base de Datos'!J6),",","")))),0)>IFERROR(FIND("@",SUBSTITUTE(TRIM('Base de Datos'!J6),".","@",LEN(TRIM('Base de Datos'!J6))-LEN(SUBSTITUTE(TRIM('Base de Datos'!J6),".","")))),0),_xlfn.NUMBERVALUE(SUBSTITUTE(SUBSTITUTE(TRIM('Base de Datos'!J6),".",""),",","."),".",","),_xlfn.NUMBERVALUE(SUBSTITUTE(TRIM('Base de Datos'!J6),",",""),".",",")),""))) -> 67247.79 | AH10: =IF(ISNUMBER(AI10),IF(ISNUMBER('Base de Datos'!Q6),IF('Base de Datos'!Q6>20000,DATE(YEAR('Base de Datos'!Q6),DAY('Base de Datos'!Q6),MONTH('Base de Datos'!Q6)),""),IF(TRIM('Base de Datos'!Q6)="","",IFERROR(DATE(VALUE(RIGHT(TRIM('Base de Datos'!Q6),4)),VALUE(LEFT(TRIM('Base de Datos'!Q6),2)),VALUE(MID(TRIM('Base de Datos'!Q6),4,2))),""))),"") -> 44486 | AI10: =IF(ISNUMBER('Base de Datos'!R6),'Base de Datos'!R6,IF(TRIM('Base de Datos'!R6)="","",IFERROR(IF(IFERROR(FIND("@",SUBSTITUTE(TRIM('Base de Datos'!R6),",","@",LEN(TRIM('Base de Datos'!R6))-LEN(SUBSTITUTE(TRIM('Base de Datos'!R6),",","")))),0)>IFERROR(FIND("@",SUBSTITUTE(TRIM('Base de Datos'!R6),".","@",LEN(TRIM('Base de Datos'!R6))-LEN(SUBSTITUTE(TRIM('Base de Datos'!R6),".","")))),0),_xlfn.NUMBERVALUE(SUBSTITUTE(SUBSTITUTE(TRIM('Base de Datos'!R6),".",""),",","."),".",","),_xlfn.NUMBERVALUE(SUBSTITUTE(TRIM('Base de Datos'!R6),",",""),".",",")),""))) -> 25 | AJ10: =IF(ISNUMBER(AK10),IF(ISNUMBER('Base de Datos'!Y6),IF('Base de Datos'!Y6>20000,INT('Base de Datos'!Y6),""),IF(TRIM('Base de Datos'!Y6)="","",IFERROR(DATE(VALUE(RIGHT(TRIM('Base de Datos'!Y6),4)),VALUE(MID(TRIM('Base de Datos'!Y6),4,2)),VALUE(LEFT(TRIM('Base de Datos'!Y6),2))),IFERROR(DATEVALUE(TRIM('Base de Datos'!Y6)),"")))),"") -> 44486 | AK10: =IF(ISNUMBER('Base de Datos'!Z6),'Base de Datos'!Z6,IF(TRIM('Base de Datos'!Z6)="","",IFERROR(IF(IFERROR(FIND("@",SUBSTITUTE(TRIM('Base de Datos'!Z6),",","@",LEN(TRIM('Base de Datos'!Z6))-LEN(SUBSTITUTE(TRIM('Base de Datos'!Z6),",","")))),0)>IFERROR(FIND("@",SUBSTITUTE(TRIM('Base de Datos'!Z6),".","@",LEN(TRIM('Base de Datos'!Z6))-LEN(SUBSTITUTE(TRIM('Base de Datos'!Z6),".","")))),0),_xlfn.NUMBERVALUE(SUBSTITUTE(SUBSTITUTE(TRIM('Base de Datos'!Z6),".",""),",","."),".",","),_xlfn.NUMBERVALUE(SUBSTITUTE(TRIM('Base de Datos'!Z6),",",""),".",",")),""))) -> 51889.66
A11: SEMANAL (base para la beta) | R11: DIARIO (precio actual y comparación) | AD11: =IF(ISNUMBER(AE11),IF(ISNUMBER('Base de Datos'!A7),IF('Base de Datos'!A7>20000,DATE(YEAR('Base de Datos'!A7),DAY('Base de Datos'!A7),MONTH('Base de Datos'!A7)),""),IF(TRIM('Base de Datos'!A7)="","",IFERROR(DATE(VALUE(RIGHT(TRIM('Base de Datos'!A7),4)),VALUE(LEFT(TRIM('Base de Datos'!A7),2)),VALUE(MID(TRIM('Base de Datos'!A7),4,2))),""))),"") -> 46205 | AE11: =IF(ISNUMBER('Base de Datos'!B7),'Base de Datos'!B7,IF(TRIM('Base de Datos'!B7)="","",IFERROR(IF(IFERROR(FIND("@",SUBSTITUTE(TRIM('Base de Datos'!B7),",","@",LEN(TRIM('Base de Datos'!B7))-LEN(SUBSTITUTE(TRIM('Base de Datos'!B7),",","")))),0)>IFERROR(FIND("@",SUBSTITUTE(TRIM('Base de Datos'!B7),".","@",LEN(TRIM('Base de Datos'!B7))-LEN(SUBSTITUTE(TRIM('Base de Datos'!B7),".","")))),0),_xlfn.NUMBERVALUE(SUBSTITUTE(SUBSTITUTE(TRIM('Base de Datos'!B7),".",""),",","."),".",","),_xlfn.NUMBERVALUE(SUBSTITUTE(TRIM('Base de Datos'!B7),",",""),".",",")),""))) -> 30.7 | AF11: =IF(ISNUMBER(AG11),IF(ISNUMBER('Base de Datos'!I7),IF('Base de Datos'!I7>20000,INT('Base de Datos'!I7),""),IF(TRIM('Base de Datos'!I7)="","",IFERROR(DATE(VALUE(RIGHT(TRIM('Base de Datos'!I7),4)),VALUE(MID(TRIM('Base de Datos'!I7),4,2)),VALUE(LEFT(TRIM('Base de Datos'!I7),2))),IFERROR(DATEVALUE(TRIM('Base de Datos'!I7)),"")))),"") -> 46205 | AG11: =IF(ISNUMBER('Base de Datos'!J7),'Base de Datos'!J7,IF(TRIM('Base de Datos'!J7)="","",IFERROR(IF(IFERROR(FIND("@",SUBSTITUTE(TRIM('Base de Datos'!J7),",","@",LEN(TRIM('Base de Datos'!J7))-LEN(SUBSTITUTE(TRIM('Base de Datos'!J7),",","")))),0)>IFERROR(FIND("@",SUBSTITUTE(TRIM('Base de Datos'!J7),".","@",LEN(TRIM('Base de Datos'!J7))-LEN(SUBSTITUTE(TRIM('Base de Datos'!J7),".","")))),0),_xlfn.NUMBERVALUE(SUBSTITUTE(SUBSTITUTE(TRIM('Base de Datos'!J7),".",""),",","."),".",","),_xlfn.NUMBERVALUE(SUBSTITUTE(TRIM('Base de Datos'!J7),",",""),".",",")),""))) -> 67071.11 | AH11: =IF(ISNUMBER(AI11),IF(ISNUMBER('Base de Datos'!Q7),IF('Base de Datos'!Q7>20000,DATE(YEAR('Base de Datos'!Q7),DAY('Base de Datos'!Q7),MONTH('Base de Datos'!Q7)),""),IF(TRIM('Base de Datos'!Q7)="","",IFERROR(DATE(VALUE(RIGHT(TRIM('Base de Datos'!Q7),4)),VALUE(LEFT(TRIM('Base de Datos'!Q7),2)),VALUE(MID(TRIM('Base de Datos'!Q7),4,2))),""))),"") -> 44493 | AI11: =IF(ISNUMBER('Base de Datos'!R7),'Base de Datos'!R7,IF(TRIM('Base de Datos'!R7)="","",IFERROR(IF(IFERROR(FIND("@",SUBSTITUTE(TRIM('Base de Datos'!R7),",","@",LEN(TRIM('Base de Datos'!R7))-LEN(SUBSTITUTE(TRIM('Base de Datos'!R7),",","")))),0)>IFERROR(FIND("@",SUBSTITUTE(TRIM('Base de Datos'!R7),".","@",LEN(TRIM('Base de Datos'!R7))-LEN(SUBSTITUTE(TRIM('Base de Datos'!R7),".","")))),0),_xlfn.NUMBERVALUE(SUBSTITUTE(SUBSTITUTE(TRIM('Base de Datos'!R7),".",""),",","."),".",","),_xlfn.NUMBERVALUE(SUBSTITUTE(TRIM('Base de Datos'!R7),",",""),".",",")),""))) -> 24.77 | AJ11: =IF(ISNUMBER(AK11),IF(ISNUMBER('Base de Datos'!Y7),IF('Base de Datos'!Y7>20000,INT('Base de Datos'!Y7),""),IF(TRIM('Base de Datos'!Y7)="","",IFERROR(DATE(VALUE(RIGHT(TRIM('Base de Datos'!Y7),4)),VALUE(MID(TRIM('Base de Datos'!Y7),4,2)),VALUE(LEFT(TRIM('Base de Datos'!Y7),2))),IFERROR(DATEVALUE(TRIM('Base de Datos'!Y7)),"")))),"") -> 44493 | AK11: =IF(ISNUMBER('Base de Datos'!Z7),'Base de Datos'!Z7,IF(TRIM('Base de Datos'!Z7)="","",IFERROR(IF(IFERROR(FIND("@",SUBSTITUTE(TRIM('Base de Datos'!Z7),",","@",LEN(TRIM('Base de Datos'!Z7))-LEN(SUBSTITUTE(TRIM('Base de Datos'!Z7),",","")))),0)>IFERROR(FIND("@",SUBSTITUTE(TRIM('Base de Datos'!Z7),".","@",LEN(TRIM('Base de Datos'!Z7))-LEN(SUBSTITUTE(TRIM('Base de Datos'!Z7),".","")))),0),_xlfn.NUMBERVALUE(SUBSTITUTE(SUBSTITUTE(TRIM('Base de Datos'!Z7),".",""),",","."),".",","),_xlfn.NUMBERVALUE(SUBSTITUTE(TRIM('Base de Datos'!Z7),",",""),".",",")),""))) -> 51309.84
A12: k | B12: Fecha | C12: Soriana B | D12: IPC | E12: Rend Soriana | F12: Rend IPC | G12: Par válido | J12: y: Rend. Soriana (ventana) | K12: x: Rend. IPC (ventana) | L12: No. en ventana | M12: Y compacto (Análisis de datos) | N12: X compacto (Análisis de datos) | O12: y gráfica | P12: x gráfica | R12: k | S12: Fecha | T12: Soriana B | U12: IPC | V12: Rend. Soriana | W12: Rend. IPC | X12: Par válido | Y12: y: Rend. Soriana | Z12: x: Rend. IPC | AA12: y gráfica | AB12: x gráfica | AD12: =IF(ISNUMBER(AE12),IF(ISNUMBER('Base de Datos'!A8),IF('Base de Datos'!A8>20000,DATE(YEAR('Base de Datos'!A8),DAY('Base de Datos'!A8),MONTH('Base de Datos'!A8)),""),IF(TRIM('Base de Datos'!A8)="","",IFERROR(DATE(VALUE(RIGHT(TRIM('Base de Datos'!A8),4)),VALUE(LEFT(TRIM('Base de Datos'!A8),2)),VALUE(MID(TRIM('Base de Datos'!A8),4,2))),""))),"") -> 46206 | AE12: =IF(ISNUMBER('Base de Datos'!B8),'Base de Datos'!B8,IF(TRIM('Base de Datos'!B8)="","",IFERROR(IF(IFERROR(FIND("@",SUBSTITUTE(TRIM('Base de Datos'!B8),",","@",LEN(TRIM('Base de Datos'!B8))-LEN(SUBSTITUTE(TRIM('Base de Datos'!B8),",","")))),0)>IFERROR(FIND("@",SUBSTITUTE(TRIM('Base de Datos'!B8),".","@",LEN(TRIM('Base de Datos'!B8))-LEN(SUBSTITUTE(TRIM('Base de Datos'!B8),".","")))),0),_xlfn.NUMBERVALUE(SUBSTITUTE(SUBSTITUTE(TRIM('Base de Datos'!B8),".",""),",","."),".",","),_xlfn.NUMBERVALUE(SUBSTITUTE(TRIM('Base de Datos'!B8),",",""),".",",")),""))) -> 29.91 | AF12: =IF(ISNUMBER(AG12),IF(ISNUMBER('Base de Datos'!I8),IF('Base de Datos'!I8>20000,INT('Base de Datos'!I8),""),IF(TRIM('Base de Datos'!I8)="","",IFERROR(DATE(VALUE(RIGHT(TRIM('Base de Datos'!I8),4)),VALUE(MID(TRIM('Base de Datos'!I8),4,2)),VALUE(LEFT(TRIM('Base de Datos'!I8),2))),IFERROR(DATEVALUE(TRIM('Base de Datos'!I8)),"")))),"") -> 46206 | AG12: =IF(ISNUMBER('Base de Datos'!J8),'Base de Datos'!J8,IF(TRIM('Base de Datos'!J8)="","",IFERROR(IF(IFERROR(FIND("@",SUBSTITUTE(TRIM('Base de Datos'!J8),",","@",LEN(TRIM('Base de Datos'!J8))-LEN(SUBSTITUTE(TRIM('Base de Datos'!J8),",","")))),0)>IFERROR(FIND("@",SUBSTITUTE(TRIM('Base de Datos'!J8),".","@",LEN(TRIM('Base de Datos'!J8))-LEN(SUBSTITUTE(TRIM('Base de Datos'!J8),".","")))),0),_xlfn.NUMBERVALUE(SUBSTITUTE(SUBSTITUTE(TRIM('Base de Datos'!J8),".",""),",","."),".",","),_xlfn.NUMBERVALUE(SUBSTITUTE(TRIM('Base de Datos'!J8),",",""),".",",")),""))) -> 67060.49 | AH12: =IF(ISNUMBER(AI12),IF(ISNUMBER('Base de Datos'!Q8),IF('Base de Datos'!Q8>20000,DATE(YEAR('Base de Datos'!Q8),DAY('Base de Datos'!Q8),MONTH('Base de Datos'!Q8)),""),IF(TRIM('Base de Datos'!Q8)="","",IFERROR(DATE(VALUE(RIGHT(TRIM('Base de Datos'!Q8),4)),VALUE(LEFT(TRIM('Base de Datos'!Q8),2)),VALUE(MID(TRIM('Base de Datos'!Q8),4,2))),""))),"") -> 44500 | AI12: =IF(ISNUMBER('Base de Datos'!R8),'Base de Datos'!R8,IF(TRIM('Base de Datos'!R8)="","",IFERROR(IF(IFERROR(FIND("@",SUBSTITUTE(TRIM('Base de Datos'!R8),",","@",LEN(TRIM('Base de Datos'!R8))-LEN(SUBSTITUTE(TRIM('Base de Datos'!R8),",","")))),0)>IFERROR(FIND("@",SUBSTITUTE(TRIM('Base de Datos'!R8),".","@",LEN(TRIM('Base de Datos'!R8))-LEN(SUBSTITUTE(TRIM('Base de Datos'!R8),".","")))),0),_xlfn.NUMBERVALUE(SUBSTITUTE(SUBSTITUTE(TRIM('Base de Datos'!R8),".",""),",","."),".",","),_xlfn.NUMBERVALUE(SUBSTITUTE(TRIM('Base de Datos'!R8),",",""),".",",")),""))) -> 24.48 | AJ12: =IF(ISNUMBER(AK12),IF(ISNUMBER('Base de Datos'!Y8),IF('Base de Datos'!Y8>20000,INT('Base de Datos'!Y8),""),IF(TRIM('Base de Datos'!Y8)="","",IFERROR(DATE(VALUE(RIGHT(TRIM('Base de Datos'!Y8),4)),VALUE(MID(TRIM('Base de Datos'!Y8),4,2)),VALUE(LEFT(TRIM('Base de Datos'!Y8),2))),IFERROR(DATEVALUE(TRIM('Base de Datos'!Y8)),"")))),"") -> 44500 | AK12: =IF(ISNUMBER('Base de Datos'!Z8),'Base de Datos'!Z8,IF(TRIM('Base de Datos'!Z8)="","",IFERROR(IF(IFERROR(FIND("@",SUBSTITUTE(TRIM('Base de Datos'!Z8),",","@",LEN(TRIM('Base de Datos'!Z8))-LEN(SUBSTITUTE(TRIM('Base de Datos'!Z8),",","")))),0)>IFERROR(FIND("@",SUBSTITUTE(TRIM('Base de Datos'!Z8),".","@",LEN(TRIM('Base de Datos'!Z8))-LEN(SUBSTITUTE(TRIM('Base de Datos'!Z8),".","")))),0),_xlfn.NUMBERVALUE(SUBSTITUTE(SUBSTITUTE(TRIM('Base de Datos'!Z8),".",""),",","."),".",","),_xlfn.NUMBERVALUE(SUBSTITUTE(TRIM('Base de Datos'!Z8),",",""),".",",")),""))) -> 51977.96
A13: =ROWS(A$13:A13) -> 1 | B13: =IF(COUNT($AH$10:$AH$409)=0,"",MIN($AH$10:$AH$409)) -> 44486 | C13: =IF(B13="","",INDEX($AI$10:$AI$409,MATCH(B13,$AH$10:$AH$409,0))) -> 25 | D13: =IF(B13="","",IFERROR(INDEX($AK$10:$AK$409,MATCH(B13,$AJ$10:$AJ$409,0)),"")) -> 51889.66 | E13: ="" | F13: ="" | G13: =IF(AND(ISNUMBER(E13),ISNUMBER(F13)),1,"") | H13: =IF(G13=1,COUNT(G13:G$412),"") | I13: =IF(G13=1,IF(H13<='Beta Regresión'!$B$5,1,""),"") | J13: =IF(I13=1,E13,"") | K13: =IF(I13=1,F13,"") | L13: =IF(I13=1,COUNT(I$13:I13),"") | M13: =IFERROR(INDEX($J$13:$J$412,MATCH(A13,$L$13:$L$412,0)),"") -> -0.0092 | N13: =IFERROR(INDEX($K$13:$K$412,MATCH(A13,$L$13:$L$412,0)),"") -> -0.011174095 | O13: =IF(I13=1,E13,NA()) -> #N/A | P13: =IF(I13=1,F13,NA()) -> #N/A | R13: =ROWS(R$13:R13) -> 1 | S13: =IF(COUNT($AD$10:$AD$509)=0,"",MIN($AD$10:$AD$509)) -> 46204 | T13: =IF(S13="","",INDEX($AE$10:$AE$509,MATCH(S13,$AD$10:$AD$509,0))) -> 30.34 | U13: =IF(S13="","",IFERROR(INDEX($AG$10:$AG$509,MATCH(S13,$AF$10:$AF$509,0)),"")) -> 67247.79 | V13: ="" | W13: ="" | X13: =IF(AND(ISNUMBER(V13),ISNUMBER(W13)),1,"") | Y13: =IF(X13=1,V13,"") | Z13: =IF(X13=1,W13,"") | AA13: =IF(X13=1,V13,NA()) -> #N/A | AB13: =IF(X13=1,W13,NA()) -> #N/A | AD13: =IF(ISNUMBER(AE13),IF(ISNUMBER('Base de Datos'!A9),IF('Base de Datos'!A9>20000,DATE(YEAR('Base de Datos'!A9),DAY('Base de Datos'!A9),MONTH('Base de Datos'!A9)),""),IF(TRIM('Base de Datos'!A9)="","",IFERROR(DATE(VALUE(RIGHT(TRIM('Base de Datos'!A9),4)),VALUE(LEFT(TRIM('Base de Datos'!A9),2)),VALUE(MID(TRIM('Base de Datos'!A9),4,2))),""))),"") -> 46209 | AE13: =IF(ISNUMBER('Base de Datos'!B9),'Base de Datos'!B9,IF(TRIM('Base de Datos'!B9)="","",IFERROR(IF(IFERROR(FIND("@",SUBSTITUTE(TRIM('Base de Datos'!B9),",","@",LEN(TRIM('Base de Datos'!B9))-LEN(SUBSTITUTE(TRIM('Base de Datos'!B9),",","")))),0)>IFERROR(FIND("@",SUBSTITUTE(TRIM('Base de Datos'!B9),".","@",LEN(TRIM('Base de Datos'!B9))-LEN(SUBSTITUTE(TRIM('Base de Datos'!B9),".","")))),0),_xlfn.NUMBERVALUE(SUBSTITUTE(SUBSTITUTE(TRIM('Base de Datos'!B9),".",""),",","."),".",","),_xlfn.NUMBERVALUE(SUBSTITUTE(TRIM('Base de Datos'!B9),",",""),".",",")),""))) -> 29.6 | AF13: =IF(ISNUMBER(AG13),IF(ISNUMBER('Base de Datos'!I9),IF('Base de Datos'!I9>20000,INT('Base de Datos'!I9),""),IF(TRIM('Base de Datos'!I9)="","",IFERROR(DATE(VALUE(RIGHT(TRIM('Base de Datos'!I9),4)),VALUE(MID(TRIM('Base de Datos'!I9),4,2)),VALUE(LEFT(TRIM('Base de Datos'!I9),2))),IFERROR(DATEVALUE(TRIM('Base de Datos'!I9)),"")))),"") -> 46209 | AG13: =IF(ISNUMBER('Base de Datos'!J9),'Base de Datos'!J9,IF(TRIM('Base de Datos'!J9)="","",IFERROR(IF(IFERROR(FIND("@",SUBSTITUTE(TRIM('Base de Datos'!J9),",","@",LEN(TRIM('Base de Datos'!J9))-LEN(SUBSTITUTE(TRIM('Base de Datos'!J9),",","")))),0)>IFERROR(FIND("@",SUBSTITUTE(TRIM('Base de Datos'!J9),".","@",LEN(TRIM('Base de Datos'!J9))-LEN(SUBSTITUTE(TRIM('Base de Datos'!J9),".","")))),0),_xlfn.NUMBERVALUE(SUBSTITUTE(SUBSTITUTE(TRIM('Base de Datos'!J9),".",""),",","."),".",","),_xlfn.NUMBERVALUE(SUBSTITUTE(TRIM('Base de Datos'!J9),",",""),".",",")),""))) -> 67466.46 | AH13: =IF(ISNUMBER(AI13),IF(ISNUMBER('Base de Datos'!Q9),IF('Base de Datos'!Q9>20000,DATE(YEAR('Base de Datos'!Q9),DAY('Base de Datos'!Q9),MONTH('Base de Datos'!Q9)),""),IF(TRIM('Base de Datos'!Q9)="","",IFERROR(DATE(VALUE(RIGHT(TRIM('Base de Datos'!Q9),4)),VALUE(LEFT(TRIM('Base de Datos'!Q9),2)),VALUE(MID(TRIM('Base de Datos'!Q9),4,2))),""))),"") -> 44507 | AI13: =IF(ISNUMBER('Base de Datos'!R9),'Base de Datos'!R9,IF(TRIM('Base de Datos'!R9)="","",IFERROR(IF(IFERROR(FIND("@",SUBSTITUTE(TRIM('Base de Datos'!R9),",","@",LEN(TRIM('Base de Datos'!R9))-LEN(SUBSTITUTE(TRIM('Base de Datos'!R9),",","")))),0)>IFERROR(FIND("@",SUBSTITUTE(TRIM('Base de Datos'!R9),".","@",LEN(TRIM('Base de Datos'!R9))-LEN(SUBSTITUTE(TRIM('Base de Datos'!R9),".","")))),0),_xlfn.NUMBERVALUE(SUBSTITUTE(SUBSTITUTE(TRIM('Base de Datos'!R9),".",""),",","."),".",","),_xlfn.NUMBERVALUE(SUBSTITUTE(TRIM('Base de Datos'!R9),",",""),".",",")),""))) -> 23.77 | AJ13: =IF(ISNUMBER(AK13),IF(ISNUMBER('Base de Datos'!Y9),IF('Base de Datos'!Y9>20000,INT('Base de Datos'!Y9),""),IF(TRIM('Base de Datos'!Y9)="","",IFERROR(DATE(VALUE(RIGHT(TRIM('Base de Datos'!Y9),4)),VALUE(MID(TRIM('Base de Datos'!Y9),4,2)),VALUE(LEFT(TRIM('Base de Datos'!Y9),2))),IFERROR(DATEVALUE(TRIM('Base de Datos'!Y9)),"")))),"") -> 44507 | AK13: =IF(ISNUMBER('Base de Datos'!Z9),'Base de Datos'!Z9,IF(TRIM('Base de Datos'!Z9)="","",IFERROR(IF(IFERROR(FIND("@",SUBSTITUTE(TRIM('Base de Datos'!Z9),",","@",LEN(TRIM('Base de Datos'!Z9))-LEN(SUBSTITUTE(TRIM('Base de Datos'!Z9),",","")))),0)>IFERROR(FIND("@",SUBSTITUTE(TRIM('Base de Datos'!Z9),".","@",LEN(TRIM('Base de Datos'!Z9))-LEN(SUBSTITUTE(TRIM('Base de Datos'!Z9),".","")))),0),_xlfn.NUMBERVALUE(SUBSTITUTE(SUBSTITUTE(TRIM('Base de Datos'!Z9),".",""),",","."),".",","),_xlfn.NUMBERVALUE(SUBSTITUTE(TRIM('Base de Datos'!Z9),",",""),".",",")),""))) -> 51432.54
A14: =ROWS(A$13:A14) -> 2 | B14: =IF(B13="","",IFERROR(SMALL($AH$10:$AH$409,COUNTIF($AH$10:$AH$409,"<="&B13)+1),"")) -> 44493 | C14: =IF(B14="","",INDEX($AI$10:$AI$409,MATCH(B14,$AH$10:$AH$409,0))) -> 24.77 | D14: =IF(B14="","",IFERROR(INDEX($AK$10:$AK$409,MATCH(B14,$AJ$10:$AJ$409,0)),"")) -> 51309.84 | E14: =IF(AND(ISNUMBER(C14),ISNUMBER(C13)),C14/C13-1,"") -> -0.0092 | F14: =IF(AND(ISNUMBER(D14),ISNUMBER(D13)),D14/D13-1,"") -> -0.011174095 | G14: =IF(AND(ISNUMBER(E14),ISNUMBER(F14)),1,"") -> 1 | H14: =IF(G14=1,COUNT(G14:G$412),"") -> 258 | I14: =IF(G14=1,IF(H14<='Beta Regresión'!$B$5,1,""),"") -> 1 | J14: =IF(I14=1,E14,"") -> -0.0092 | K14: =IF(I14=1,F14,"") -> -0.011174095 | L14: =IF(I14=1,COUNT(I$13:I14),"") -> 1 | M14: =IFERROR(INDEX($J$13:$J$412,MATCH(A14,$L$13:$L$412,0)),"") -> -0.011707711 | N14: =IFERROR(INDEX($K$13:$K$412,MATCH(A14,$L$13:$L$412,0)),"") -> 0.013021284 | O14: =IF(I14=1,E14,NA()) -> -0.0092 | P14: =IF(I14=1,F14,NA()) -> -0.011174095 | R14: =ROWS(R$13:R14) -> 2 | S14: =IF(S13="","",IFERROR(SMALL($AD$10:$AD$509,COUNTIF($AD$10:$AD$509,"<="&S13)+1),"")) -> 46205 | T14: =IF(S14="","",INDEX($AE$10:$AE$509,MATCH(S14,$AD$10:$AD$509,0))) -> 30.7 | U14: =IF(S14="","",IFERROR(INDEX($AG$10:$AG$509,MATCH(S14,$AF$10:$AF$509,0)),"")) -> 67071.11 | V14: =IF(AND(ISNUMBER(T14),ISNUMBER(T13)),T14/T13-1,"") -> 0.011865524 | W14: =IF(AND(ISNUMBER(U14),ISNUMBER(U13)),U14/U13-1,"") -> -0.0026272982 | X14: =IF(AND(ISNUMBER(V14),ISNUMBER(W14)),1,"") -> 1 | Y14: =IF(X14=1,V14,"") -> 0.011865524 | Z14: =IF(X14=1,W14,"") -> -0.0026272982 | AA14: =IF(X14=1,V14,NA()) -> 0.011865524 | AB14: =IF(X14=1,W14,NA()) -> -0.0026272982 | AD14: =IF(ISNUMBER(AE14),IF(ISNUMBER('Base de Datos'!A10),IF('Base de Datos'!A10>20000,DATE(YEAR('Base de Datos'!A10),DAY('Base de Datos'!A10),MONTH('Base de Datos'!A10)),""),IF(TRIM('Base de Datos'!A10)="","",IFERROR(DATE(VALUE(RIGHT(TRIM('Base de Datos'!A10),4)),VALUE(LEFT(TRIM('Base de Datos'!A10),2)),VALUE(MID(TRIM('Base de Datos'!A10),4,2))),""))),"") -> 46210 | AE14: =IF(ISNUMBER('Base de Datos'!B10),'Base de Datos'!B10,IF(TRIM('Base de Datos'!B10)="","",IFERROR(IF(IFERROR(FIND("@",SUBSTITUTE(TRIM('Base de Datos'!B10),",","@",LEN(TRIM('Base de Datos'!B10))-LEN(SUBSTITUTE(TRIM('Base de Datos'!B10),",","")))),0)>IFERROR(FIND("@",SUBSTITUTE(TRIM('Base de Datos'!B10),".","@",LEN(TRIM('Base de Datos'!B10))-LEN(SUBSTITUTE(TRIM('Base de Datos'!B10),".","")))),0),_xlfn.NUMBERVALUE(SUBSTITUTE(SUBSTITUTE(TRIM('Base de Datos'!B10),".",""),",","."),".",","),_xlfn.NUMBERVALUE(SUBSTITUTE(TRIM('Base de Datos'!B10),",",""),".",",")),""))) -> 30.29 | AF14: =IF(ISNUMBER(AG14),IF(ISNUMBER('Base de Datos'!I10),IF('Base de Datos'!I10>20000,INT('Base de Datos'!I10),""),IF(TRIM('Base de Datos'!I10)="","",IFERROR(DATE(VALUE(RIGHT(TRIM('Base de Datos'!I10),4)),VALUE(MID(TRIM('Base de Datos'!I10),4,2)),VALUE(LEFT(TRIM('Base de Datos'!I10),2))),IFERROR(DATEVALUE(TRIM('Base de Datos'!I10)),"")))),"") -> 46210 | AG14: =IF(ISNUMBER('Base de Datos'!J10),'Base de Datos'!J10,IF(TRIM('Base de Datos'!J10)="","",IFERROR(IF(IFERROR(FIND("@",SUBSTITUTE(TRIM('Base de Datos'!J10),",","@",LEN(TRIM('Base de Datos'!J10))-LEN(SUBSTITUTE(TRIM('Base de Datos'!J10),",","")))),0)>IFERROR(FIND("@",SUBSTITUTE(TRIM('Base de Datos'!J10),".","@",LEN(TRIM('Base de Datos'!J10))-LEN(SUBSTITUTE(TRIM('Base de Datos'!J10),".","")))),0),_xlfn.NUMBERVALUE(SUBSTITUTE(SUBSTITUTE(TRIM('Base de Datos'!J10),".",""),",","."),".",","),_xlfn.NUMBERVALUE(SUBSTITUTE(TRIM('Base de Datos'!J10),",",""),".",",")),""))) -> 66674.7 | AH14: =IF(ISNUMBER(AI14),IF(ISNUMBER('Base de Datos'!Q10),IF('Base de Datos'!Q10>20000,DATE(YEAR('Base de Datos'!Q10),DAY('Base de Datos'!Q10),MONTH('Base de Datos'!Q10)),""),IF(TRIM('Base de Datos'!Q10)="","",IFERROR(DATE(VALUE(RIGHT(TRIM('Base de Datos'!Q10),4)),VALUE(LEFT(TRIM('Base de Datos'!Q10),2)),VALUE(MID(TRIM('Base de Datos'!Q10),4,2))),""))),"") -> 44514 | AI14: =IF(ISNUMBER('Base de Datos'!R10),'Base de Datos'!R10,IF(TRIM('Base de Datos'!R10)="","",IFERROR(IF(IFERROR(FIND("@",SUBSTITUTE(TRIM('Base de Datos'!R10),",","@",LEN(TRIM('Base de Datos'!R10))-LEN(SUBSTITUTE(TRIM('Base de Datos'!R10),",","")))),0)>IFERROR(FIND("@",SUBSTITUTE(TRIM('Base de Datos'!R10),".","@",LEN(TRIM('Base de Datos'!R10))-LEN(SUBSTITUTE(TRIM('Base de Datos'!R10),".","")))),0),_xlfn.NUMBERVALUE(SUBSTITUTE(SUBSTITUTE(TRIM('Base de Datos'!R10),".",""),",","."),".",","),_xlfn.NUMBERVALUE(SUBSTITUTE(TRIM('Base de Datos'!R10),",",""),".",",")),""))) -> 22.99 | AJ14: =IF(ISNUMBER(AK14),IF(ISNUMBER('Base de Datos'!Y10),IF('Base de Datos'!Y10>20000,INT('Base de Datos'!Y10),""),IF(TRIM('Base de Datos'!Y10)="","",IFERROR(DATE(VALUE(RIGHT(TRIM('Base de Datos'!Y10),4)),VALUE(MID(TRIM('Base de Datos'!Y10),4,2)),VALUE(LEFT(TRIM('Base de Datos'!Y10),2))),IFERROR(DATEVALUE(TRIM('Base de Datos'!Y10)),"")))),"") -> 44514 | AK14: =IF(ISNUMBER('Base de Datos'!Z10),'Base de Datos'!Z10,IF(TRIM('Base de Datos'!Z10)="","",IFERROR(IF(IFERROR(FIND("@",SUBSTITUTE(TRIM('Base de Datos'!Z10),",","@",LEN(TRIM('Base de Datos'!Z10))-LEN(SUBSTITUTE(TRIM('Base de Datos'!Z10),",","")))),0)>IFERROR(FIND("@",SUBSTITUTE(TRIM('Base de Datos'!Z10),".","@",LEN(TRIM('Base de Datos'!Z10))-LEN(SUBSTITUTE(TRIM('Base de Datos'!Z10),".","")))),0),_xlfn.NUMBERVALUE(SUBSTITUTE(SUBSTITUTE(TRIM('Base de Datos'!Z10),".",""),",","."),".",","),_xlfn.NUMBERVALUE(SUBSTITUTE(TRIM('Base de Datos'!Z10),",",""),".",",")),""))) -> 50811.3
